Workbook
Name baxv: [1]!الجدول2[[#Headers],[#Data]]
Name baxv: [1]!الجدول2[[#Headers],[#Data]]
Name baxv: [1]!الجدول2[[#Headers],[#Data]]
Name baxv: [1]!الجدول2[[#Headers],[#Data]]
Name baxv: [1]!الجدول2[[#Headers],[#Data]]
Name baxv: [1]!الجدول2[[#Headers],[#Data]]
Name baxv: [1]!الجدول2[[#Headers],[#Data]]
Name baxv: [1]!الجدول2[[#Headers],[#Data]]
Name baxv: [1]!الجدول2[[#Headers],[#Data]]
Name baxv: [1]!الجدول2[[#Headers],[#Data]]
Name baxv: [1]!الجدول2[[#Headers],[#Data]]
Name baxv: [1]!الجدول2[[#Headers],[#Data]]
Name baxv: [1]!الجدول2[[#Headers],[#Data]]
Name baxv: [1]!الجدول2[[#Headers],[#Data]]
Name baxv: [1]!الجدول2[[#Headers],[#Data]]
Name baxv: [1]!الجدول2[[#Headers],[#Data]]
Name baxv: [1]!الجدول2[[#Headers],[#Data]]
Name baxv: [1]!الجدول2[[#Headers],[#Data]]
Name baxv: [1]!الجدول2[[#Headers],[#Data]]
Name baxv: [1]!الجدول2[[#Headers],[#Data]]
Name baxv: [1]!الجدول2[[#Headers],[#Data]]
Name baxv: [1]!الجدول2[[#Headers],[#Data]]
Name baxv: [1]!الجدول2[[#Headers],[#Data]]
Name baxv: [1]!الجدول2[[#Headers],[#Data]]
Name baxv: [1]!الجدول2[[#Headers],[#Data]]
Name baxv: [1]!الجدول2[[#Headers],[#Data]]
Name baxv: [1]!الجدول2[[#Headers],[#Data]]
Name baxv: [1]!الجدول2[[#Headers],[#Data]]
Name baxv: [1]!الجدول2[[#Headers],[#Data]]
Name baxv: [1]!الجدول2[[#Headers],[#Data]]
Name baxv: [1]!الجدول2[[#Headers],[#Data]]
Name baxv: [1]!الجدول2[[#Headers],[#Data]]
Name baxv: [1]!الجدول2[[#Headers],[#Data]]
Name baxv: [1]!الجدول2[[#Headers],[#Data]]
Name baxv: [1]!الجدول2[[#Headers],[#Data]]
Name baxv: [1]!الجدول2[[#Headers],[#Data]]
Name baxv: [1]!الجدول2[[#Headers],[#Data]]
Name baxv: [1]!الجدول2[[#Headers],[#Data]]
Name baxv: [1]!الجدول2[[#Headers],[#Data]]
Name baxv: [1]!الجدول2[[#Headers],[#Data]]
Name baxv: [1]!الجدول2[[#Headers],[#Data]]
Name baxv: [1]!الجدول2[[#Headers],[#Data]]
Name baxv: [1]!الجدول2[[#Headers],[#Data]]
Name baxv: [1]!الجدول2[[#Headers],[#Data]]
Name baxv: [1]!الجدول2[[#Headers],[#Data]]
Name baxv: [1]!الجدول2[[#Headers],[#Data]]
Name baxv: [1]!الجدول2[[#Headers],[#Data]]
Name baxv: [1]!الجدول2[[#Headers],[#Data]]
Name baxv: [1]!الجدول2[[#Headers],[#Data]]
Name baxv: [1]!الجدول2[[#Headers],[#Data]]
Name baxv: [1]!الجدول2[[#Headers],[#Data]]
Name baxv: [1]!الجدول2[[#Headers],[#Data]]
Name baxv: [1]!الجدول2[[#Headers],[#Data]]
Name baxv: [1]!الجدول2[[#Headers],[#Data]]
Name baxv: [1]!الجدول2[[#Headers],[#Data]]
Name baxv: [1]!الجدول2[[#Headers],[#Data]]
Name baxv: [1]!الجدول2[[#Headers],[#Data]]
Name baxv: [1]!الجدول2[[#Headers],[#Data]]
Name baxv: [1]!الجدول2[[#Headers],[#Data]]
Name baxv: [1]!الجدول2[[#Headers],[#Data]]

Sheet قائمة الموظفين
A1: مؤسسة زاد الجود للوجبات السريعة
A3: # | B3: اسم المشترك | C3: رقم الهوية | D3: الجنسية | E3: الجنس | F3: تاريخ الميلاد | G3: الأجر الأساسي | H3: السكن | I3: العمولات | J3: البدلات الأخرى | K3: إجمالي الأجر | L3: الاجر الخاضع للاشتراك | M3: المهنة | N3: تاريخ الإلتحاق | O3: فترة العمل بالشركة | P3: رصيد الاجازة المستحق | Q3: رصيد الاجازة المستخدم | R3: رصيد الاجازة الحالي | S3: قيمة مستحقات الاجازة | T3: مستحقات نهاية الخدمة
A4: 10000 | B4: GOLAM NOBI | C4: 2429697275 | D4: بنغلادش | E4: ذكر | F4: 1992-11-15 | G4: 2200 | H4: 0 | I4: 0 | J4: 0 | K4: 2200 | L4: 2200 | M4: عامل مطبخ | N4: 43037 | O4: =YEARFRAC(TODAY(),Table1[[#This Row],[تاريخ الإلتحاق]],1) -> 8.1703681 | P4: =IF(Table1[[#This Row],[فترة العمل بالشركة]]<=5,Table1[[#This Row],[فترة العمل بالشركة]]*21,(((Table1[[#This Row],[فترة العمل بالشركة]]-5)*30)+(5*21))) -> 200.11104 | Q4: ='10000'!E37 -> 170 | R4: =Table1[[#This Row],[رصيد الاجازة المستحق]]-Table1[[#This Row],[رصيد الاجازة المستخدم]] -> 30.111044 | S4: =Table1[[#This Row],[رصيد الاجازة الحالي]]/30*Table1[[#This Row],[إجمالي الأجر]] -> 2208.1432 | T4: =IF(Table1[[#This Row],[فترة العمل بالشركة]]<=5,Table1[[#This Row],[فترة العمل بالشركة]]*Table1[[#This Row],[الاجر الخاضع للاشتراك]]/2,((Table1[[#This Row],[فترة العمل بالشركة]]-2.5)*Table1[[#This Row],[الاجر الخاضع للاشتراك]])) -> 12474.81
A5: 10001 | B5: عمر محمد احمد صالح الوايلي | C5: 2450159252 | D5: اليمن | E5: ذكر | F5: 1990-02-16 | G5: 3500 | H5: 0 | I5: 0 | J5: 0 | K5: 3500 | L5: 3500 | M5: سائق شاحنة صغيرة | N5: 43221 | O5: =YEARFRAC(TODAY(),Table1[[#This Row],[تاريخ الإلتحاق]],1) -> 7.6659822 | P5: =IF(Table1[[#This Row],[فترة العمل بالشركة]]<=5,Table1[[#This Row],[فترة العمل بالشركة]]*21,(((Table1[[#This Row],[فترة العمل بالشركة]]-5)*30)+(5*21))) -> 184.97947 | Q5: ='10001'!E37 -> 165 | R5: =Table1[[#This Row],[رصيد الاجازة المستحق]]-Table1[[#This Row],[رصيد الاجازة المستخدم]] -> 19.979466 | S5: =Table1[[#This Row],[رصيد الاجازة الحالي]]/30*Table1[[#This Row],[إجمالي الأجر]] -> 2330.9377 | T5: =IF(Table1[[#This Row],[فترة العمل بالشركة]]<=5,Table1[[#This Row],[فترة العمل بالشركة]]*Table1[[#This Row],[الاجر الخاضع للاشتراك]]/2,((Table1[[#This Row],[فترة العمل بالشركة]]-2.5)*Table1[[#This Row],[الاجر الخاضع للاشتراك]])) -> 18080.938
A6: 10002 | B6: عصام محمد عبده قايد العربي | C6: 2458947997 | D6: اليمن | E6: ذكر | F6: 1989-07-04 | G6: 3000 | H6: 0 | I6: 0 | J6: 0 | K6: 3000 | L6: 3000 | M6: عامل مطبخ | N6: 43387 | O6: =YEARFRAC(TODAY(),Table1[[#This Row],[تاريخ الإلتحاق]],1) -> 7.211499 | P6: =IF(Table1[[#This Row],[فترة العمل بالشركة]]<=5,Table1[[#This Row],[فترة العمل بالشركة]]*21,(((Table1[[#This Row],[فترة العمل بالشركة]]-5)*30)+(5*21))) -> 171.34497 | Q6: ='10002'!E37 -> 134 | R6: =Table1[[#This Row],[رصيد الاجازة المستحق]]-Table1[[#This Row],[رصيد الاجازة المستخدم]] -> 37.344969 | S6: =Table1[[#This Row],[رصيد الاجازة الحالي]]/30*Table1[[#This Row],[إجمالي الأجر]] -> 3734.4969 | T6: =IF(Table1[[#This Row],[فترة العمل بالشركة]]<=5,Table1[[#This Row],[فترة العمل بالشركة]]*Table1[[#This Row],[الاجر الخاضع للاشتراك]]/2,((Table1[[#This Row],[فترة العمل بالشركة]]-2.5)*Table1[[#This Row],[الاجر الخاضع للاشتراك]])) -> 14134.497
A7: 10003 | B7: نشوان صادق محسن عبدالله زعيل | C7: 2452413053 | D7: اليمن | E7: ذكر | F7: 1996-01-01 | G7: 3000 | H7: 0 | I7: 0 | J7: 0 | K7: 3000 | L7: 3000 | M7: عامل مطبخ | N7: 43497 | O7: =YEARFRAC(TODAY(),Table1[[#This Row],[تاريخ الإلتحاق]],1) -> 6.9096598 | P7: =IF(Table1[[#This Row],[فترة العمل بالشركة]]<=5,Table1[[#This Row],[فترة العمل بالشركة]]*21,(((Table1[[#This Row],[فترة العمل بالشركة]]-5)*30)+(5*21))) -> 162.28979 | Q7: ='10003'!E37 -> 133 | R7: =Table1[[#This Row],[رصيد الاجازة المستحق]]-Table1[[#This Row],[رصيد الاجازة المستخدم]] -> 29.289793 | S7: =Table1[[#This Row],[رصيد الاجازة الحالي]]/30*Table1[[#This Row],[إجمالي الأجر]] -> 2928.9793 | T7: =IF(Table1[[#This Row],[فترة العمل بالشركة]]<=5,Table1[[#This Row],[فترة العمل بالشركة]]*Table1[[#This Row],[الاجر الخاضع للاشتراك]]/2,((Table1[[#This Row],[فترة العمل بالشركة]]-2.5)*Table1[[#This Row],[الاجر الخاضع للاشتراك]])) -> 13228.979
A8: 10004 | B8: MD KAWSAR GOLAM RASUL | C8: 2458805666 | D8: بنغلادش | E8: ذكر | F8: 1995-12-06 | G8: 1800 | H8: 0 | I8: 0 | J8: 0 | K8: 1800 | L8: 1800 | M8: عامل مطبخ | N8: 43556 | O8: =YEARFRAC(TODAY(),Table1[[#This Row],[تاريخ الإلتحاق]],1) -> 6.7481424 | P8: =IF(Table1[[#This Row],[فترة العمل بالشركة]]<=5,Table1[[#This Row],[فترة العمل بالشركة]]*21,(((Table1[[#This Row],[فترة العمل بالشركة]]-5)*30)+(5*21))) -> 157.44427 | Q8: ='10004'!E37 -> 129 | R8: =Table1[[#This Row],[رصيد الاجازة المستحق]]-Table1[[#This Row],[رصيد الاجازة المستخدم]] -> 28.444271 | S8: =Table1[[#This Row],[رصيد الاجازة الحالي]]/30*Table1[[#This Row],[إجمالي الأجر]] -> 1706.6562 | T8: =IF(Table1[[#This Row],[فترة العمل بالشركة]]<=5,Table1[[#This Row],[فترة العمل بالشركة]]*Table1[[#This Row],[الاجر الخاضع للاشتراك]]/2,((Table1[[#This Row],[فترة العمل بالشركة]]-2.5)*Table1[[#This Row],[الاجر الخاضع للاشتراك]])) -> 7646.6562
A9: 10005 | B9: عيده مدلف مرزوق الجحيشي | C9: 1006176208 | D9: السعودية | E9: انثى | F9: 1974-07-20 | G9: 4000 | H9: 0 | I9: 0 | J9: 0 | K9: 4000 | L9: 4000 | M9: مندوب مشتريات | N9: 44105 | O9: =YEARFRAC(TODAY(),Table1[[#This Row],[تاريخ الإلتحاق]],1) -> 5.2445255 | P9: =IF(Table1[[#This Row],[فترة العمل بالشركة]]<=5,Table1[[#This Row],[فترة العمل بالشركة]]*21,(((Table1[[#This Row],[فترة العمل بالشركة]]-5)*30)+(5*21))) -> 112.33577 | Q9: ='10005'!E37 -> 90 | R9: =Table1[[#This Row],[رصيد الاجازة المستحق]]-Table1[[#This Row],[رصيد الاجازة المستخدم]] -> 22.335766 | S9: =Table1[[#This Row],[رصيد الاجازة الحالي]]/30*Table1[[#This Row],[إجمالي الأجر]] -> 2978.1022 | T9: =IF(Table1[[#This Row],[فترة العمل بالشركة]]<=5,Table1[[#This Row],[فترة العمل بالشركة]]*Table1[[#This Row],[الاجر الخاضع للاشتراك]]/2,((Table1[[#This Row],[فترة العمل بالشركة]]-2.5)*Table1[[#This Row],[الاجر الخاضع للاشتراك]])) -> 10978.102
A10: 10006 | B10: هلا خالد عبدالله القعيد | C10: 1112518376 | D10: السعودية | E10: انثى | F10: 2001-02-02 | G10: 4000 | H10: 0 | I10: 0 | J10: 0 | K10: 4000 | L10: 4000 | M10: مندوب مشتريات | N10: 44105 | O10: =YEARFRAC(TODAY(),Table1[[#This Row],[تاريخ الإلتحاق]],1) -> 5.2445255 | P10: =IF(Table1[[#This Row],[فترة العمل بالشركة]]<=5,Table1[[#This Row],[فترة العمل بالشركة]]*21,(((Table1[[#This Row],[فترة العمل بالشركة]]-5)*30)+(5*21))) -> 112.33577 | Q10: ='10006'!E37 -> 89 | R10: =Table1[[#This Row],[رصيد الاجازة المستحق]]-Table1[[#This Row],[رصيد الاجازة المستخدم]] -> 23.335766 | S10: =Table1[[#This Row],[رصيد الاجازة الحالي]]/30*Table1[[#This Row],[إجمالي الأجر]] -> 3111.4355 | T10: =IF(Table1[[#This Row],[فترة العمل بالشركة]]<=5,Table1[[#This Row],[فترة العمل بالشركة]]*Table1[[#This Row],[الاجر الخاضع للاشتراك]]/2,((Table1[[#This Row],[فترة العمل بالشركة]]-2.5)*Table1[[#This Row],[الاجر الخاضع للاشتراك]])) -> 10978.102
A11: 10007 | B11: ABDUL KADIR | C11: 2507903470 | D11: بنغلادش | E11: ذكر | F11: 1967-05-20 | G11: 2000 | H11: 0 | I11: 0 | J11: 0 | K11: 2000 | L11: 2000 | M11: عامل مطبخ | N11: 44364 | O11: =YEARFRAC(TODAY(),Table1[[#This Row],[تاريخ الإلتحاق]],1) -> 4.5372399 | P11: =IF(Table1[[#This Row],[فترة العمل بالشركة]]<=5,Table1[[#This Row],[فترة العمل بالشركة]]*21,(((Table1[[#This Row],[فترة العمل بالشركة]]-5)*30)+(5*21))) -> 95.282037 | Q11: ='10007'!E37 -> 74 | R11: =Table1[[#This Row],[رصيد الاجازة المستحق]]-Table1[[#This Row],[رصيد الاجازة المستخدم]] -> 21.282037 | S11: =Table1[[#This Row],[رصيد الاجازة الحالي]]/30*Table1[[#This Row],[إجمالي الأجر]] -> 1418.8025 | T11: =IF(Table1[[#This Row],[فترة العمل بالشركة]]<=5,Table1[[#This Row],[فترة العمل بالشركة]]*Table1[[#This Row],[الاجر الخاضع للاشتراك]]/2,((Table1[[#This Row],[فترة العمل بالشركة]]-2.5)*Table1[[#This Row],[الاجر الخاضع للاشتراك]])) -> 4537.2399
A12: 10008 | B12: MONIR HOSSAIN | C12: 2507903686 | D12: بنغلادش | E12: ذكر | F12: 1983-05-05 | G12: 2200 | H12: 0 | I12: 0 | J12: 0 | K12: 2200 | L12: 2200 | M12: عامل مطبخ | N12: 44364 | O12: =YEARFRAC(TODAY(),Table1[[#This Row],[تاريخ الإلتحاق]],1) -> 4.5372399 | P12: =IF(Table1[[#This Row],[فترة العمل بالشركة]]<=5,Table1[[#This Row],[فترة العمل بالشركة]]*21,(((Table1[[#This Row],[فترة العمل بالشركة]]-5)*30)+(5*21))) -> 95.282037 | Q12: ='10008'!E37 -> 74 | R12: =Table1[[#This Row],[رصيد الاجازة المستحق]]-Table1[[#This Row],[رصيد الاجازة المستخدم]] -> 21.282037 | S12: =Table1[[#This Row],[رصيد الاجازة الحالي]]/30*Table1[[#This Row],[إجمالي الأجر]] -> 1560.6827 | T12: =IF(Table1[[#This Row],[فترة العمل بالشركة]]<=5,Table1[[#This Row],[فترة العمل بالشركة]]*Table1[[#This Row],[الاجر الخاضع للاشتراك]]/2,((Table1[[#This Row],[فترة العمل بالشركة]]-2.5)*Table1[[#This Row],[الاجر الخاضع للاشتراك]])) -> 4990.9639
A13: 10009 | B13: فاطمه عليان بن ثواب الحربي | C13: 1114222910 | D13: السعودية | E13: انثى | F13: 2001-11-30 | G13: 4500 | H13: 0 | I13: 0 | J13: 0 | K13: 4500 | L13: 4500 | M13: أخصائي تسويق | N13: 44621 | O13: =YEARFRAC(TODAY(),Table1[[#This Row],[تاريخ الإلتحاق]],1) -> 3.8329911 | P13: =IF(Table1[[#This Row],[فترة العمل بالشركة]]<=5,Table1[[#This Row],[فترة العمل بالشركة]]*21,(((Table1[[#This Row],[فترة العمل بالشركة]]-5)*30)+(5*21))) -> 80.492813 | Q13: ='10009'!E37 -> 40 | R13: =Table1[[#This Row],[رصيد الاجازة المستحق]]-Table1[[#This Row],[رصيد الاجازة المستخدم]] -> 40.492813 | S13: =Table1[[#This Row],[رصيد الاجازة الحالي]]/30*Table1[[#This Row],[إجمالي الأجر]] -> 6073.922 | T13: =IF(Table1[[#This Row],[فترة العمل بالشركة]]<=5,Table1[[#This Row],[فترة العمل بالشركة]]*Table1[[#This Row],[الاجر الخاضع للاشتراك]]/2,((Table1[[#This Row],[فترة العمل بالشركة]]-2.5)*Table1[[#This Row],[الاجر الخاضع للاشتراك]])) -> 8624.23
A14: 10010 | B14: ساره صالح مطلق الراكضي | C14: 1135022026 | D14: السعودية | E14: انثى | F14: 2002-12-08 | G14: 5500 | H14: 0 | I14: 0 | J14: 0 | K14: 5500 | L14: 5500 | M14: أخصائي تسويق | N14: 44621 | O14: =YEARFRAC(TODAY(),Table1[[#This Row],[تاريخ الإلتحاق]],1) -> 3.8329911 | P14: =IF(Table1[[#This Row],[فترة العمل بالشركة]]<=5,Table1[[#This Row],[فترة العمل بالشركة]]*21,(((Table1[[#This Row],[فترة العمل بالشركة]]-5)*30)+(5*21))) -> 80.492813 | Q14: ='10010'!E37 -> 45 | R14: =Table1[[#This Row],[رصيد الاجازة المستحق]]-Table1[[#This Row],[رصيد الاجازة المستخدم]] -> 35.492813 | S14: =Table1[[#This Row],[رصيد الاجازة الحالي]]/30*Table1[[#This Row],[إجمالي الأجر]] -> 6507.0157 | T14: =IF(Table1[[#This Row],[فترة العمل بالشركة]]<=5,Table1[[#This Row],[فترة العمل بالشركة]]*Table1[[#This Row],[الاجر الخاضع للاشتراك]]/2,((Table1[[#This Row],[فترة العمل بالشركة]]-2.5)*Table1[[#This Row],[الاجر الخاضع للاشتراك]])) -> 10540.726
A15: 10011 | B15: أديب محمد سعيد عبدالصفي | C15: 2503945004 | D15: اليمن | E15: ذكر | F15: 1994-02-15 | G15: 7000 | H15: 0 | I15: 0 | J15: 0 | K15: 7000 | L15: 7000 | M15: عامل عادي | N15: 44628 | O15: =YEARFRAC(TODAY(),Table1[[#This Row],[تاريخ الإلتحاق]],1) -> 3.8138261 | P15: =IF(Table1[[#This Row],[فترة العمل بالشركة]]<=5,Table1[[#This Row],[فترة العمل بالشركة]]*21,(((Table1[[#This Row],[فترة العمل بالشركة]]-5)*30)+(5*21))) -> 80.090349 | Q15: ='10011'!E37 -> 55 | R15: =Table1[[#This Row],[رصيد الاجازة المستحق]]-Table1[[#This Row],[رصيد الاجازة المستخدم]] -> 25.090349 | S15: =Table1[[#This Row],[رصيد الاجازة الحالي]]/30*Table1[[#This Row],[إجمالي الأجر]] -> 5854.4148 | T15: =IF(Table1[[#This Row],[فترة العمل بالشركة]]<=5,Table1[[#This Row],[فترة العمل بالشركة]]*Table1[[#This Row],[الاجر الخاضع للاشتراك]]/2,((Table1[[#This Row],[فترة العمل بالشركة]]-2.5)*Table1[[#This Row],[الاجر الخاضع للاشتراك]])) -> 13348.392
A16: 10012 | B16: MO AKRAM HASIN | C16: 2509447294 | D16: الهند | E16: ذكر | F16: 1992-06-26 | G16: 8000 | H16: 0 | I16: 0 | J16: 0 | K16: 8000 | L16: 8000 | M16: عامل مطبخ | N16: 44629 | O16: =YEARFRAC(TODAY(),Table1[[#This Row],[تاريخ الإلتحاق]],1) -> 3.8110883 | P16: =IF(Table1[[#This Row],[فترة العمل بالشركة]]<=5,Table1[[#This Row],[فترة العمل بالشركة]]*21,(((Table1[[#This Row],[فترة العمل بالشركة]]-5)*30)+(5*21))) -> 80.032854 | Q16: ='10012'!E37 -> 59 | R16: =Table1[[#This Row],[رصيد الاجازة المستحق]]-Table1[[#This Row],[رصيد الاجازة المستخدم]] -> 21.032854 | S16: =Table1[[#This Row],[رصيد الاجازة الحالي]]/30*Table1[[#This Row],[إجمالي الأجر]] -> 5608.7611 | T16: =IF(Table1[[#This Row],[فترة العمل بالشركة]]<=5,Table1[[#This Row],[فترة العمل بالشركة]]*Table1[[#This Row],[الاجر الخاضع للاشتراك]]/2,((Table1[[#This Row],[فترة العمل بالشركة]]-2.5)*Table1[[#This Row],[الاجر الخاضع للاشتراك]])) -> 15244.353
A17: 10013 | B17: ماهر مهيوب محمد سلطان الفقيه | C17: 2463831509 | D17: اليمن | E17: ذكر | F17: 1994-05-03 | G17: 3000 | H17: 0 | I17: 0 | J17: 0 | K17: 3000 | L17: 3000 | M17: سائق شاحنة صغيرة | N17: 44631 | O17: =YEARFRAC(TODAY(),Table1[[#This Row],[تاريخ الإلتحاق]],1) -> 3.8056126 | P17: =IF(Table1[[#This Row],[فترة العمل بالشركة]]<=5,Table1[[#This Row],[فترة العمل بالشركة]]*21,(((Table1[[#This Row],[فترة العمل بالشركة]]-5)*30)+(5*21))) -> 79.917864 | Q17: ='10013'!E37 -> 64 | R17: =Table1[[#This Row],[رصيد الاجازة المستحق]]-Table1[[#This Row],[رصيد الاجازة المستخدم]] -> 15.917864 | S17: =Table1[[#This Row],[رصيد الاجازة الحالي]]/30*Table1[[#This Row],[إجمالي الأجر]] -> 1591.7864 | T17: =IF(Table1[[#This Row],[فترة العمل بالشركة]]<=5,Table1[[#This Row],[فترة العمل بالشركة]]*Table1[[#This Row],[الاجر الخاضع للاشتراك]]/2,((Table1[[#This Row],[فترة العمل بالشركة]]-2.5)*Table1[[#This Row],[الاجر الخاضع للاشتراك]])) -> 5708.4189
A18: 10014 | B18: PAPON HASAN APU | C18: 2509540718 | D18: بنغلادش | E18: ذكر | F18: 1996-06-12 | G18: 1500 | H18: 0 | I18: 0 | J18: 0 | K18: 1500 | L18: 1500 | M18: عامل مطبخ | N18: 44641 | O18: =YEARFRAC(TODAY(),Table1[[#This Row],[تاريخ الإلتحاق]],1) -> 3.7782341 | P18: =IF(Table1[[#This Row],[فترة العمل بالشركة]]<=5,Table1[[#This Row],[فترة العمل بالشركة]]*21,(((Table1[[#This Row],[فترة العمل بالشركة]]-5)*30)+(5*21))) -> 79.342916 | Q18: ='10014'!E37 -> 61 | R18: =Table1[[#This Row],[رصيد الاجازة المستحق]]-Table1[[#This Row],[رصيد الاجازة المستخدم]] -> 18.342916 | S18: =Table1[[#This Row],[رصيد الاجازة الحالي]]/30*Table1[[#This Row],[إجمالي الأجر]] -> 917.14579 | T18: =IF(Table1[[#This Row],[فترة العمل بالشركة]]<=5,Table1[[#This Row],[فترة العمل بالشركة]]*Table1[[#This Row],[الاجر الخاضع للاشتراك]]/2,((Table1[[#This Row],[فترة العمل بالشركة]]-2.5)*Table1[[#This Row],[الاجر الخاضع للاشتراك]])) -> 2833.6756
A19: 10015 | B19: صدام عبده علي الغانمي | C19: 2378255323 | D19: اليمن | E19: ذكر | F19: 1989-08-02 | G19: 2600 | H19: 0 | I19: 0 | J19: 0 | K19: 2600 | L19: 2600 | M19: سائق شاحنة صغيرة | N19: 44741 | O19: =YEARFRAC(TODAY(),Table1[[#This Row],[تاريخ الإلتحاق]],1) -> 3.504449 | P19: =IF(Table1[[#This Row],[فترة العمل بالشركة]]<=5,Table1[[#This Row],[فترة العمل بالشركة]]*21,(((Table1[[#This Row],[فترة العمل بالشركة]]-5)*30)+(5*21))) -> 73.593429 | Q19: ='10015'!E37 -> 58 | R19: =Table1[[#This Row],[رصيد الاجازة المستحق]]-Table1[[#This Row],[رصيد الاجازة المستخدم]] -> 15.593429 | S19: =Table1[[#This Row],[رصيد الاجازة الحالي]]/30*Table1[[#This Row],[إجمالي الأجر]] -> 1351.4305 | T19: =IF(Table1[[#This Row],[فترة العمل بالشركة]]<=5,Table1[[#This Row],[فترة العمل بالشركة]]*Table1[[#This Row],[الاجر الخاضع للاشتراك]]/2,((Table1[[#This Row],[فترة العمل بالشركة]]-2.5)*Table1[[#This Row],[الاجر الخاضع للاشتراك]])) -> 4555.7837
A20: 10016 | B20: مارية ابراهيم بن صالح الخضيري | C20: 1118007143 | D20: السعودية | E20: انثى | F20: 2002-10-01 | G20: 4500 | H20: 0 | I20: 0 | J20: 0 | K20: 4500 | L20: 4500 | M20: مندوب مبيعات | N20: 44743 | O20: =YEARFRAC(TODAY(),Table1[[#This Row],[تاريخ الإلتحاق]],1) -> 3.4989733 | P20: =IF(Table1[[#This Row],[فترة العمل بالشركة]]<=5,Table1[[#This Row],[فترة العمل بالشركة]]*21,(((Table1[[#This Row],[فترة العمل بالشركة]]-5)*30)+(5*21))) -> 73.478439 | Q20: ='10016'!E37 -> 34 | R20: =Table1[[#This Row],[رصيد الاجازة المستحق]]-Table1[[#This Row],[رصيد الاجازة المستخدم]] -> 39.478439 | S20: =Table1[[#This Row],[رصيد الاجازة الحالي]]/30*Table1[[#This Row],[إجمالي الأجر]] -> 5921.7659 | T20: =IF(Table1[[#This Row],[فترة العمل بالشركة]]<=5,Table1[[#This Row],[فترة العمل بالشركة]]*Table1[[#This Row],[الاجر الخاضع للاشتراك]]/2,((Table1[[#This Row],[فترة العمل بالشركة]]-2.5)*Table1[[#This Row],[الاجر الخاضع للاشتراك]])) -> 7872.6899
A21: 10017 | B21: PAWAN SINGH BACHI SINGH | C21: 2526368002 | D21: الهند | E21: ذكر | F21: 1998-07-02 | G21: 4500 | H21: 0 | I21: 0 | J21: 0 | K21: 4500 | L21: 4500 | M21: عامل مطبخ | N21: 44812 | O21: =YEARFRAC(TODAY(),Table1[[#This Row],[تاريخ الإلتحاق]],1) -> 3.3100616 | P21: =IF(Table1[[#This Row],[فترة العمل بالشركة]]<=5,Table1[[#This Row],[فترة العمل بالشركة]]*21,(((Table1[[#This Row],[فترة العمل بالشركة]]-5)*30)+(5*21))) -> 69.511294 | Q21: ='10017'!E37 -> 48 | R21: =Table1[[#This Row],[رصيد الاجازة المستحق]]-Table1[[#This Row],[رصيد الاجازة المستخدم]] -> 21.511294 | S21: =Table1[[#This Row],[رصيد الاجازة الحالي]]/30*Table1[[#This Row],[إجمالي الأجر]] -> 3226.694 | T21: =IF(Table1[[#This Row],[فترة العمل بالشركة]]<=5,Table1[[#This Row],[فترة العمل بالشركة]]*Table1[[#This Row],[الاجر الخاضع للاشتراك]]/2,((Table1[[#This Row],[فترة العمل بالشركة]]-2.5)*Table1[[#This Row],[الاجر الخاضع للاشتراك]])) -> 7447.6386
A22: 10018 | B22: MD MONIR HOSEN | C22: 2520396314 | D22: بنغلادش | E22: ذكر | F22: 2000-01-01 | G22: 2000 | H22: 0 | I22: 0 | J22: 0 | K22: 2000 | L22: 2000 | M22: عامل تنظيف مكاتب ومنشآت | N22: 44848 | O22: =YEARFRAC(TODAY(),Table1[[#This Row],[تاريخ الإلتحاق]],1) -> 3.211499 | P22: =IF(Table1[[#This Row],[فترة العمل بالشركة]]<=5,Table1[[#This Row],[فترة العمل بالشركة]]*21,(((Table1[[#This Row],[فترة العمل بالشركة]]-5)*30)+(5*21))) -> 67.441478 | Q22: ='10018'!E37 -> 54 | R22: =Table1[[#This Row],[رصيد الاجازة المستحق]]-Table1[[#This Row],[رصيد الاجازة المستخدم]] -> 13.441478 | S22: =Table1[[#This Row],[رصيد الاجازة الحالي]]/30*Table1[[#This Row],[إجمالي الأجر]] -> 896.09856 | T22: =IF(Table1[[#This Row],[فترة العمل بالشركة]]<=5,Table1[[#This Row],[فترة العمل بالشركة]]*Table1[[#This Row],[الاجر الخاضع للاشتراك]]/2,((Table1[[#This Row],[فترة العمل بالشركة]]-2.5)*Table1[[#This Row],[الاجر الخاضع للاشتراك]])) -> 3211.499
A23: 10019 | B23: FAKHRUL ISLAM | C23: 2520488384 | D23: بنغلادش | E23: ذكر | F23: 1986-05-04 | G23: 1500 | H23: 0 | I23: 0 | J23: 0 | K23: 1500 | L23: 1500 | M23: عامل مطبخ | N23: 44848 | O23: =YEARFRAC(TODAY(),Table1[[#This Row],[تاريخ الإلتحاق]],1) -> 3.211499 | P23: =IF(Table1[[#This Row],[فترة العمل بالشركة]]<=5,Table1[[#This Row],[فترة العمل بالشركة]]*21,(((Table1[[#This Row],[فترة العمل بالشركة]]-5)*30)+(5*21))) -> 67.441478 | Q23: ='10019'!E37 -> 46 | R23: =Table1[[#This Row],[رصيد الاجازة المستحق]]-Table1[[#This Row],[رصيد الاجازة المستخدم]] -> 21.441478 | S23: =Table1[[#This Row],[رصيد الاجازة الحالي]]/30*Table1[[#This Row],[إجمالي الأجر]] -> 1072.0739 | T23: =IF(Table1[[#This Row],[فترة العمل بالشركة]]<=5,Table1[[#This Row],[فترة العمل بالشركة]]*Table1[[#This Row],[الاجر الخاضع للاشتراك]]/2,((Table1[[#This Row],[فترة العمل بالشركة]]-2.5)*Table1[[#This Row],[الاجر الخاضع للاشتراك]])) -> 2408.6242
A24: 10020 | B24: حمد دفع الله حمد على | C24: 2470286960 | D24: السودان | E24: ذكر | F24: 1994-10-19 | G24: 3500 | H24: 0 | I24: 0 | J24: 0 | K24: 3500 | L24: 3500 | M24: عامل مطبخ | N24: 44857 | O24: =YEARFRAC(TODAY(),Table1[[#This Row],[تاريخ الإلتحاق]],1) -> 3.1868583 | P24: =IF(Table1[[#This Row],[فترة العمل بالشركة]]<=5,Table1[[#This Row],[فترة العمل بالشركة]]*21,(((Table1[[#This Row],[فترة العمل بالشركة]]-5)*30)+(5*21))) -> 66.924025 | Q24: ='10020'!E37 -> 46 | R24: =Table1[[#This Row],[رصيد الاجازة المستحق]]-Table1[[#This Row],[رصيد الاجازة المستخدم]] -> 20.924025 | S24: =Table1[[#This Row],[رصيد الاجازة الحالي]]/30*Table1[[#This Row],[إجمالي الأجر]] -> 2441.1362 | T24: =IF(Table1[[#This Row],[فترة العمل بالشركة]]<=5,Table1[[#This Row],[فترة العمل بالشركة]]*Table1[[#This Row],[الاجر الخاضع للاشتراك]]/2,((Table1[[#This Row],[فترة العمل بالشركة]]-2.5)*Table1[[#This Row],[الاجر الخاضع للاشتراك]])) -> 5577.0021
A25: 10021 | B25: شادي عبدالكافي محسن عبدالله | C25: 2531089973 | D25: اليمن | E25: ذكر | F25: 1995-05-05 | G25: 3000 | H25: 0 | I25: 0 | J25: 0 | K25: 3000 | L25: 3000 | M25: عامل عادي | N25: 44955 | O25: =YEARFRAC(TODAY(),Table1[[#This Row],[تاريخ الإلتحاق]],1) -> 2.9178832 | P25: =IF(Table1[[#This Row],[فترة العمل بالشركة]]<=5,Table1[[#This Row],[فترة العمل بالشركة]]*21,(((Table1[[#This Row],[فترة العمل بالشركة]]-5)*30)+(5*21))) -> 61.275547 | Q25: ='10021'!E37 -> 40 | R25: =Table1[[#This Row],[رصيد الاجازة المستحق]]-Table1[[#This Row],[رصيد الاجازة المستخدم]] -> 21.275547 | S25: =Table1[[#This Row],[رصيد الاجازة الحالي]]/30*Table1[[#This Row],[إجمالي الأجر]] -> 2127.5547 | T25: =IF(Table1[[#This Row],[فترة العمل بالشركة]]<=5,Table1[[#This Row],[فترة العمل بالشركة]]*Table1[[#This Row],[الاجر الخاضع للاشتراك]]/2,((Table1[[#This Row],[فترة العمل بالشركة]]-2.5)*Table1[[#This Row],[الاجر الخاضع للاشتراك]])) -> 4376.8248
A26: 10022 | B26: صادق امين محمد شملان | C26: 2518243080 | D26: اليمن | E26: ذكر | F26: 1997-01-18 | G26: 2300 | H26: 0 | I26: 0 | J26: 0 | K26: 2300 | L26: 2300 | M26: سائق شاحنة صغيرة | N26: 44958 | O26: =YEARFRAC(TODAY(),Table1[[#This Row],[تاريخ الإلتحاق]],1) -> 2.9096715 | P26: =IF(Table1[[#This Row],[فترة العمل بالشركة]]<=5,Table1[[#This Row],[فترة العمل بالشركة]]*21,(((Table1[[#This Row],[فترة العمل بالشركة]]-5)*30)+(5*21))) -> 61.103102 | Q26: ='10022'!E37 -> 47 | R26: =Table1[[#This Row],[رصيد الاجازة المستحق]]-Table1[[#This Row],[رصيد الاجازة المستخدم]] -> 14.103102 | S26: =Table1[[#This Row],[رصيد الاجازة الحالي]]/30*Table1[[#This Row],[إجمالي الأجر]] -> 1081.2378 | T26: =IF(Table1[[#This Row],[فترة العمل بالشركة]]<=5,Table1[[#This Row],[فترة العمل بالشركة]]*Table1[[#This Row],[الاجر الخاضع للاشتراك]]/2,((Table1[[#This Row],[فترة العمل بالشركة]]-2.5)*Table1[[#This Row],[الاجر الخاضع للاشتراك]])) -> 3346.1223
A27: 10023 | B27: MD MEHEDI HASAN | C27: 2520488889 | D27: بنغلادش | E27: ذكر | F27: 2000-01-01 | G27: 1500 | H27: 0 | I27: 0 | J27: 0 | K27: 1500 | L27: 1500 | M27: عامل مطبخ | N27: 44991 | O27: =YEARFRAC(TODAY(),Table1[[#This Row],[تاريخ الإلتحاق]],1) -> 2.8193431 | P27: =IF(Table1[[#This Row],[فترة العمل بالشركة]]<=5,Table1[[#This Row],[فترة العمل بالشركة]]*21,(((Table1[[#This Row],[فترة العمل بالشركة]]-5)*30)+(5*21))) -> 59.206204 | Q27: ='10023'!E37 -> 38 | R27: =Table1[[#This Row],[رصيد الاجازة المستحق]]-Table1[[#This Row],[رصيد الاجازة المستخدم]] -> 21.206204 | S27: =Table1[[#This Row],[رصيد الاجازة الحالي]]/30*Table1[[#This Row],[إجمالي الأجر]] -> 1060.3102 | T27: =IF(Table1[[#This Row],[فترة العمل بالشركة]]<=5,Table1[[#This Row],[فترة العمل بالشركة]]*Table1[[#This Row],[الاجر الخاضع للاشتراك]]/2,((Table1[[#This Row],[فترة العمل بالشركة]]-2.5)*Table1[[#This Row],[الاجر الخاضع للاشتراك]])) -> 2114.5073
A28: 10024 | B28: عبدالرحمن خالد عبدالله القعيد | C28: 1119578480 | D28: السعودية | E28: ذكر | F28: 2003-02-27 | G28: 4000 | H28: 0 | I28: 0 | J28: 0 | K28: 4000 | L28: 4000 | M28: مشرف مدخلي البيانات | N28: 45004 | O28: =YEARFRAC(TODAY(),Table1[[#This Row],[تاريخ الإلتحاق]],1) -> 2.7837591 | P28: =IF(Table1[[#This Row],[فترة العمل بالشركة]]<=5,Table1[[#This Row],[فترة العمل بالشركة]]*21,(((Table1[[#This Row],[فترة العمل بالشركة]]-5)*30)+(5*21))) -> 58.458942 | Q28: ='10024'!E37 -> 37 | R28: =Table1[[#This Row],[رصيد الاجازة المستحق]]-Table1[[#This Row],[رصيد الاجازة المستخدم]] -> 21.458942 | S28: =Table1[[#This Row],[رصيد الاجازة الحالي]]/30*Table1[[#This Row],[إجمالي الأجر]] -> 2861.1922 | T28: =IF(Table1[[#This Row],[فترة العمل بالشركة]]<=5,Table1[[#This Row],[فترة العمل بالشركة]]*Table1[[#This Row],[الاجر الخاضع للاشتراك]]/2,((Table1[[#This Row],[فترة العمل بالشركة]]-2.5)*Table1[[#This Row],[الاجر الخاضع للاشتراك]])) -> 5567.5182
A29: 10025 | B29: أميره هليل بديع العنزي | C29: 1127393369 | D29: السعودية | E29: انثى | F29: 1992-12-13 | G29: 4000 | H29: 0 | I29: 0 | J29: 0 | K29: 4000 | L29: 4000 | M29: أخصائي خدمة عملاء | N29: 45082 | O29: =YEARFRAC(TODAY(),Table1[[#This Row],[تاريخ الإلتحاق]],1) -> 2.5702555 | P29: =IF(Table1[[#This Row],[فترة العمل بالشركة]]<=5,Table1[[#This Row],[فترة العمل بالشركة]]*21,(((Table1[[#This Row],[فترة العمل بالشركة]]-5)*30)+(5*21))) -> 53.975365 | Q29: ='10025'!E37 -> 33 | R29: =Table1[[#This Row],[رصيد الاجازة المستحق]]-Table1[[#This Row],[رصيد الاجازة المستخدم]] -> 20.975365 | S29: =Table1[[#This Row],[رصيد الاجازة الحالي]]/30*Table1[[#This Row],[إجمالي الأجر]] -> 2796.7153 | T29: =IF(Table1[[#This Row],[فترة العمل بالشركة]]<=5,Table1[[#This Row],[فترة العمل بالشركة]]*Table1[[#This Row],[الاجر الخاضع للاشتراك]]/2,((Table1[[#This Row],[فترة العمل بالشركة]]-2.5)*Table1[[#This Row],[الاجر الخاضع للاشتراك]])) -> 5140.5109
A30: 10026 | B30: حليمه محمد محمد طميحي | C30: 1061612477 | D30: السعودية | E30: انثى | F30: 1977-10-17 | G30: 4000 | H30: 0 | I30: 0 | J30: 0 | K30: 4000 | L30: 4000 | M30: أخصائي خدمة عملاء | N30: 45083 | O30: =YEARFRAC(TODAY(),Table1[[#This Row],[تاريخ الإلتحاق]],1) -> 2.5675182 | P30: =IF(Table1[[#This Row],[فترة العمل بالشركة]]<=5,Table1[[#This Row],[فترة العمل بالشركة]]*21,(((Table1[[#This Row],[فترة العمل بالشركة]]-5)*30)+(5*21))) -> 53.917883 | Q30: ='10026'!E37 -> 32 | R30: =Table1[[#This Row],[رصيد الاجازة المستحق]]-Table1[[#This Row],[رصيد الاجازة المستخدم]] -> 21.917883 | S30: =Table1[[#This Row],[رصيد الاجازة الحالي]]/30*Table1[[#This Row],[إجمالي الأجر]] -> 2922.3844 | T30: =IF(Table1[[#This Row],[فترة العمل بالشركة]]<=5,Table1[[#This Row],[فترة العمل بالشركة]]*Table1[[#This Row],[الاجر الخاضع للاشتراك]]/2,((Table1[[#This Row],[فترة العمل بالشركة]]-2.5)*Table1[[#This Row],[الاجر الخاضع للاشتراك]])) -> 5135.0365
A31: 10027 | B31: رغد علي بن غياض العنزي | C31: 1106594839 | D31: السعودية | E31: انثى | F31: 1999-06-10 | G31: 4000 | H31: 0 | I31: 0 | J31: 0 | K31: 4000 | L31: 4000 | M31: أخصائي خدمة عملاء | N31: 45086 | O31: =YEARFRAC(TODAY(),Table1[[#This Row],[تاريخ الإلتحاق]],1) -> 2.5593066 | P31: =IF(Table1[[#This Row],[فترة العمل بالشركة]]<=5,Table1[[#This Row],[فترة العمل بالشركة]]*21,(((Table1[[#This Row],[فترة العمل بالشركة]]-5)*30)+(5*21))) -> 53.745438 | Q31: ='10027'!E37 -> 32 | R31: =Table1[[#This Row],[رصيد الاجازة المستحق]]-Table1[[#This Row],[رصيد الاجازة المستخدم]] -> 21.745438 | S31: =Table1[[#This Row],[رصيد الاجازة الحالي]]/30*Table1[[#This Row],[إجمالي الأجر]] -> 2899.3917 | T31: =IF(Table1[[#This Row],[فترة العمل بالشركة]]<=5,Table1[[#This Row],[فترة العمل بالشركة]]*Table1[[#This Row],[الاجر الخاضع للاشتراك]]/2,((Table1[[#This Row],[فترة العمل بالشركة]]-2.5)*Table1[[#This Row],[الاجر الخاضع للاشتراك]])) -> 5118.6131
A32: 10028 | B32: رشيد محمد عبدالله قائد الشميري | C32: 2520913530 | D32: اليمن | E32: ذكر | F32: 1982-12-15 | G32: 2600 | H32: 0 | I32: 0 | J32: 0 | K32: 2600 | L32: 2600 | M32: عامل عادي | N32: 45108 | O32: =YEARFRAC(TODAY(),Table1[[#This Row],[تاريخ الإلتحاق]],1) -> 2.4990876 | P32: =IF(Table1[[#This Row],[فترة العمل بالشركة]]<=5,Table1[[#This Row],[فترة العمل بالشركة]]*21,(((Table1[[#This Row],[فترة العمل بالشركة]]-5)*30)+(5*21))) -> 52.480839 | Q32: ='10028'!E37 -> 31 | R32: =Table1[[#This Row],[رصيد الاجازة المستحق]]-Table1[[#This Row],[رصيد الاجازة المستخدم]] -> 21.480839 | S32: =Table1[[#This Row],[رصيد الاجازة الحالي]]/30*Table1[[#This Row],[إجمالي الأجر]] -> 1861.6727 | T32: =IF(Table1[[#This Row],[فترة العمل بالشركة]]<=5,Table1[[#This Row],[فترة العمل بالشركة]]*Table1[[#This Row],[الاجر الخاضع للاشتراك]]/2,((Table1[[#This Row],[فترة العمل بالشركة]]-2.5)*Table1[[#This Row],[الاجر الخاضع للاشتراك]])) -> 3248.8139
A33: 10029 | B33: سامي ابراهيم محمد عبده الشلح | C33: 2462760915 | D33: اليمن | E33: ذكر | F33: 1997-02-19 | G33: 2300 | H33: 0 | I33: 0 | J33: 0 | K33: 2300 | L33: 2300 | M33: سائق شاحنة صغيرة | N33: 45113 | O33: =YEARFRAC(TODAY(),Table1[[#This Row],[تاريخ الإلتحاق]],1) -> 2.4854015 | P33: =IF(Table1[[#This Row],[فترة العمل بالشركة]]<=5,Table1[[#This Row],[فترة العمل بالشركة]]*21,(((Table1[[#This Row],[فترة العمل بالشركة]]-5)*30)+(5*21))) -> 52.193431 | Q33: ='10029'!E37 -> 31 | R33: =Table1[[#This Row],[رصيد الاجازة المستحق]]-Table1[[#This Row],[رصيد الاجازة المستخدم]] -> 21.193431 | S33: =Table1[[#This Row],[رصيد الاجازة الحالي]]/30*Table1[[#This Row],[إجمالي الأجر]] -> 1624.8297 | T33: =IF(Table1[[#This Row],[فترة العمل بالشركة]]<=5,Table1[[#This Row],[فترة العمل بالشركة]]*Table1[[#This Row],[الاجر الخاضع للاشتراك]]/2,((Table1[[#This Row],[فترة العمل بالشركة]]-2.5)*Table1[[#This Row],[الاجر الخاضع للاشتراك]])) -> 2858.2117
A34: 10030 | B34: SAROJIT BISWAS BISWAS | C34: 2554004347 | D34: الهند | E34: ذكر | F34: 1990-09-21 | G34: 2500 | H34: 0 | I34: 0 | J34: 0 | K34: 2500 | L34: 2500 | M34: عامل مطبخ | N34: 45170 | O34: =YEARFRAC(TODAY(),Table1[[#This Row],[تاريخ الإلتحاق]],1) -> 2.3293796 | P34: =IF(Table1[[#This Row],[فترة العمل بالشركة]]<=5,Table1[[#This Row],[فترة العمل بالشركة]]*21,(((Table1[[#This Row],[فترة العمل بالشركة]]-5)*30)+(5*21))) -> 48.916971 | Q34: ='10030'!E37 -> 27 | R34: =Table1[[#This Row],[رصيد الاجازة المستحق]]-Table1[[#This Row],[رصيد الاجازة المستخدم]] -> 21.916971 | S34: =Table1[[#This Row],[رصيد الاجازة الحالي]]/30*Table1[[#This Row],[إجمالي الأجر]] -> 1826.4142 | T34: =IF(Table1[[#This Row],[فترة العمل بالشركة]]<=5,Table1[[#This Row],[فترة العمل بالشركة]]*Table1[[#This Row],[الاجر الخاضع للاشتراك]]/2,((Table1[[#This Row],[فترة العمل بالشركة]]-2.5)*Table1[[#This Row],[الاجر الخاضع للاشتراك]])) -> 2911.7245
A35: 10031 | B35: شروق جهاد بن مقاط العنزي | C35: 1088340854 | D35: السعودية | E35: انثى | F35: 1991-06-12 | G35: 4000 | H35: 0 | I35: 0 | J35: 0 | K35: 4000 | L35: 4000 | M35: أخصائي خدمة عملاء | N35: 45186 | O35: =YEARFRAC(TODAY(),Table1[[#This Row],[تاريخ الإلتحاق]],1) -> 2.2855839 | P35: =IF(Table1[[#This Row],[فترة العمل بالشركة]]<=5,Table1[[#This Row],[فترة العمل بالشركة]]*21,(((Table1[[#This Row],[فترة العمل بالشركة]]-5)*30)+(5*21))) -> 47.997263 | Q35: ='10031'!E37 -> 27 | R35: =Table1[[#This Row],[رصيد الاجازة المستحق]]-Table1[[#This Row],[رصيد الاجازة المستخدم]] -> 20.997263 | S35: =Table1[[#This Row],[رصيد الاجازة الحالي]]/30*Table1[[#This Row],[إجمالي الأجر]] -> 2799.635 | T35: =IF(Table1[[#This Row],[فترة العمل بالشركة]]<=5,Table1[[#This Row],[فترة العمل بالشركة]]*Table1[[#This Row],[الاجر الخاضع للاشتراك]]/2,((Table1[[#This Row],[فترة العمل بالشركة]]-2.5)*Table1[[#This Row],[الاجر الخاضع للاشتراك]])) -> 4571.1679
A36: 10032 | B36: نوره محمد عبدالرحمن القعيد | C36: 1119142683 | D36: السعودية | E36: انثى | F36: 2003-01-11 | G36: 4000 | H36: 0 | I36: 0 | J36: 0 | K36: 4000 | L36: 4000 | M36: أخصائي خدمة عملاء | N36: 45198 | O36: =YEARFRAC(TODAY(),Table1[[#This Row],[تاريخ الإلتحاق]],1) -> 2.2527372 | P36: =IF(Table1[[#This Row],[فترة العمل بالشركة]]<=5,Table1[[#This Row],[فترة العمل بالشركة]]*21,(((Table1[[#This Row],[فترة العمل بالشركة]]-5)*30)+(5*21))) -> 47.307482 | Q36: ='10032'!E37 -> 26 | R36: =Table1[[#This Row],[رصيد الاجازة المستحق]]-Table1[[#This Row],[رصيد الاجازة المستخدم]] -> 21.307482 | S36: =Table1[[#This Row],[رصيد الاجازة الحالي]]/30*Table1[[#This Row],[إجمالي الأجر]] -> 2840.9976 | T36: =IF(Table1[[#This Row],[فترة العمل بالشركة]]<=5,Table1[[#This Row],[فترة العمل بالشركة]]*Table1[[#This Row],[الاجر الخاضع للاشتراك]]/2,((Table1[[#This Row],[فترة العمل بالشركة]]-2.5)*Table1[[#This Row],[الاجر الخاضع للاشتراك]])) -> 4505.4745
A37: 10033 | B37: MD AMRAN HOSSAIN | C37: 2548252242 | D37: بنغلادش | E37: ذكر | F37: 1992-06-05 | G37: 1500 | H37: 0 | I37: 0 | J37: 0 | K37: 1500 | L37: 1500 | M37: عامل تحميل وتنزيل | N37: 45215 | O37: =YEARFRAC(TODAY(),Table1[[#This Row],[تاريخ الإلتحاق]],1) -> 2.2062044 | P37: =IF(Table1[[#This Row],[فترة العمل بالشركة]]<=5,Table1[[#This Row],[فترة العمل بالشركة]]*21,(((Table1[[#This Row],[فترة العمل بالشركة]]-5)*30)+(5*21))) -> 46.330292 | Q37: ='10033'!E37 -> 25 | R37: =Table1[[#This Row],[رصيد الاجازة المستحق]]-Table1[[#This Row],[رصيد الاجازة المستخدم]] -> 21.330292 | S37: =Table1[[#This Row],[رصيد الاجازة الحالي]]/30*Table1[[#This Row],[إجمالي الأجر]] -> 1066.5146 | T37: =IF(Table1[[#This Row],[فترة العمل بالشركة]]<=5,Table1[[#This Row],[فترة العمل بالشركة]]*Table1[[#This Row],[الاجر الخاضع للاشتراك]]/2,((Table1[[#This Row],[فترة العمل بالشركة]]-2.5)*Table1[[#This Row],[الاجر الخاضع للاشتراك]])) -> 1654.6533
A38: 10034 | B38: MAHAMUDUL HASAN | C38: 2548252408 | D38: بنغلادش | E38: ذكر | F38: 1999-10-29 | G38: 1500 | H38: 0 | I38: 0 | J38: 0 | K38: 1500 | L38: 1500 | M38: عامل تحميل وتنزيل | N38: 45250 | O38: =YEARFRAC(TODAY(),Table1[[#This Row],[تاريخ الإلتحاق]],1) -> 2.1104015 | P38: =IF(Table1[[#This Row],[فترة العمل بالشركة]]<=5,Table1[[#This Row],[فترة العمل بالشركة]]*21,(((Table1[[#This Row],[فترة العمل بالشركة]]-5)*30)+(5*21))) -> 44.318431 | Q38: ='10034'!E37 -> 23 | R38: =Table1[[#This Row],[رصيد الاجازة المستحق]]-Table1[[#This Row],[رصيد الاجازة المستخدم]] -> 21.318431 | S38: =Table1[[#This Row],[رصيد الاجازة الحالي]]/30*Table1[[#This Row],[إجمالي الأجر]] -> 1065.9215 | T38: =IF(Table1[[#This Row],[فترة العمل بالشركة]]<=5,Table1[[#This Row],[فترة العمل بالشركة]]*Table1[[#This Row],[الاجر الخاضع للاشتراك]]/2,((Table1[[#This Row],[فترة العمل بالشركة]]-2.5)*Table1[[#This Row],[الاجر الخاضع للاشتراك]])) -> 1582.8011
A39: 10035 | B39: MANOJ SINGH BIHARI | C39: 2555700422 | D39: الهند | E39: ذكر | F39: 1993-02-15 | G39: 1800 | H39: 0 | I39: 0 | J39: 0 | K39: 1800 | L39: 1800 | M39: عامل مطبخ | N39: 45263 | O39: =YEARFRAC(TODAY(),Table1[[#This Row],[تاريخ الإلتحاق]],1) -> 2.0748175 | P39: =IF(Table1[[#This Row],[فترة العمل بالشركة]]<=5,Table1[[#This Row],[فترة العمل بالشركة]]*21,(((Table1[[#This Row],[فترة العمل بالشركة]]-5)*30)+(5*21))) -> 43.571168 | Q39: ='10035'!E37 -> 22 | R39: =Table1[[#This Row],[رصيد الاجازة المستحق]]-Table1[[#This Row],[رصيد الاجازة المستخدم]] -> 21.571168 | S39: =Table1[[#This Row],[رصيد الاجازة الحالي]]/30*Table1[[#This Row],[إجمالي الأجر]] -> 1294.2701 | T39: =IF(Table1[[#This Row],[فترة العمل بالشركة]]<=5,Table1[[#This Row],[فترة العمل بالشركة]]*Table1[[#This Row],[الاجر الخاضع للاشتراك]]/2,((Table1[[#This Row],[فترة العمل بالشركة]]-2.5)*Table1[[#This Row],[الاجر الخاضع للاشتراك]])) -> 1867.3358
A40: 10036 | B40: RUPESH VILAS GAIKWAD | C40: 2555701347 | D40: الهند | E40: ذكر | F40: 1998-12-07 | G40: 2300 | H40: 0 | I40: 0 | J40: 0 | K40: 2300 | L40: 2300 | M40: عامل مطبخ | N40: 45263 | O40: =YEARFRAC(TODAY(),Table1[[#This Row],[تاريخ الإلتحاق]],1) -> 2.0748175 | P40: =IF(Table1[[#This Row],[فترة العمل بالشركة]]<=5,Table1[[#This Row],[فترة العمل بالشركة]]*21,(((Table1[[#This Row],[فترة العمل بالشركة]]-5)*30)+(5*21))) -> 43.571168 | Q40: ='10036'!E37 -> 22 | R40: =Table1[[#This Row],[رصيد الاجازة المستحق]]-Table1[[#This Row],[رصيد الاجازة المستخدم]] -> 21.571168 | S40: =Table1[[#This Row],[رصيد الاجازة الحالي]]/30*Table1[[#This Row],[إجمالي الأجر]] -> 1653.7895 | T40: =IF(Table1[[#This Row],[فترة العمل بالشركة]]<=5,Table1[[#This Row],[فترة العمل بالشركة]]*Table1[[#This Row],[الاجر الخاضع للاشتراك]]/2,((Table1[[#This Row],[فترة العمل بالشركة]]-2.5)*Table1[[#This Row],[الاجر الخاضع للاشتراك]])) -> 2386.0401
A41: 10037 | B41: SATEESH PAL DURGA PRASAD | C41: 2559055146 | D41: الهند | E41: ذكر | F41: 1984-07-10 | G41: 2300 | H41: 0 | I41: 0 | J41: 0 | K41: 2300 | L41: 2300 | M41: عامل مطبخ | N41: 45263 | O41: =YEARFRAC(TODAY(),Table1[[#This Row],[تاريخ الإلتحاق]],1) -> 2.0748175 | P41: =IF(Table1[[#This Row],[فترة العمل بالشركة]]<=5,Table1[[#This Row],[فترة العمل بالشركة]]*21,(((Table1[[#This Row],[فترة العمل بالشركة]]-5)*30)+(5*21))) -> 43.571168 | Q41: ='10037'!E37 -> 22 | R41: =Table1[[#This Row],[رصيد الاجازة المستحق]]-Table1[[#This Row],[رصيد الاجازة المستخدم]] -> 21.571168 | S41: =Table1[[#This Row],[رصيد الاجازة الحالي]]/30*Table1[[#This Row],[إجمالي الأجر]] -> 1653.7895 | T41: =IF(Table1[[#This Row],[فترة العمل بالشركة]]<=5,Table1[[#This Row],[فترة العمل بالشركة]]*Table1[[#This Row],[الاجر الخاضع للاشتراك]]/2,((Table1[[#This Row],[فترة العمل بالشركة]]-2.5)*Table1[[#This Row],[الاجر الخاضع للاشتراك]])) -> 2386.0401
...

Sheet 10001
B1: #VALUE!
B2: نموذج احتساب رصيد الاجازات
B3: رقم الموظف | C3: 10001 | E3: مدة العمل | F3: =YEARFRAC(TODAY(),C6,1) -> 7.6659822
B4: الاسم | C4: =VLOOKUP(C3,score,2,FALSE) -> عمر محمد احمد صالح الوايلي | E4: الرصيد المستحق منذ تاريخ التعيين | F4: =IF(F3<=5,F3*21,(((F3-5)*30)+(5*21))) -> 184.97947
B5: المسمى الوظيفي | C5: =VLOOKUP(C3,score,13,FALSE) -> سائق شاحنة صغيرة | E5: الرصيد السنوي المستحق | F5: =IF(F3<=5,21,30) -> 30
B6: تاريخ التعيين | C6: =VLOOKUP(C3,score,14,FALSE) -> 43221 | E6: الرصيد المتبقي حتى اليوم | F6: =F4-E37 -> 19.979466
B8: احتساب رصيد الموظف لتارخ معين
B9: تاريخ بداية الاجازة | C9: 45657 | D9: =YEARFRAC(C9,C6,1) -> 6.6687524 | E9: الرصيد حتى تاريخه | F9: =(IF(D9<=5,D9*21,(((D9-5)*30)+(5*21))))-E37 -> -9.9374267
B10: الاجازات السنوية
B11: # | C11: تاريخ بداية الاجازة | D11: تاريخ نهاية الاجازة | E11: المدة | F11: هل تم صرف تذاكر السفر له
B12: 1 | C12: 44851 | D12: 45016 | E12: =D12-C12 -> 165 | F12: نعم
B13: 2 | E13: =D13-C13 -> 0
B14: 3 | E14: =D14-C14 -> 0
B15: 4 | E15: =D14-C15 -> 0
B16: 5 | E16: =D16-C16 -> 0
B17: 6 | E17: =D17-C17 -> 0
B18: 7 | E18: =D18-C18 -> 0
B19: 8 | E19: =D19-C19 -> 0
B20: 9 | E20: =D20-C20 -> 0
B21: 10 | E21: =D21-C21 -> 0
B22: 11 | E22: =D22-C22 -> 0
B23: 12 | E23: =D23-C23 -> 0
B24: 13 | E24: =D24-C24 -> 0
B25: 14 | E25: =D25-C25 -> 0
B26: 15 | E26: =D26-C26 -> 0
B27: 16 | E27: =D27-C27 -> 0
... B36: 25 | E36: =D36-C36 -> 0
B37: المجموع | E37: =SUM(E12:E36) -> 165
B39: الاجازات الأخرى
B41: # | C41: تاريخ بداية الاجازة | D41: تاريخ نهاية الاجازة | E41: المدة | F41: نوع الاجازة
B42: 1 | C42: 45016 | D42: 45043 | E42: =D42-C42 -> 27
B43: 2 | E43: =D43-C43 -> 0
B44: 3 | E44: =D44-C44 -> 0
B45: 4 | E45: =D45-C45 -> 0
B46: 5 | E46: =D46-C46 -> 0
B47: 6 | E47: =D47-C47 -> 0
B48: 7 | E48: =D48-C48 -> 0
B49: 8 | E49: =D49-C49 -> 0

Sheet 10000
B1: #VALUE!
B2: نموذج احتساب رصيد الاجازات
B3: رقم الموظف | C3: 10000 | E3: مدة العمل | F3: =YEARFRAC(TODAY(),C6,1) -> 8.1703681
B4: الاسم | C4: =VLOOKUP(C3,score,2,FALSE) -> GOLAM NOBI | E4: الرصيد المستحق منذ تاريخ التعيين | F4: =IF(F3<=5,F3*21,(((F3-5)*30)+(5*21))) -> 200.11104
B5: المسمى الوظيفي | C5: =VLOOKUP(C3,score,13,FALSE) -> عامل مطبخ | E5: الرصيد السنوي المستحق | F5: =IF(F3<=5,21,30) -> 30
B6: تاريخ التعيين | C6: =VLOOKUP(C3,score,14,FALSE) -> 43037 | E6: الرصيد المتبقي حتى اليوم | F6: =F4-E37 -> 30.111044
B8: احتساب رصيد الموظف لتارخ معين
B9: تاريخ بداية الاجازة | C9: 45945 | D9: =YEARFRAC(C9,C6,1) -> 7.9622756 | E9: الرصيد حتى تاريخه | F9: =(IF(D9<=5,D9*21,(((D9-5)*30)+(5*21))))-E37 -> 23.868269
B10: الاجازات السنوية
B11: # | C11: تاريخ بداية الاجازة | D11: تاريخ نهاية الاجازة | E11: المدة | F11: هل تم صرف تذاكر السفر له
B12: 1 | C12: 43922 | D12: 44047 | E12: =D12-C12 -> 125 | F12: نعم
B13: 2 | C13: 45139 | D13: 45184 | E13: =D13-C13 -> 45 | F13: نعم
B14: 3 | E14: =D14-C14 -> 0
B15: 4 | E15: =D15-C15 -> 0
B16: 5 | E16: =D16-C16 -> 0
B17: 6 | E17: =D17-C17 -> 0
B18: 7 | E18: =D18-C18 -> 0
B19: 8 | E19: =D19-C19 -> 0
B20: 9 | E20: =D20-C20 -> 0
B21: 10 | E21: =D21-C21 -> 0
B22: 11 | E22: =D22-C22 -> 0
B23: 12 | E23: =D23-C23 -> 0
B24: 13 | E24: =D24-C24 -> 0
B25: 14 | E25: =D25-C25 -> 0
... B36: 25 | E36: =D36-C36 -> 0
B37: المجموع | E37: =SUM(E12:E36) -> 170
B39: الاجازات الأخرى
B41: # | C41: تاريخ بداية الاجازة | D41: تاريخ نهاية الاجازة | E41: المدة | F41: نوع الاجازة
B42: 1 | E42: =D42-C42 -> 0
B43: 2 | E43: =D43-C43 -> 0
B44: 3 | E44: =D44-C44 -> 0
B45: 4 | E45: =D45-C45 -> 0
B46: 5 | E46: =D46-C46 -> 0
B47: 6 | E47: =D47-C47 -> 0
B48: 7 | E48: =D48-C48 -> 0
B49: 8 | E49: =D49-C49 -> 0

Sheet 10002
B1: #VALUE!
B2: نموذج احتساب رصيد الاجازات
B3: رقم الموظف | C3: 10002 | E3: مدة العمل | F3: =YEARFRAC(TODAY(),C6,1) -> 7.211499
B4: الاسم | C4: =VLOOKUP(C3,score,2,FALSE) -> عصام محمد عبده قايد العربي | E4: الرصيد المستحق منذ تاريخ التعيين | F4: =IF(F3<=5,F3*21,(((F3-5)*30)+(5*21))) -> 171.34497
B5: المسمى الوظيفي | C5: =VLOOKUP(C3,score,13,FALSE) -> عامل مطبخ | E5: الرصيد السنوي المستحق | F5: =IF(F3<=5,21,30) -> 30
B6: تاريخ التعيين | C6: =VLOOKUP(C3,score,14,FALSE) -> 43387 | E6: الرصيد المتبقي حتى اليوم | F6: =F4-E37 -> 37.344969
B8: احتساب رصيد الموظف لتارخ معين
B9: تاريخ بداية الاجازة | C9: 45657 | D9: =YEARFRAC(C9,C6,1) -> 6.2143136 | E9: الرصيد حتى تاريخه | F9: =(IF(D9<=5,D9*21,(((D9-5)*30)+(5*21))))-E37 -> 7.4294095
B10: الاجازات السنوية
B11: # | C11: تاريخ بداية الاجازة | D11: تاريخ نهاية الاجازة | E11: المدة | F11: هل تم صرف تذاكر السفر له
B12: 1 | C12: 44992 | D12: 45126 | E12: =D12-C12 -> 134 | F12: نعم
B13: 2 | E13: =D13-C13 -> 0
B14: 3 | E14: =D14-C14 -> 0
B15: 4 | E15: =D15-C15 -> 0
B16: 5 | E16: =D16-C16 -> 0
B17: 6 | E17: =D17-C17 -> 0
B18: 7 | E18: =D18-C18 -> 0
B19: 8 | E19: =D19-C19 -> 0
B20: 9 | E20: =D20-C20 -> 0
B21: 10 | E21: =D21-C21 -> 0
B22: 11 | E22: =D22-C22 -> 0
B23: 12 | E23: =D23-C23 -> 0
B24: 13 | E24: =D24-C24 -> 0
... B36: 25 | E36: =D36-C36 -> 0
B37: المجموع | E37: =SUM(E12:E36) -> 134
B39: الاجازات الأخرى
B41: # | C41: تاريخ بداية الاجازة | D41: تاريخ نهاية الاجازة | E41: المدة | F41: نوع الاجازة
B42: 1 | E42: =D42-C42 -> 0
B43: 2 | E43: =D43-C43 -> 0
B44: 3 | E44: =D44-C44 -> 0
B45: 4 | E45: =D45-C45 -> 0
B46: 5 | E46: =D46-C46 -> 0
B47: 6 | E47: =D47-C47 -> 0
B48: 7 | E48: =D48-C48 -> 0
B49: 8 | E49: =D49-C49 -> 0

Sheet 10003
B1: #VALUE!
B2: نموذج احتساب رصيد الاجازات
B3: رقم الموظف | C3: 10003 | E3: مدة العمل | F3: =YEARFRAC(TODAY(),C6,1) -> 6.9096598
B4: الاسم | C4: =VLOOKUP(C3,score,2,FALSE) -> نشوان صادق محسن عبدالله زعيل | E4: الرصيد المستحق منذ تاريخ التعيين | F4: =IF(F3<=5,F3*21,(((F3-5)*30)+(5*21))) -> 162.28979
B5: المسمى الوظيفي | C5: =VLOOKUP(C3,score,13,FALSE) -> عامل مطبخ | E5: الرصيد السنوي المستحق | F5: =IF(F3<=5,21,30) -> 30
B6: تاريخ التعيين | C6: =VLOOKUP(C3,score,14,FALSE) -> 43497 | E6: الرصيد المتبقي حتى اليوم | F6: =F4-E37 -> 29.289793
B8: احتساب رصيد الموظف لتارخ معين
B9: تاريخ بداية الاجازة | C9: 45657 | D9: =YEARFRAC(C9,C6,1) -> 5.9124088 | E9: الرصيد حتى تاريخه | F9: =(IF(D9<=5,D9*21,(((D9-5)*30)+(5*21))))-E37 -> -0.62773723
B10: الاجازات السنوية
B11: # | C11: تاريخ بداية الاجازة | D11: تاريخ نهاية الاجازة | E11: المدة | F11: هل تم صرف تذاكر السفر له
B12: 1 | C12: 45264 | D12: 45397 | E12: =D12-C12 -> 133 | F12: نعم
B13: 2 | E13: =D13-C13 -> 0
B14: 3 | E14: =D14-C14 -> 0
B15: 4 | E15: =D15-C15 -> 0
B16: 5 | E16: =D16-C16 -> 0
B17: 6 | E17: =D17-C17 -> 0
B18: 7 | E18: =D18-C18 -> 0
B19: 8 | E19: =D19-C19 -> 0
B20: 9 | E20: =D20-C20 -> 0
B21: 10 | E21: =D21-C21 -> 0
B22: 11 | E22: =D22-C22 -> 0
B23: 12 | E23: =D23-C23 -> 0
B24: 13 | E24: =D24-C24 -> 0
... B36: 25 | E36: =D36-C36 -> 0
B37: المجموع | E37: =SUM(E12:E36) -> 133
B39: الاجازات الأخرى
B41: # | C41: تاريخ بداية الاجازة | D41: تاريخ نهاية الاجازة | E41: المدة | F41: نوع الاجازة
B42: 1 | C42: 45397 | D42: 45441 | E42: =D42-C42 -> 44 | F42: غير مدفوعه
B43: 2 | E43: =D43-C43 -> 0
B44: 3 | E44: =D44-C44 -> 0
B45: 4 | E45: =D45-C45 -> 0
B46: 5 | E46: =D46-C46 -> 0
B47: 6 | E47: =D47-C47 -> 0
B48: 7 | E48: =D48-C48 -> 0
B49: 8 | E49: =D49-C49 -> 0

Sheet 10004
B1: #VALUE!
B2: نموذج احتساب رصيد الاجازات
B3: رقم الموظف | C3: 10004 | E3: مدة العمل | F3: =YEARFRAC(TODAY(),C6,1) -> 6.7481424
B4: الاسم | C4: =VLOOKUP(C3,score,2,FALSE) -> MD KAWSAR GOLAM RASUL | E4: الرصيد المستحق منذ تاريخ التعيين | F4: =IF(F3<=5,F3*21,(((F3-5)*30)+(5*21))) -> 157.44427
B5: المسمى الوظيفي | C5: =VLOOKUP(C3,score,13,FALSE) -> عامل مطبخ | E5: الرصيد السنوي المستحق | F5: =IF(F3<=5,21,30) -> 30
B6: تاريخ التعيين | C6: =VLOOKUP(C3,score,14,FALSE) -> 43556 | E6: الرصيد المتبقي حتى اليوم | F6: =F4-E37 -> 28.444271
B8: احتساب رصيد الموظف لتارخ معين
B9: تاريخ بداية الاجازة | C9: 45657 | D9: =YEARFRAC(C9,C6,1) -> 5.7509124 | E9: الرصيد حتى تاريخه | F9: =(IF(D9<=5,D9*21,(((D9-5)*30)+(5*21))))-E37 -> -1.4726277
B10: الاجازات السنوية
B11: # | C11: تاريخ بداية الاجازة | D11: تاريخ نهاية الاجازة | E11: المدة | F11: هل تم صرف تذاكر السفر له
B12: 1 | C12: 45288 | D12: 45417 | E12: =D12-C12 -> 129 | F12: نعم
B13: 2 | E13: =D13-C13 -> 0
B14: 3 | E14: =D14-C14 -> 0
B15: 4 | E15: =D15-C15 -> 0
B16: 5 | E16: =D16-C16 -> 0
B17: 6 | E17: =D17-C17 -> 0
B18: 7 | E18: =D18-C18 -> 0
B19: 8 | E19: =D19-C19 -> 0
B20: 9 | E20: =D20-C20 -> 0
B21: 10 | E21: =D21-C21 -> 0
B22: 11 | E22: =D22-C22 -> 0
B23: 12 | E23: =D23-C23 -> 0
B24: 13 | E24: =D24-C24 -> 0
... B36: 25 | E36: =D36-C36 -> 0
B37: المجموع | E37: =SUM(E12:E36) -> 129
B39: الاجازات الأخرى
B41: # | C41: تاريخ بداية الاجازة | D41: تاريخ نهاية الاجازة | E41: المدة | F41: نوع الاجازة
B42: 1 | C42: 45417 | D42: 45423 | E42: =D42-C42 -> 6 | F42: غير مدفوعه
B43: 2 | E43: =D43-C43 -> 0
B44: 3 | E44: =D44-C44 -> 0
B45: 4 | E45: =D45-C45 -> 0
B46: 5 | E46: =D46-C46 -> 0
B47: 6 | E47: =D47-C47 -> 0
B48: 7 | E48: =D48-C48 -> 0
B49: 8 | E49: =D49-C49 -> 0

Sheet 10005
B1: #VALUE!
B2: نموذج احتساب رصيد الاجازات
B3: رقم الموظف | C3: 10005 | E3: مدة العمل | F3: =YEARFRAC(TODAY(),C6,1) -> 5.2445255
B4: الاسم | C4: =VLOOKUP(C3,score,2,FALSE) -> عيده مدلف مرزوق الجحيشي | E4: الرصيد المستحق منذ تاريخ التعيين | F4: =IF(F3<=5,F3*21,(((F3-5)*30)+(5*21))) -> 112.33577
B5: المسمى الوظيفي | C5: =VLOOKUP(C3,score,13,FALSE) -> مندوب مشتريات | E5: الرصيد السنوي المستحق | F5: =IF(F3<=5,21,30) -> 30
B6: تاريخ التعيين | C6: =VLOOKUP(C3,score,14,FALSE) -> 44105 | E6: الرصيد المتبقي حتى اليوم | F6: =F4-E37 -> 22.335766
B8: احتساب رصيد الموظف لتارخ معين
B9: تاريخ بداية الاجازة | C9: 45657 | D9: =YEARFRAC(C9,C6,1) -> 4.2474001 | E9: الرصيد حتى تاريخه | F9: =(IF(D9<=5,D9*21,(((D9-5)*30)+(5*21))))-E37 -> -0.8045977
B10: الاجازات السنوية
B11: # | C11: تاريخ بداية الاجازة | D11: تاريخ نهاية الاجازة | E11: المدة | F11: هل تم صرف تذاكر السفر له
B12: 1 | C12: 44652 | D12: 44685 | E12: =D12-C12 -> 33
B13: 2 | C13: 45047 | D13: 45068 | E13: =D13-C13 -> 21
B14: 3 | C14: 45597 | D14: 45633 | E14: =D14-C14 -> 36
B15: 4 | E15: =D15-C15 -> 0
B16: 5 | E16: =D16-C16 -> 0
B17: 6 | E17: =D17-C17 -> 0
B18: 7 | E18: =D18-C18 -> 0
B19: 8 | E19: =D19-C19 -> 0
B20: 9 | E20: =D20-C20 -> 0
B21: 10 | E21: =D21-C21 -> 0
B22: 11 | E22: =D22-C22 -> 0
B23: 12 | E23: =D23-C23 -> 0
B24: 13 | E24: =D24-C24 -> 0
B25: 14 | E25: =D25-C25 -> 0
B26: 15 | E26: =D26-C26 -> 0
... B36: 25 | E36: =D36-C36 -> 0
B37: المجموع | E37: =SUM(E12:E36) -> 90
B39: الاجازات الأخرى
B41: # | C41: تاريخ بداية الاجازة | D41: تاريخ نهاية الاجازة | E41: المدة | F41: نوع الاجازة
B42: 1 | E42: =D42-C42 -> 0
B43: 2 | E43: =D43-C43 -> 0
B44: 3 | E44: =D44-C44 -> 0
B45: 4 | E45: =D45-C45 -> 0
B46: 5 | E46: =D46-C46 -> 0
B47: 6 | E47: =D47-C47 -> 0
B48: 7 | E48: =D48-C48 -> 0
B49: 8 | E49: =D49-C49 -> 0

Sheet 10006
B1: #VALUE!
B2: نموذج احتساب رصيد الاجازات
B3: رقم الموظف | C3: 10006 | E3: مدة العمل | F3: =YEARFRAC(TODAY(),C6,1) -> 5.2445255
B4: الاسم | C4: =VLOOKUP(C3,score,2,FALSE) -> هلا خالد عبدالله القعيد | E4: الرصيد المستحق منذ تاريخ التعيين | F4: =IF(F3<=5,F3*21,(((F3-5)*30)+(5*21))) -> 112.33577
B5: المسمى الوظيفي | C5: =VLOOKUP(C3,score,13,FALSE) -> مندوب مشتريات | E5: الرصيد السنوي المستحق | F5: =IF(F3<=5,21,30) -> 30
B6: تاريخ التعيين | C6: =VLOOKUP(C3,score,14,FALSE) -> 44105 | E6: الرصيد المتبقي حتى اليوم | F6: =F4-E37 -> 23.335766
B8: احتساب رصيد الموظف لتارخ معين
B9: تاريخ بداية الاجازة | C9: 45657 | D9: =YEARFRAC(C9,C6,1) -> 4.2474001 | E9: الرصيد حتى تاريخه | F9: =(IF(D9<=5,D9*21,(((D9-5)*30)+(5*21))))-E37 -> 0.1954023
B10: الاجازات السنوية
B11: # | C11: تاريخ بداية الاجازة | D11: تاريخ نهاية الاجازة | E11: المدة | F11: هل تم صرف تذاكر السفر له
B12: 1 | C12: 44652 | D12: 44685 | E12: =D12-C12 -> 33
B13: 2 | C13: 45231 | D13: 45266 | E13: =D13-C13 -> 35
B14: 3 | C14: 45627 | D14: 45648 | E14: =D14-C14 -> 21
B15: 4 | E15: =D15-C15 -> 0
B16: 5 | E16: =D16-C16 -> 0
B17: 6 | E17: =D17-C17 -> 0
B18: 7 | E18: =D18-C18 -> 0
B19: 8 | E19: =D19-C19 -> 0
B20: 9 | E20: =D20-C20 -> 0
B21: 10 | E21: =D21-C21 -> 0
B22: 11 | E22: =D22-C22 -> 0
B23: 12 | E23: =D23-C23 -> 0
B24: 13 | E24: =D24-C24 -> 0
B25: 14 | E25: =D25-C25 -> 0
B26: 15 | E26: =D26-C26 -> 0
... B36: 25 | E36: =D36-C36 -> 0
B37: المجموع | E37: =SUM(E12:E36) -> 89
B39: الاجازات الأخرى
B41: # | C41: تاريخ بداية الاجازة | D41: تاريخ نهاية الاجازة | E41: المدة | F41: نوع الاجازة
B42: 1 | E42: =D42-C42 -> 0
B43: 2 | E43: =D43-C43 -> 0
B44: 3 | E44: =D44-C44 -> 0
B45: 4 | E45: =D45-C45 -> 0
B46: 5 | E46: =D46-C46 -> 0
B47: 6 | E47: =D47-C47 -> 0
B48: 7 | E48: =D48-C48 -> 0
B49: 8 | E49: =D49-C49 -> 0

Sheet 10007
B1: #VALUE!
B2: نموذج احتساب رصيد الاجازات
B3: رقم الموظف | C3: 10007 | E3: مدة العمل | F3: =YEARFRAC(TODAY(),C6,1) -> 4.5372399
B4: الاسم | C4: =VLOOKUP(C3,score,2,FALSE) -> ABDUL KADIR | E4: الرصيد المستحق منذ تاريخ التعيين | F4: =IF(F3<=5,F3*21,(((F3-5)*30)+(5*21))) -> 95.282037
B5: المسمى الوظيفي | C5: =VLOOKUP(C3,score,13,FALSE) -> عامل مطبخ | E5: الرصيد السنوي المستحق | F5: =IF(F3<=5,21,30) -> 21
B6: تاريخ التعيين | C6: =VLOOKUP(C3,score,14,FALSE) -> 44364 | E6: الرصيد المتبقي حتى اليوم | F6: =F4-E37 -> 21.282037
B8: احتساب رصيد الموظف لتارخ معين
B9: تاريخ بداية الاجازة | C9: 45657 | D9: =YEARFRAC(C9,C6,1) -> 3.5400411 | E9: الرصيد حتى تاريخه | F9: =(IF(D9<=5,D9*21,(((D9-5)*30)+(5*21))))-E37 -> 0.34086242
B10: الاجازات السنوية
B11: # | C11: تاريخ بداية الاجازة | D11: تاريخ نهاية الاجازة | E11: المدة | F11: هل تم صرف تذاكر السفر له
B12: 1 | C12: 45506 | D12: 45580 | E12: =D12-C12 -> 74 | F12: نعم
B13: 2 | E13: =D13-C13 -> 0
B14: 3 | E14: =D14-C14 -> 0
B15: 4 | E15: =D15-C15 -> 0
B16: 5 | E16: =D16-C16 -> 0
B17: 6 | E17: =D17-C17 -> 0
B18: 7 | E18: =D18-C18 -> 0
B19: 8 | E19: =D19-C19 -> 0
B20: 9 | E20: =D20-C20 -> 0
B21: 10 | E21: =D21-C21 -> 0
B22: 11 | E22: =D22-C22 -> 0
B23: 12 | E23: =D23-C23 -> 0
B24: 13 | E24: =D24-C24 -> 0
... B36: 25 | E36: =D36-C36 -> 0
B37: المجموع | E37: =SUM(E12:E36) -> 74
B39: الاجازات الأخرى
B41: # | C41: تاريخ بداية الاجازة | D41: تاريخ نهاية الاجازة | E41: المدة | F41: نوع الاجازة
B42: 1 | C42: 45580 | D42: 45591 | E42: =D42-C42 -> 11 | F42: غير مدفوعه
B43: 2 | E43: =D43-C43 -> 0
B44: 3 | E44: =D44-C44 -> 0
B45: 4 | E45: =D45-C45 -> 0
B46: 5 | E46: =D46-C46 -> 0
B47: 6 | E47: =D47-C47 -> 0
B48: 7 | E48: =D48-C48 -> 0
B49: 8 | E49: =D49-C49 -> 0

Sheet 10008
B1: #VALUE!
B2: نموذج احتساب رصيد الاجازات
B3: رقم الموظف | C3: 10008 | E3: مدة العمل | F3: =YEARFRAC(TODAY(),C6,1) -> 4.5372399
B4: الاسم | C4: =VLOOKUP(C3,score,2,FALSE) -> MONIR HOSSAIN | E4: الرصيد المستحق منذ تاريخ التعيين | F4: =IF(F3<=5,F3*21,(((F3-5)*30)+(5*21))) -> 95.282037
B5: المسمى الوظيفي | C5: =VLOOKUP(C3,score,13,FALSE) -> عامل مطبخ | E5: الرصيد السنوي المستحق | F5: =IF(F3<=5,21,30) -> 21
B6: تاريخ التعيين | C6: =VLOOKUP(C3,score,14,FALSE) -> 44364 | E6: الرصيد المتبقي حتى اليوم | F6: =F4-E37 -> 21.282037
B8: احتساب رصيد الموظف لتارخ معين
B9: تاريخ بداية الاجازة | C9: 45657 | D9: =YEARFRAC(C9,C6,1) -> 3.5400411 | E9: الرصيد حتى تاريخه | F9: =(IF(D9<=5,D9*21,(((D9-5)*30)+(5*21))))-E37 -> 0.34086242
B10: الاجازات السنوية
B11: # | C11: تاريخ بداية الاجازة | D11: تاريخ نهاية الاجازة | E11: المدة | F11: هل تم صرف تذاكر السفر له
B12: 1 | C12: 44835 | D12: 44859 | E12: =D12-C12 -> 24 | F12: نعم
B13: 2 | C13: 45261 | D13: 45290 | E13: =D13-C13 -> 29 | F13: نعم
B14: 3 | C14: 45627 | D14: 45648 | E14: =D14-C14 -> 21 | F14: نعم
B15: 4 | E15: =D15-C15 -> 0
B16: 5 | E16: =D16-C16 -> 0
B17: 6 | E17: =D17-C17 -> 0
B18: 7 | E18: =D18-C18 -> 0
B19: 8 | E19: =D19-C19 -> 0
B20: 9 | E20: =D20-C20 -> 0
B21: 10 | E21: =D21-C21 -> 0
B22: 11 | E22: =D22-C22 -> 0
B23: 12 | E23: =D23-C23 -> 0
B24: 13 | E24: =D24-C24 -> 0
B25: 14 | E25: =D25-C25 -> 0
B26: 15 | E26: =D26-C26 -> 0
... B36: 25 | E36: =D36-C36 -> 0
B37: المجموع | E37: =SUM(E12:E36) -> 74
B39: الاجازات الأخرى
B41: # | C41: تاريخ بداية الاجازة | D41: تاريخ نهاية الاجازة | E41: المدة | F41: نوع الاجازة
B42: 1 | E42: =D42-C42 -> 0
B43: 2 | E43: =D43-C43 -> 0
B44: 3 | E44: =D44-C44 -> 0
B45: 4 | E45: =D45-C45 -> 0
B46: 5 | E46: =D46-C46 -> 0
B47: 6 | E47: =D47-C47 -> 0
B48: 7 | E48: =D48-C48 -> 0
B49: 8 | E49: =D49-C49 -> 0

Sheet 10009
B1: #VALUE!
B2: نموذج احتساب رصيد الاجازات
B3: رقم الموظف | C3: 10009 | E3: مدة العمل | F3: =YEARFRAC(TODAY(),C6,1) -> 3.8329911
B4: الاسم | C4: =VLOOKUP(C3,score,2,FALSE) -> فاطمه عليان بن ثواب الحربي | E4: الرصيد المستحق منذ تاريخ التعيين | F4: =IF(F3<=5,F3*21,(((F3-5)*30)+(5*21))) -> 80.492813
B5: المسمى الوظيفي | C5: =VLOOKUP(C3,score,13,FALSE) -> أخصائي تسويق | E5: الرصيد السنوي المستحق | F5: =IF(F3<=5,21,30) -> 21
B6: تاريخ التعيين | C6: =VLOOKUP(C3,score,14,FALSE) -> 44621 | E6: الرصيد المتبقي حتى اليوم | F6: =F4-E37 -> 40.492813
B8: احتساب رصيد الموظف لتارخ معين
B9: تاريخ بداية الاجازة | C9: 45657 | D9: =YEARFRAC(C9,C6,1) -> 2.8357664 | E9: الرصيد حتى تاريخه | F9: =(IF(D9<=5,D9*21,(((D9-5)*30)+(5*21))))-E37 -> 19.551095
B10: الاجازات السنوية
B11: # | C11: تاريخ بداية الاجازة | D11: تاريخ نهاية الاجازة | E11: المدة | F11: هل تم صرف تذاكر السفر له
B12: 1 | C12: 45089 | D12: 45098 | E12: =D12-C12 -> 9
B13: 2 | C13: 45488 | D13: 45519 | E13: =D13-C13 -> 31
B14: 3 | E14: =D14-C14 -> 0
B15: 4 | E15: =D15-C15 -> 0
B16: 5 | E16: =D16-C16 -> 0
B17: 6 | E17: =D17-C17 -> 0
B18: 7 | E18: =D18-C18 -> 0
B19: 8 | E19: =D19-C19 -> 0
B20: 9 | E20: =D20-C20 -> 0
B21: 10 | E21: =D21-C21 -> 0
B22: 11 | E22: =D22-C22 -> 0
B23: 12 | E23: =D23-C23 -> 0
B24: 13 | E24: =D24-C24 -> 0
B25: 14 | E25: =D25-C25 -> 0
... B36: 25 | E36: =D36-C36 -> 0
B37: المجموع | E37: =SUM(E12:E36) -> 40
B39: الاجازات الأخرى
B41: # | C41: تاريخ بداية الاجازة | D41: تاريخ نهاية الاجازة | E41: المدة | F41: نوع الاجازة
B42: 1 | E42: =D42-C42 -> 0
B43: 2 | E43: =D43-C43 -> 0
B44: 3 | E44: =D44-C44 -> 0
B45: 4 | E45: =D45-C45 -> 0
B46: 5 | E46: =D46-C46 -> 0
B47: 6 | E47: =D47-C47 -> 0
B48: 7 | E48: =D48-C48 -> 0
B49: 8 | E49: =D49-C49 -> 0

Sheet 10011
B1: #VALUE!
B2: نموذج احتساب رصيد الاجازات
B3: رقم الموظف | C3: 10011 | E3: مدة العمل | F3: =YEARFRAC(TODAY(),C6,1) -> 3.8138261
B4: الاسم | C4: =VLOOKUP(C3,score,2,FALSE) -> أديب محمد سعيد عبدالصفي | E4: الرصيد المستحق منذ تاريخ التعيين | F4: =IF(F3<=5,F3*21,(((F3-5)*30)+(5*21))) -> 80.090349
B5: المسمى الوظيفي | C5: =VLOOKUP(C3,score,13,FALSE) -> عامل عادي | E5: الرصيد السنوي المستحق | F5: =IF(F3<=5,21,30) -> 21
B6: تاريخ التعيين | C6: =VLOOKUP(C3,score,14,FALSE) -> 44628 | E6: الرصيد المتبقي حتى اليوم | F6: =F4-E37 -> 25.090349
B8: احتساب رصيد الموظف لتارخ معين
B9: تاريخ بداية الاجازة | C9: 45657 | D9: =YEARFRAC(C9,C6,1) -> 2.8166058 | E9: الرصيد حتى تاريخه | F9: =(IF(D9<=5,D9*21,(((D9-5)*30)+(5*21))))-E37 -> 4.1487226
B10: الاجازات السنوية
B11: # | C11: تاريخ بداية الاجازة | D11: تاريخ نهاية الاجازة | E11: المدة | F11: هل تم صرف تذاكر السفر له
B12: 1 | C12: 45162 | D12: 45171 | E12: =D12-C12 -> 9 | F12: نعم
B13: 2 | C13: 45516 | D13: 45562 | E13: =D13-C13 -> 46 | F13: نعم
B14: 3 | E14: =D14-C14 -> 0
B15: 4 | E15: =D15-C15 -> 0
B16: 5 | E16: =D16-C16 -> 0
B17: 6 | E17: =D17-C17 -> 0
B18: 7 | E18: =D18-C18 -> 0
B19: 8 | E19: =D19-C19 -> 0
B20: 9 | E20: =D20-C20 -> 0
B21: 10 | E21: =D21-C21 -> 0
B22: 11 | E22: =D22-C22 -> 0
B23: 12 | E23: =D23-C23 -> 0
B24: 13 | E24: =D24-C24 -> 0
B25: 14 | E25: =D25-C25 -> 0
... B36: 25 | E36: =D36-C36 -> 0
B37: المجموع | E37: =SUM(E12:E36) -> 55
B39: الاجازات الأخرى
B41: # | C41: تاريخ بداية الاجازة | D41: تاريخ نهاية الاجازة | E41: المدة | F41: نوع الاجازة
B42: 1 | E42: =D42-C42 -> 0
B43: 2 | E43: =D43-C43 -> 0
B44: 3 | E44: =D44-C44 -> 0
B45: 4 | E45: =D45-C45 -> 0
B46: 5 | E46: =D46-C46 -> 0
B47: 6 | E47: =D47-C47 -> 0
B48: 7 | E48: =D48-C48 -> 0
B49: 8 | E49: =D49-C49 -> 0

Sheet 10010
B1: #VALUE!
B2: نموذج احتساب رصيد الاجازات
B3: رقم الموظف | C3: 10010 | E3: مدة العمل | F3: =YEARFRAC(TODAY(),C6,1) -> 3.8329911
B4: الاسم | C4: =VLOOKUP(C3,score,2,FALSE) -> ساره صالح مطلق الراكضي | E4: الرصيد المستحق منذ تاريخ التعيين | F4: =IF(F3<=5,F3*21,(((F3-5)*30)+(5*21))) -> 80.492813
B5: المسمى الوظيفي | C5: =VLOOKUP(C3,score,13,FALSE) -> أخصائي تسويق | E5: الرصيد السنوي المستحق | F5: =IF(F3<=5,21,30) -> 21
B6: تاريخ التعيين | C6: =VLOOKUP(C3,score,14,FALSE) -> 44621 | E6: الرصيد المتبقي حتى اليوم | F6: =F4-E37 -> 35.492813
B8: احتساب رصيد الموظف لتارخ معين
B9: تاريخ بداية الاجازة | C9: 45657 | D9: =YEARFRAC(C9,C6,1) -> 2.8357664 | E9: الرصيد حتى تاريخه | F9: =(IF(D9<=5,D9*21,(((D9-5)*30)+(5*21))))-E37 -> 14.551095
B10: الاجازات السنوية
B11: # | C11: تاريخ بداية الاجازة | D11: تاريخ نهاية الاجازة | E11: المدة | F11: هل تم صرف تذاكر السفر له
B12: 1 | C12: 45569 | D12: 45571 | E12: =D12-C12 -> 2
B13: 2 | C13: 45308 | D13: 45311 | E13: =D13-C13 -> 3
B14: 3 | C14: 45455 | D14: 45494 | E14: =D14-C14 -> 39
B15: 4 | C15: 45609 | D15: 45610 | E15: =D15-C15 -> 1
B16: 5 | E16: =D16-C16 -> 0
B17: 6 | E17: =D17-C17 -> 0
B18: 7 | E18: =D18-C18 -> 0
B19: 8 | E19: =D19-C19 -> 0
B20: 9 | E20: =D20-C20 -> 0
B21: 10 | E21: =D21-C21 -> 0
B22: 11 | E22: =D22-C22 -> 0
B23: 12 | E23: =D23-C23 -> 0
B24: 13 | E24: =D24-C24 -> 0
B25: 14 | E25: =D25-C25 -> 0
B26: 15 | E26: =D26-C26 -> 0
B27: 16 | E27: =D27-C27 -> 0
... B36: 25 | E36: =D36-C36 -> 0
B37: المجموع | E37: =SUM(E12:E36) -> 45
B39: الاجازات الأخرى
B41: # | C41: تاريخ بداية الاجازة | D41: تاريخ نهاية الاجازة | E41: المدة | F41: نوع الاجازة
B42: 1 | E42: =D42-C42 -> 0
B43: 2 | E43: =D43-C43 -> 0
B44: 3 | E44: =D44-C44 -> 0
B45: 4 | E45: =D45-C45 -> 0
B46: 5 | E46: =D46-C46 -> 0
B47: 6 | E47: =D47-C47 -> 0
B48: 7 | E48: =D48-C48 -> 0
B49: 8 | E49: =D49-C49 -> 0

Sheet 10012
B1: #VALUE!
B2: نموذج احتساب رصيد الاجازات
B3: رقم الموظف | C3: 10012 | E3: مدة العمل | F3: =YEARFRAC(TODAY(),C6,1) -> 3.8110883
B4: الاسم | C4: =VLOOKUP(C3,score,2,FALSE) -> MO AKRAM HASIN | E4: الرصيد المستحق منذ تاريخ التعيين | F4: =IF(F3<=5,F3*21,(((F3-5)*30)+(5*21))) -> 80.032854
B5: المسمى الوظيفي | C5: =VLOOKUP(C3,score,13,FALSE) -> عامل مطبخ | E5: الرصيد السنوي المستحق | F5: =IF(F3<=5,21,30) -> 21
