Workbook

Sheet تكاليف المنتجات
A1: # | B1: Ingerident Name | C1: اسم المكون | D1: التكلفة قبل الضريبة (للمصفى) | F1: الصافي | G1: المصفى | H1: اسم الوصفة | J1: اوصال لحم بيستو | M1: كباب لحم | P1: شيش طاووق | S1: كباب دجاج | V1: حمسة لحم | Y1: دجاج فاهيتا | AB1: لبنة مع خضار | AE1: مصقعة باذنجان | AH1: تبولة | AK1: فتوش | AN1: بابا غنوج | AQ1: ورق عنب | AT1: ملفوف محشي | AW1: حمص كلاسيك | AZ1: حمص بيستو | BC1: متبل باذنجان | BF1: متبل خضار مشوية | BI1: ارز الزعفران | BL1: ذرة مشوية | BO1: كبة مقلية | BR1: زهرة مقلية | BU1: بطاطا حارة | BX1: بطاطا مشوية بالاعشاب | CA1: حمص لحم | CD1: صلصة ثوم | CG1: صلصة طحينة | CJ1: صلصة الجبنة | CM1: صلصة الزبادي | CP1: صلصة المايونيز الحارة | CS1: متبل محضر 1 كيلو | CV1: بيستو صوص 1 كيلو | CY1: حمص محضر 1 كيلو | DB1: خضار مشوية 1 كيلو | DE1: صوص فتوش | DH1: ذرة محضر 1 كيلو | DK1: صلصة طماطم محضرة
H2: التكلفة قبل الضريبة | J2: =SUM(K10:K142) -> 9.6924351 | M2: =SUM(N10:N142) -> 7.46828 | P2: =SUM(Q10:Q142) -> 4.1725675 | S2: =SUM(T10:T142) -> 5.0339158 | V2: =SUM(W10:W142) -> 6.633786 | Y2: =SUM(Z10:Z142) -> 4.2958416 | AB2: =SUM(AC10:AC142) -> 3.6889196 | AE2: =SUM(AF10:AF142) -> 2.87723 | AH2: =SUM(AI10:AI142) -> 1.1374836 | AK2: =SUM(AL10:AL142) -> 2.4518189 | AN2: =SUM(AO10:AO142) -> 4.0902399 | AQ2: =SUM(AR10:AR142) -> 4.3667579 | AT2: =SUM(AU10:AU142) -> 1.3528911 | AW2: =SUM(AX10:AX142) -> 2.1891231 | AZ2: =SUM(BA10:BA142) -> 3.9314167 | BC2: =SUM(BD10:BD142) -> 1.4439199 | BF2: =SUM(BG10:BG142) -> 3.0536774 | BI2: =SUM(BJ10:BJ142) -> 3.4456422 | BL2: =SUM(BM10:BM142) -> 1.3607709 | BO2: =SUM(BP10:BP142) -> 2.2973438 | BR2: =SUM(BS10:BS142) -> 3.6220431 | BU2: =SUM(BV10:BV142) -> 3.3522781 | BX2: =SUM(BY10:BY142) -> 1.8655869 | CA2: =SUM(CB10:CB142) -> 3.5869224 | CD2: =SUM(CE10:CE142) -> 0.26805875 | CG2: =SUM(CH10:CH142) -> 0.20513913 | CJ2: =SUM(CK10:CK142) -> 0.38352 | CM2: =SUM(CN10:CN142) -> 0.15968624 | CP2: =SUM(CQ10:CQ142) -> 0.16961198 | CS2: =SUM(CT10:CT142) -> 3.6376204 | CV2: =SUM(CW10:CW142) -> 60.350604 | CY2: =SUM(CZ10:CZ142) -> 4.8729168 | DB2: =SUM(DC10:DC192) -> 1.6099501 | DE2: =SUM(DF10:DF142) -> 0.20685852 | DH2: =SUM(DI10:DI142) -> 2.7179764 | DK2: =SUM(DL10:DL142) -> 2.5342246
H3: تكلفة التوصيل | J3: =18%*J5 -> 6.48 | M3: =18%*M5 -> 5.22 | P3: =18%*P5 -> 4.86 | S3: =18%*S5 -> 4.86 | V3: =18%*V5 -> 4.14 | Y3: =18%*Y5 -> 3.78 | AB3: =18%*AB5 -> 3.78 | AE3: =18%*AE5 -> 4.14 | AH3: =18%*AH5 -> 2.16 | AK3: =18%*AK5 -> 2.16 | AN3: =18%*AN5 -> 2.7 | AQ3: =18%*AQ5 -> 2.88 | AT3: =18%*AT5 -> 2.88 | AW3: =18%*AW5 -> 2.16 | AZ3: =18%*AZ5 -> 2.16 | BC3: =18%*BC5 -> 2.16 | BF3: =18%*BF5 -> 2.16 | BI3: =18%*BI5 -> 2.16 | BL3: =18%*BL5 -> 2.16 | BO3: =18%*BO5 -> 2.16 | BR3: =18%*BR5 -> 2.16 | BU3: =18%*BU5 -> 2.16 | BX3: =18%*BX5 -> 2.16 | CA3: =18%*CA5 -> 2.88 | CD3: =18%*CD5 -> 0.36 | CG3: =18%*CG5 -> 0.36 | CJ3: =18%*CJ5 -> 0.36 | CM3: =18%*CM5 -> 0.36 | CP3: =18%*CP5 -> 0.36 | CS3: =18%*CS2 -> 0.65477166 | CV3: =18%*CV2 -> 10.863109 | CY3: =18%*CY2 -> 0.87712503 | DB3: =18%*DB2 -> 0.28979101 | DE3: =18%*DE2 -> 0.037234533 | DH3: =18%*DH2 -> 0.48923575 | DK3: =18%*DK2 -> 0.45616043
H4: التكلفة الكلية | J4: =J2+J3 -> 16.172435 | M4: =M2+M3 -> 12.68828 | P4: =P2+P3 -> 9.0325675 | S4: =S2+S3 -> 9.8939158 | V4: =V2+V3 -> 10.773786 | Y4: =Y2+Y3 -> 8.0758416 | AB4: =AB2+AB3 -> 7.4689196 | AE4: =AE2+AE3 -> 7.01723 | AH4: =AH2+AH3 -> 3.2974836 | AK4: =AK2+AK3 -> 4.6118189 | AN4: =AN2+AN3 -> 6.7902399 | AQ4: =AQ2+AQ3 -> 7.2467579 | AT4: =AT2+AT3 -> 4.2328911 | AW4: =AW2+AW3 -> 4.3491231 | AZ4: =AZ2+AZ3 -> 6.0914167 | BC4: =BC2+BC3 -> 3.6039199 | BF4: =BF2+BF3 -> 5.2136774 | BI4: =BI2+BI3 -> 5.6056422 | BL4: =BL2+BL3 -> 3.5207709 | BO4: =BO2+BO3 -> 4.4573438 | BR4: =BR2+BR3 -> 5.7820431 | BU4: =BU2+BU3 -> 5.5122781 | BX4: =BX2+BX3 -> 4.0255869 | CA4: =CA2+CA3 -> 6.4669224 | CD4: =CD2+CD3 -> 0.62805875 | CG4: =CG2+CG3 -> 0.56513913 | CJ4: =CJ2+CJ3 -> 0.74352 | CM4: =CM2+CM3 -> 0.51968624 | CP4: =CP2+CP3 -> 0.52961198 | CS4: =CS2+CS3 -> 4.292392 | CV4: =CV2+CV3 -> 71.213712 | CY4: =CY2+CY3 -> 5.7500419 | DB4: =DB2+DB3 -> 1.8997411 | DE4: =DE2+DE3 -> 0.24409305 | DH4: =DH2+DH3 -> 3.2072122 | DK4: =DK2+DK3 -> 2.990385
H5: البيع شامل الضريبة | J5: 36 | M5: 29 | P5: 27 | S5: 27 | V5: 23 | Y5: 21 | AB5: 21 | AE5: 23 | AH5: 12 | AK5: 12 | AN5: 15 | AQ5: 16 | AT5: 16 | AW5: 12 | AZ5: 12 | BC5: 12 | BF5: 12 | BI5: 12 | BL5: 12 | BO5: 12 | BR5: 12 | BU5: 12 | BX5: 12 | CA5: 16 | CD5: 2 | CG5: 2 | CJ5: 2 | CM5: 2 | CP5: 2 | CS5: 10 | CV5: 2 | CY5: 2 | DB5: 2 | DE5: 2 | DH5: 2 | DK5: 2
E6: =1.1+0.21+0.236 -> 1.546 | H6: الضريبة | J6: =J5-J5/1.15 -> 4.6956522 | M6: =M5-M5/1.15 -> 3.7826087 | P6: =P5-P5/1.15 -> 3.5217391 | S6: =S5-S5/1.15 -> 3.5217391 | V6: =V5-V5/1.15 -> 3 | Y6: =Y5-Y5/1.15 -> 2.7391304 | AB6: =AB5-AB5/1.15 -> 2.7391304 | AE6: =AE5-AE5/1.15 -> 3 | AH6: =AH5-AH5/1.15 -> 1.5652174 | AK6: =AK5-AK5/1.15 -> 1.5652174 | AN6: =AN5-AN5/1.15 -> 1.9565217 | AQ6: =AQ5-AQ5/1.15 -> 2.0869565 | AT6: =AT5-AT5/1.15 -> 2.0869565 | AW6: =AW5-AW5/1.15 -> 1.5652174 | AZ6: =AZ5-AZ5/1.15 -> 1.5652174 | BC6: =BC5-BC5/1.15 -> 1.5652174 | BF6: =BF5-BF5/1.15 -> 1.5652174 | BI6: =BI5-BI5/1.15 -> 1.5652174 | BL6: =BL5-BL5/1.15 -> 1.5652174 | BO6: =BO5-BO5/1.15 -> 1.5652174 | BR6: =BR5-BR5/1.15 -> 1.5652174 | BU6: =BU5-BU5/1.15 -> 1.5652174 | BX6: =BX5-BX5/1.15 -> 1.5652174 | CA6: =CA5-CA5/1.15 -> 2.0869565 | CD6: =CD5-CD5/1.15 -> 0.26086957 | CG6: =CG5-CG5/1.15 -> 0.26086957 | CJ6: =CJ5-CJ5/1.15 -> 0.26086957 | CM6: =CM5-CM5/1.15 -> 0.26086957 | CP6: =CP5-CP5/1.15 -> 0.26086957 | CS6: =CS5-CS5/1.15 -> 1.3043478 | CV6: =CV5-CV5/1.15 -> 0.26086957 | CY6: =CY5-CY5/1.15 -> 0.26086957 | DB6: =DB5-DB5/1.15 -> 0.26086957 | DE6: =DE5-DE5/1.15 -> 0.26086957 | DH6: =DH5-DH5/1.15 -> 0.26086957 | DK6: =DK5-DK5/1.15 -> 0.26086957
H7: الصافي | J7: =J5-J4-J6 -> 15.131913 | M7: =M5-M4-M6 -> 12.529111 | P7: =P5-P4-P6 -> 14.445693 | S7: =S5-S4-S6 -> 13.584345 | V7: =V5-V4-V6 -> 9.226214 | Y7: =Y5-Y4-Y6 -> 10.185028 | AB7: =AB5-AB4-AB6 -> 10.79195 | AE7: =AE5-AE4-AE6 -> 12.98277 | AH7: =AH5-AH4-AH6 -> 7.137299 | AK7: =AK5-AK4-AK6 -> 5.8229637 | AN7: =AN5-AN4-AN6 -> 6.2532384 | AQ7: =AQ5-AQ4-AQ6 -> 6.6662856 | AT7: =AT5-AT4-AT6 -> 9.6801523 | AW7: =AW5-AW4-AW6 -> 6.0856595 | AZ7: =AZ5-AZ4-AZ6 -> 4.3433659 | BC7: =BC5-BC4-BC6 -> 6.8308627 | BF7: =BF5-BF4-BF6 -> 5.2211052 | BI7: =BI5-BI4-BI6 -> 4.8291405 | BL7: =BL5-BL4-BL6 -> 6.9140117 | BO7: =BO5-BO4-BO6 -> 5.9774388 | BR7: =BR5-BR4-BR6 -> 4.6527395 | BU7: =BU5-BU4-BU6 -> 4.9225045 | BX7: =BX5-BX4-BX6 -> 6.4091957 | CA7: =CA5-CA4-CA6 -> 7.4461211 | CD7: =CD5-CD4-CD6 -> 1.1110717 | CG7: =CG5-CG4-CG6 -> 1.1739913 | CJ7: =CJ5-CJ4-CJ6 -> 0.99561043 | CM7: =CM5-CM4-CM6 -> 1.2194442 | CP7: =CP5-CP4-CP6 -> 1.2095185 | CS7: =CS5-CS4-CS6 -> 4.4032602 | CV7: =CV5-CV4-CV6 -> -69.474582 | CY7: =CY5-CY4-CY6 -> -4.0109114 | DB7: =DB5-DB4-DB6 -> -0.16061064 | DE7: =DE5-DE4-DE6 -> 1.4950374 | DH7: =DH5-DH4-DH6 -> -1.4680817 | DK7: =DK5-DK4-DK6 -> -1.2512546
H8: نسبة التكلفة | J8: =J4/(J5-J6) -> 0.51661946 | M8: =M4/(M5-M6) -> 0.50315593 | P8: =P4/(P5-P6) -> 0.38472047 | S8: =S4/(S5-S6) -> 0.42140753 | V8: =V4/(V5-V6) -> 0.5386893 | Y8: =Y4/(Y5-Y6) -> 0.44224847 | AB8: =AB4/(AB5-AB6) -> 0.40901226 | AE8: =AE4/(AE5-AE6) -> 0.3508615 | AH8: =AH4/(AH5-AH6) -> 0.31600885 | AK8: =AK4/(AK5-AK6) -> 0.44196598 | AN8: =AN4/(AN5-AN6) -> 0.52058506 | AQ8: =AQ4/(AQ5-AQ6) -> 0.52086072 | AT8: =AT4/(AT5-AT6) -> 0.30423905 | AW8: =AW4/(AW5-AW6) -> 0.41679097 | AZ8: =AZ4/(AZ5-AZ6) -> 0.58376077 | BC8: =BC4/(BC5-BC6) -> 0.34537566 | BF8: =BF4/(BF5-BF6) -> 0.49964408 | BI8: =BI4/(BI5-BI6) -> 0.53720737 | BL8: =BL4/(BL5-BL6) -> 0.33740722 | BO8: =BO4/(BO5-BO6) -> 0.42716211 | BR8: =BR4/(BR5-BR6) -> 0.55411247 | BU8: =BU4/(BU5-BU6) -> 0.52825999 | BX8: =BX4/(BX5-BX6) -> 0.38578541 | CA8: =CA4/(CA5-CA6) -> 0.46481005 | CD8: =CD4/(CD5-CD6) -> 0.36113378 | CG8: =CG4/(CG5-CG6) -> 0.324955 | CJ8: =CJ4/(CJ5-CJ6) -> 0.427524 | CM8: =CM4/(CM5-CM6) -> 0.29881959 | CP8: =CP4/(CP5-CP6) -> 0.30452689 | CS8: =CS4/(CS5-CS6) -> 0.49362508 | CV8: =CV4/(CV5-CV6) -> 40.947885 | CY8: =CY4/(CY5-CY6) -> 3.3062741 | DB8: =DB4/(DB5-DB6) -> 1.0923511 | DE8: =DE4/(DE5-DE6) -> 0.1403535 | DH8: =DH4/(DH5-DH6) -> 1.844147 | DK8: =DK4/(DK5-DK6) -> 1.7194714
H9: الضريبة | I9: التكلفة شامل الضريبة | J9: الكمية | K9: التكلفة | L9: نسبة التكلفة | M9: الكمية | N9: التكلفة | O9: نسبة التكلفة | P9: الكمية | Q9: التكلفة | R9: نسبة التكلفة | S9: الكمية | T9: التكلفة | U9: نسبة التكلفة | V9: الكمية | W9: التكلفة | X9: نسبة التكلفة | Y9: الكمية | Z9: التكلفة | AA9: نسبة التكلفة | AB9: الكمية | AC9: التكلفة | AD9: نسبة التكلفة | AE9: الكمية | AF9: التكلفة | AG9: نسبة التكلفة | AH9: الكمية | AI9: التكلفة | AJ9: نسبة التكلفة | AK9: الكمية | AL9: التكلفة | AM9: نسبة التكلفة | AN9: الكمية | AO9: التكلفة | AP9: نسبة التكلفة | AQ9: الكمية | AR9: التكلفة | AS9: نسبة التكلفة | AT9: الكمية | AU9: التكلفة | AV9: نسبة التكلفة | AW9: الكمية | AX9: التكلفة | AY9: نسبة التكلفة | AZ9: الكمية | BA9: التكلفة | BB9: نسبة التكلفة | BC9: الكمية | BD9: التكلفة | BE9: نسبة التكلفة | BF9: الكمية | BG9: التكلفة | BH9: نسبة التكلفة | BI9: الكمية | BJ9: التكلفة | BK9: نسبة التكلفة | BL9: الكمية | BM9: التكلفة | BN9: نسبة التكلفة | BO9: الكمية | BP9: التكلفة | BQ9: نسبة التكلفة | BR9: الكمية | BS9: التكلفة | BT9: نسبة التكلفة | BU9: الكمية | BV9: التكلفة | BW9: نسبة التكلفة | BX9: الكمية | BY9: التكلفة | BZ9: نسبة التكلفة | CA9: الكمية | CB9: التكلفة | CC9: نسبة التكلفة | CD9: الكمية | CE9: التكلفة | CF9: نسبة التكلفة | CG9: الكمية | CH9: التكلفة | CI9: نسبة التكلفة | CJ9: الكمية | CK9: التكلفة | CL9: نسبة التكلفة | CM9: الكمية | CN9: التكلفة | CO9: نسبة التكلفة | CP9: الكمية | CQ9: التكلفة | CR9: نسبة التكلفة | CS9: الكمية | CT9: التكلفة | CU9: نسبة التكلفة | CV9: الكمية | CW9: التكلفة | CX9: نسبة التكلفة | CY9: الكمية | CZ9: التكلفة | DA9: نسبة التكلفة | DB9: الكمية | DC9: التكلفة | DD9: نسبة التكلفة | DE9: الكمية | DF9: التكلفة | DG9: نسبة التكلفة | DH9: الكمية | DI9: التكلفة | DJ9: نسبة التكلفة | DK9: الكمية | DL9: التكلفة | DM9: نسبة التكلفة
A10: 1 | B10: Shawarma chicken | C10: دجاج شاورما | D10: =E10/G10 -> 19.375 | E10: 15.5 | F10: 1 | G10: 0.8 | H10: =D10*15% -> 2.90625 | I10: =H10+D10 -> 22.28125 | K10: =J10*D10 -> 0 | L10: =K10/$J$2 -> 0 | N10: =M10*D10 -> 0 | O10: =N10/$M$2 -> 0 | Q10: =P10*D10 -> 0 | R10: =Q10/$P$2 -> 0 | S10: 0.12 | T10: =S10*D10 -> 2.325 | U10: =T10/$S$2 -> 0.46186708 | W10: =V10*D10 -> 0 | X10: =W10/$V$2 -> 0 | Z10: =Y10*D10 -> 0 | AA10: =Z10/$Y$2 -> 0 | AC10: =AB10*D10 -> 0 | AD10: =AC10/$AB$2 -> 0 | AF10: =AE10*D10 -> 0 | AG10: =AF10/$AE$2 -> 0 | AI10: =AH10*D10 -> 0 | AJ10: =AI10/$AH$2 -> 0 | AL10: =AK10*D10 -> 0 | AM10: =AL10/$AK$2 -> 0 | AO10: =AN10*D10 -> 0 | AP10: =AO10/$AN$2 -> 0 | AR10: =AQ10*D10 -> 0 | AS10: =AR10/$AQ$2 -> 0 | AU10: =D10*AT10 -> 0 | AV10: =AU10/$AT$2 -> 0 | AX10: =D10*AW10 -> 0 | AY10: =AX10/$AW$2 -> 0 | BA10: =AZ10*D10 -> 0 | BB10: =BA10/$AZ$2 -> 0 | BD10: =D10*BC10 -> 0 | BE10: =BD10/$BC$2 -> 0 | BG10: =D10*BF10 -> 0 | BH10: =BG10/$BF$2 -> 0 | BJ10: =BI10*D10 -> 0 | BK10: =BJ10/$BI$2 -> 0 | BM10: =BL10*D10 -> 0 | BN10: =BM10/$BL$2 -> 0 | BP10: =BO10*D10 -> 0 | BQ10: =BP10/$BO$2 -> 0 | BS10: =D10*BR10 -> 0 | BT10: =BS10/$BR$2 -> 0 | BV10: =BU10*D10 -> 0 | BW10: =BV10/$BU$2 -> 0 | BY10: =D10*BX10 -> 0 | BZ10: =BY10/$BX$2 -> 0 | CB10: =CA10*D10 -> 0 | CC10: =CB10/$CA$2 -> 0 | CE10: =D10*CD10 -> 0 | CF10: =CE10/$CD$2 -> 0 | CH10: =D10*CG10 -> 0 | CI10: =CH10/$CG$2 -> 0 | CK10: =D10*CJ10 -> 0 | CL10: =CK10/$CJ$2 -> 0 | CN10: =D10*CM10 -> 0 | CO10: =CN10/$CM$2 -> 0 | CQ10: =CP10*D10 -> 0 | CR10: =CQ10/$CP$2 -> 0 | CT10: =CS10*G10 -> 0 | CU10: =CT10/$CP$2 -> 0 | CW10: =CV10*D10 -> 0 | CX10: =CW10/$CP$2 -> 0 | CZ10: =CY10*M10 -> 0 | DA10: =CZ10/$CP$2 -> 0 | DC10: =DB10*P10 -> 0 | DD10: =DC10/$CP$2 -> 0 | DF10: =DE10*D10 -> 0 | DG10: =DF10/$CP$2 -> 0 | DI10: =DH10*D10 -> 0 | DJ10: =DI10/$CP$2 -> 0 | DL10: =DK10*D10 -> 0 | DM10: =DL10/$CP$2 -> 0
A11: 2 | B11: Tenderloin | C11: لحم تندرلوين | D11: =E11/G11 -> 58.75 | E11: 47 | F11: 1 | G11: 0.8 | H11: =D11*15% -> 8.8125 | I11: =H11+D11 -> 67.5625 | J11: 0.12 | K11: =J11*D11 -> 7.05 | L11: =K11/$J$2 -> 0.72737139 | N11: =M11*D11 -> 0 | O11: =N11/$M$2 -> 0 | Q11: =P11*D11 -> 0 | R11: =Q11/$P$2 -> 0 | T11: =S11*D11 -> 0 | U11: =T11/$S$2 -> 0 | V11: 0.07 | W11: =V11*D11 -> 4.1125 | X11: =W11/$V$2 -> 0.61993256 | Z11: =Y11*D11 -> 0 | AA11: =Z11/$Y$2 -> 0 | AC11: =AB11*D11 -> 0 | AD11: =AC11/$AB$2 -> 0 | AF11: =AE11*D11 -> 0 | AG11: =AF11/$AE$2 -> 0 | AI11: =AH11*D11 -> 0 | AJ11: =AI11/$AH$2 -> 0 | AL11: =AK11*D11 -> 0 | AM11: =AL11/$AK$2 -> 0 | AO11: =AN11*D11 -> 0 | AP11: =AO11/$AN$2 -> 0 | AR11: =AQ11*D11 -> 0 | AS11: =AR11/$AQ$2 -> 0 | AU11: =D11*AT11 -> 0 | AV11: =AU11/$AT$2 -> 0 | AX11: =D11*AW11 -> 0 | AY11: =AX11/$AW$2 -> 0 | BA11: =AZ11*D11 -> 0 | BB11: =BA11/$AZ$2 -> 0 | BD11: =D11*BC11 -> 0 | BE11: =BD11/$BC$2 -> 0 | BG11: =D11*BF11 -> 0 | BH11: =BG11/$BF$2 -> 0 | BJ11: =BI11*D11 -> 0 | BK11: =BJ11/$BI$2 -> 0 | BM11: =BL11*D11 -> 0 | BN11: =BM11/$BL$2 -> 0 | BP11: =BO11*D11 -> 0 | BQ11: =BP11/$BO$2 -> 0 | BS11: =D11*BR11 -> 0 | BT11: =BS11/$BR$2 -> 0 | BV11: =BU11*D11 -> 0 | BW11: =BV11/$BU$2 -> 0 | BY11: =D11*BX11 -> 0 | BZ11: =BY11/$BX$2 -> 0 | CA11: 0.03 | CB11: =CA11*D11 -> 1.7625 | CC11: =CB11/$CA$2 -> 0.49136831 | CE11: =D11*CD11 -> 0 | CF11: =CE11/$CD$2 -> 0 | CH11: =D11*CG11 -> 0 | CI11: =CH11/$CG$2 -> 0 | CK11: =D11*CJ11 -> 0 | CL11: =CK11/$CJ$2 -> 0 | CN11: =D11*CM11 -> 0 | CO11: =CN11/$CM$2 -> 0 | CQ11: =CP11*D11 -> 0 | CR11: =CQ11/$CP$2 -> 0 | CT11: =CS11*G11 -> 0 | CU11: =CT11/$CP$2 -> 0 | CW11: =CV11*D11 -> 0 | CX11: =CW11/$CP$2 -> 0 | CZ11: =CY11*M11 -> 0 | DA11: =CZ11/$CP$2 -> 0 | DC11: =DB11*P11 -> 0 | DD11: =DC11/$CP$2 -> 0 | DF11: =DE11*D11 -> 0 | DG11: =DF11/$CP$2 -> 0 | DI11: =DH11*D11 -> 0 | DJ11: =DI11/$CP$2 -> 0 | DL11: =DK11*D11 -> 0 | DM11: =DL11/$CP$2 -> 0
A12: 3 | B12: Beef Brisket | C12: لحم بريسكت | D12: =E12/G12 -> 50 | E12: 40 | F12: 1 | G12: 0.8 | H12: =D12*15% -> 7.5 | I12: =H12+D12 -> 57.5 | K12: =J12*D12 -> 0 | L12: =K12/$J$2 -> 0 | M12: 0.05 | N12: =M12*D12 -> 2.5 | O12: =N12/$M$2 -> 0.3347491 | Q12: =P12*D12 -> 0 | R12: =Q12/$P$2 -> 0 | T12: =S12*D12 -> 0 | U12: =T12/$S$2 -> 0 | W12: =V12*D12 -> 0 | X12: =W12/$V$2 -> 0 | Z12: =Y12*D12 -> 0 | AA12: =Z12/$Y$2 -> 0 | AC12: =AB12*D12 -> 0 | AD12: =AC12/$AB$2 -> 0 | AF12: =AE12*D12 -> 0 | AG12: =AF12/$AE$2 -> 0 | AI12: =AH12*D12 -> 0 | AJ12: =AI12/$AH$2 -> 0 | AL12: =AK12*D12 -> 0 | AM12: =AL12/$AK$2 -> 0 | AO12: =AN12*D12 -> 0 | AP12: =AO12/$AN$2 -> 0 | AR12: =AQ12*D12 -> 0 | AS12: =AR12/$AQ$2 -> 0 | AU12: =D12*AT12 -> 0 | AV12: =AU12/$AT$2 -> 0 | AX12: =D12*AW12 -> 0 | AY12: =AX12/$AW$2 -> 0 | BA12: =AZ12*D12 -> 0 | BB12: =BA12/$AZ$2 -> 0 | BD12: =D12*BC12 -> 0 | BE12: =BD12/$BC$2 -> 0 | BG12: =D12*BF12 -> 0 | BH12: =BG12/$BF$2 -> 0 | BJ12: =BI12*D12 -> 0 | BK12: =BJ12/$BI$2 -> 0 | BM12: =BL12*D12 -> 0 | BN12: =BM12/$BL$2 -> 0 | BP12: =BO12*D12 -> 0 | BQ12: =BP12/$BO$2 -> 0 | BS12: =D12*BR12 -> 0 | BT12: =BS12/$BR$2 -> 0 | BV12: =BU12*D12 -> 0 | BW12: =BV12/$BU$2 -> 0 | BY12: =D12*BX12 -> 0 | BZ12: =BY12/$BX$2 -> 0 | CB12: =CA12*D12 -> 0 | CC12: =CB12/$CA$2 -> 0 | CE12: =D12*CD12 -> 0 | CF12: =CE12/$CD$2 -> 0 | CH12: =D12*CG12 -> 0 | CI12: =CH12/$CG$2 -> 0 | CK12: =D12*CJ12 -> 0 | CL12: =CK12/$CJ$2 -> 0 | CN12: =D12*CM12 -> 0 | CO12: =CN12/$CM$2 -> 0 | CQ12: =CP12*D12 -> 0 | CR12: =CQ12/$CP$2 -> 0 | CT12: =CS12*G12 -> 0 | CU12: =CT12/$CP$2 -> 0 | CW12: =CV12*D12 -> 0 | CX12: =CW12/$CP$2 -> 0 | CZ12: =CY12*M12 -> 0 | DA12: =CZ12/$CP$2 -> 0 | DC12: =DB12*P12 -> 0 | DD12: =DC12/$CP$2 -> 0 | DF12: =DE12*D12 -> 0 | DG12: =DF12/$CP$2 -> 0 | DI12: =DH12*D12 -> 0 | DJ12: =DI12/$CP$2 -> 0 | DL12: =DK12*D12 -> 0 | DM12: =DL12/$CP$2 -> 0
A13: 4 | B13: Beef chuck | C13: لحم تشك | D13: =E13/G13 -> 50 | E13: 40 | F13: 1 | G13: 0.8 | H13: =D13*15% -> 7.5 | I13: =H13+D13 -> 57.5 | K13: =J13*D13 -> 0 | L13: =K13/$J$2 -> 0 | M13: 0.05 | N13: =M13*D13 -> 2.5 | O13: =N13/$M$2 -> 0.3347491 | Q13: =P13*D13 -> 0 | R13: =Q13/$P$2 -> 0 | T13: =S13*D13 -> 0 | U13: =T13/$S$2 -> 0 | W13: =V13*D13 -> 0 | X13: =W13/$V$2 -> 0 | Z13: =Y13*D13 -> 0 | AA13: =Z13/$Y$2 -> 0 | AC13: =AB13*D13 -> 0 | AD13: =AC13/$AB$2 -> 0 | AF13: =AE13*D13 -> 0 | AG13: =AF13/$AE$2 -> 0 | AI13: =AH13*D13 -> 0 | AJ13: =AI13/$AH$2 -> 0 | AL13: =AK13*D13 -> 0 | AM13: =AL13/$AK$2 -> 0 | AO13: =AN13*D13 -> 0 | AP13: =AO13/$AN$2 -> 0 | AR13: =AQ13*D13 -> 0 | AS13: =AR13/$AQ$2 -> 0 | AU13: =D13*AT13 -> 0 | AV13: =AU13/$AT$2 -> 0 | AX13: =D13*AW13 -> 0 | AY13: =AX13/$AW$2 -> 0 | BA13: =AZ13*D13 -> 0 | BB13: =BA13/$AZ$2 -> 0 | BD13: =D13*BC13 -> 0 | BE13: =BD13/$BC$2 -> 0 | BG13: =D13*BF13 -> 0 | BH13: =BG13/$BF$2 -> 0 | BJ13: =BI13*D13 -> 0 | BK13: =BJ13/$BI$2 -> 0 | BM13: =BL13*D13 -> 0 | BN13: =BM13/$BL$2 -> 0 | BO13: 0.02 | BP13: =BO13*D13 -> 1 | BQ13: =BP13/$BO$2 -> 0.43528531 | BS13: =D13*BR13 -> 0 | BT13: =BS13/$BR$2 -> 0 | BV13: =BU13*D13 -> 0 | BW13: =BV13/$BU$2 -> 0 | BY13: =D13*BX13 -> 0 | BZ13: =BY13/$BX$2 -> 0 | CB13: =CA13*D13 -> 0 | CC13: =CB13/$CA$2 -> 0 | CE13: =D13*CD13 -> 0 | CF13: =CE13/$CD$2 -> 0 | CH13: =D13*CG13 -> 0 | CI13: =CH13/$CG$2 -> 0 | CK13: =D13*CJ13 -> 0 | CL13: =CK13/$CJ$2 -> 0 | CN13: =D13*CM13 -> 0 | CO13: =CN13/$CM$2 -> 0 | CQ13: =CP13*D13 -> 0 | CR13: =CQ13/$CP$2 -> 0 | CT13: =CS13*G13 -> 0 | CU13: =CT13/$CP$2 -> 0 | CW13: =CV13*D13 -> 0 | CX13: =CW13/$CP$2 -> 0 | CZ13: =CY13*M13 -> 0 | DA13: =CZ13/$CP$2 -> 0 | DC13: =DB13*P13 -> 0 | DD13: =DC13/$CP$2 -> 0 | DF13: =DE13*D13 -> 0 | DG13: =DF13/$CP$2 -> 0 | DI13: =DH13*D13 -> 0 | DJ13: =DI13/$CP$2 -> 0 | DL13: =DK13*D13 -> 0 | DM13: =DL13/$CP$2 -> 0
A14: 5 | B14: Chicken breast | C14: صدور دجاج | D14: =E14/G14 -> 17.894737 | E14: 17 | F14: 1 | G14: 0.95 | H14: =D14*15% -> 2.6842105 | I14: =H14+D14 -> 20.578947 | K14: =J14*D14 -> 0 | L14: =K14/$J$2 -> 0 | N14: =M14*D14 -> 0 | O14: =N14/$M$2 -> 0 | P14: 0.12 | Q14: =P14*D14 -> 2.1473684 | R14: =Q14/$P$2 -> 0.51463959 | T14: =S14*D14 -> 0 | U14: =T14/$S$2 -> 0 | W14: =V14*D14 -> 0 | X14: =W14/$V$2 -> 0 | Y14: 0.1 | Z14: =Y14*D14 -> 1.7894737 | AA14: =Z14/$Y$2 -> 0.41655951 | AC14: =AB14*D14 -> 0 | AD14: =AC14/$AB$2 -> 0 | AF14: =AE14*D14 -> 0 | AG14: =AF14/$AE$2 -> 0 | AI14: =AH14*D14 -> 0 | AJ14: =AI14/$AH$2 -> 0 | AL14: =AK14*D14 -> 0 | AM14: =AL14/$AK$2 -> 0 | AO14: =AN14*D14 -> 0 | AP14: =AO14/$AN$2 -> 0 | AR14: =AQ14*D14 -> 0 | AS14: =AR14/$AQ$2 -> 0 | AU14: =D14*AT14 -> 0 | AV14: =AU14/$AT$2 -> 0 | AX14: =D14*AW14 -> 0 | AY14: =AX14/$AW$2 -> 0 | BA14: =AZ14*D14 -> 0 | BB14: =BA14/$AZ$2 -> 0 | BD14: =D14*BC14 -> 0 | BE14: =BD14/$BC$2 -> 0 | BG14: =D14*BF14 -> 0 | BH14: =BG14/$BF$2 -> 0 | BJ14: =BI14*D14 -> 0 | BK14: =BJ14/$BI$2 -> 0 | BM14: =BL14*D14 -> 0 | BN14: =BM14/$BL$2 -> 0 | BP14: =BO14*D14 -> 0 | BQ14: =BP14/$BO$2 -> 0 | BS14: =D14*BR14 -> 0 | BT14: =BS14/$BR$2 -> 0 | BV14: =BU14*D14 -> 0 | BW14: =BV14/$BU$2 -> 0 | BY14: =D14*BX14 -> 0 | BZ14: =BY14/$BX$2 -> 0 | CB14: =CA14*D14 -> 0 | CC14: =CB14/$CA$2 -> 0 | CE14: =D14*CD14 -> 0 | CF14: =CE14/$CD$2 -> 0 | CH14: =D14*CG14 -> 0 | CI14: =CH14/$CG$2 -> 0 | CK14: =D14*CJ14 -> 0 | CL14: =CK14/$CJ$2 -> 0 | CN14: =D14*CM14 -> 0 | CO14: =CN14/$CM$2 -> 0 | CQ14: =CP14*D14 -> 0 | CR14: =CQ14/$CP$2 -> 0 | CT14: =CS14*G14 -> 0 | CU14: =CT14/$CP$2 -> 0 | CW14: =CV14*D14 -> 0 | CX14: =CW14/$CP$2 -> 0 | CZ14: =CY14*M14 -> 0 | DA14: =CZ14/$CP$2 -> 0 | DC14: =DB14*P14 -> 0 | DD14: =DC14/$CP$2 -> 0 | DF14: =DE14*D14 -> 0 | DG14: =DF14/$CP$2 -> 0 | DI14: =DH14*D14 -> 0 | DJ14: =DI14/$CP$2 -> 0 | DL14: =DK14*D14 -> 0 | DM14: =DL14/$CP$2 -> 0
A15: 6 | B15: All spice | C15: بهارات مشكلة | D15: =E15/G15 -> 10 | E15: 10 | F15: 1 | G15: 1 | H15: =D15*15% -> 1.5 | I15: =H15+D15 -> 11.5 | K15: =J15*D15 -> 0 | L15: =K15/$J$2 -> 0 | N15: =M15*D15 -> 0 | O15: =N15/$M$2 -> 0 | Q15: =P15*D15 -> 0 | R15: =Q15/$P$2 -> 0 | T15: =S15*D15 -> 0 | U15: =T15/$S$2 -> 0 | W15: =V15*D15 -> 0 | X15: =W15/$V$2 -> 0 | Z15: =Y15*D15 -> 0 | AA15: =Z15/$Y$2 -> 0 | AC15: =AB15*D15 -> 0 | AD15: =AC15/$AB$2 -> 0 | AF15: =AE15*D15 -> 0 | AG15: =AF15/$AE$2 -> 0 | AI15: =AH15*D15 -> 0 | AJ15: =AI15/$AH$2 -> 0 | AL15: =AK15*D15 -> 0 | AM15: =AL15/$AK$2 -> 0 | AO15: =AN15*D15 -> 0 | AP15: =AO15/$AN$2 -> 0 | AR15: =AQ15*D15 -> 0 | AS15: =AR15/$AQ$2 -> 0 | AU15: =D15*AT15 -> 0 | AV15: =AU15/$AT$2 -> 0 | AX15: =D15*AW15 -> 0 | AY15: =AX15/$AW$2 -> 0 | BA15: =AZ15*D15 -> 0 | BB15: =BA15/$AZ$2 -> 0 | BD15: =D15*BC15 -> 0 | BE15: =BD15/$BC$2 -> 0 | BG15: =D15*BF15 -> 0 | BH15: =BG15/$BF$2 -> 0 | BJ15: =BI15*D15 -> 0 | BK15: =BJ15/$BI$2 -> 0 | BM15: =BL15*D15 -> 0 | BN15: =BM15/$BL$2 -> 0 | BO15: 0.0004 | BP15: =BO15*D15 -> 0.004 | BQ15: =BP15/$BO$2 -> 0.0017411412 | BS15: =D15*BR15 -> 0 | BT15: =BS15/$BR$2 -> 0 | BV15: =BU15*D15 -> 0 | BW15: =BV15/$BU$2 -> 0 | BY15: =D15*BX15 -> 0 | BZ15: =BY15/$BX$2 -> 0 | CB15: =CA15*D15 -> 0 | CC15: =CB15/$CA$2 -> 0 | CE15: =D15*CD15 -> 0 | CF15: =CE15/$CD$2 -> 0 | CH15: =D15*CG15 -> 0 | CI15: =CH15/$CG$2 -> 0 | CK15: =D15*CJ15 -> 0 | CL15: =CK15/$CJ$2 -> 0 | CN15: =D15*CM15 -> 0 | CO15: =CN15/$CM$2 -> 0 | CQ15: =CP15*D15 -> 0 | CR15: =CQ15/$CP$2 -> 0 | CT15: =CS15*G15 -> 0 | CU15: =CT15/$CP$2 -> 0 | CW15: =CV15*D15 -> 0 | CX15: =CW15/$CP$2 -> 0 | CZ15: =CY15*M15 -> 0 | DA15: =CZ15/$CP$2 -> 0 | DC15: =DB15*P15 -> 0 | DD15: =DC15/$CP$2 -> 0 | DF15: =DE15*D15 -> 0 | DG15: =DF15/$CP$2 -> 0 | DI15: =DH15*D15 -> 0 | DJ15: =DI15/$CP$2 -> 0 | DL15: =DK15*D15 -> 0 | DM15: =DL15/$CP$2 -> 0
A16: 7 | B16: Almonds | C16: لوز | D16: =E16/G16 -> 30 | E16: 30 | F16: 1 | G16: 1 | H16: =D16*15% -> 4.5 | I16: =H16+D16 -> 34.5 | K16: =J16*D16 -> 0 | L16: =K16/$J$2 -> 0 | N16: =M16*D16 -> 0 | O16: =N16/$M$2 -> 0 | Q16: =P16*D16 -> 0 | R16: =Q16/$P$2 -> 0 | T16: =S16*D16 -> 0 | U16: =T16/$S$2 -> 0 | W16: =V16*D16 -> 0 | X16: =W16/$V$2 -> 0 | Z16: =Y16*D16 -> 0 | AA16: =Z16/$Y$2 -> 0 | AC16: =AB16*D16 -> 0 | AD16: =AC16/$AB$2 -> 0 | AF16: =AE16*D16 -> 0 | AG16: =AF16/$AE$2 -> 0 | AI16: =AH16*D16 -> 0 | AJ16: =AI16/$AH$2 -> 0 | AL16: =AK16*D16 -> 0 | AM16: =AL16/$AK$2 -> 0 | AO16: =AN16*D16 -> 0 | AP16: =AO16/$AN$2 -> 0 | AR16: =AQ16*D16 -> 0 | AS16: =AR16/$AQ$2 -> 0 | AU16: =D16*AT16 -> 0 | AV16: =AU16/$AT$2 -> 0 | AX16: =D16*AW16 -> 0 | AY16: =AX16/$AW$2 -> 0 | BA16: =AZ16*D16 -> 0 | BB16: =BA16/$AZ$2 -> 0 | BD16: =D16*BC16 -> 0 | BE16: =BD16/$BC$2 -> 0 | BG16: =D16*BF16 -> 0 | BH16: =BG16/$BF$2 -> 0 | BJ16: =BI16*D16 -> 0 | BK16: =BJ16/$BI$2 -> 0 | BM16: =BL16*D16 -> 0 | BN16: =BM16/$BL$2 -> 0 | BO16: 0.001 | BP16: =BO16*D16 -> 0.03 | BQ16: =BP16/$BO$2 -> 0.013058559 | BS16: =D16*BR16 -> 0 | BT16: =BS16/$BR$2 -> 0 | BV16: =BU16*D16 -> 0 | BW16: =BV16/$BU$2 -> 0 | BY16: =D16*BX16 -> 0 | BZ16: =BY16/$BX$2 -> 0 | CB16: =CA16*D16 -> 0 | CC16: =CB16/$CA$2 -> 0 | CE16: =D16*CD16 -> 0 | CF16: =CE16/$CD$2 -> 0 | CH16: =D16*CG16 -> 0 | CI16: =CH16/$CG$2 -> 0 | CK16: =D16*CJ16 -> 0 | CL16: =CK16/$CJ$2 -> 0 | CN16: =D16*CM16 -> 0 | CO16: =CN16/$CM$2 -> 0 | CQ16: =CP16*D16 -> 0 | CR16: =CQ16/$CP$2 -> 0 | CT16: =CS16*G16 -> 0 | CU16: =CT16/$CP$2 -> 0 | CV16: 0.2 | CW16: =CV16*D16 -> 6 | CX16: =CW16/$CP$2 -> 35.37486 | CZ16: =CY16*M16 -> 0 | DA16: =CZ16/$CP$2 -> 0 | DC16: =DB16*P16 -> 0 | DD16: =DC16/$CP$2 -> 0 | DF16: =DE16*D16 -> 0 | DG16: =DF16/$CP$2 -> 0 | DI16: =DH16*D16 -> 0 | DJ16: =DI16/$CP$2 -> 0 | DL16: =DK16*D16 -> 0 | DM16: =DL16/$CP$2 -> 0
A17: 8 | B17: Arabic spice | C17: بهارات عربية | D17: =E17/G17 -> 45 | E17: 45 | F17: 1 | G17: 1 | H17: =D17*15% -> 6.75 | I17: =H17+D17 -> 51.75 | K17: =J17*D17 -> 0 | L17: =K17/$J$2 -> 0 | N17: =M17*D17 -> 0 | O17: =N17/$M$2 -> 0 | Q17: =P17*D17 -> 0 | R17: =Q17/$P$2 -> 0 | T17: =S17*D17 -> 0 | U17: =T17/$S$2 -> 0 | W17: =V17*D17 -> 0 | X17: =W17/$V$2 -> 0 | Z17: =Y17*D17 -> 0 | AA17: =Z17/$Y$2 -> 0 | AC17: =AB17*D17 -> 0 | AD17: =AC17/$AB$2 -> 0 | AF17: =AE17*D17 -> 0 | AG17: =AF17/$AE$2 -> 0 | AI17: =AH17*D17 -> 0 | AJ17: =AI17/$AH$2 -> 0 | AL17: =AK17*D17 -> 0 | AM17: =AL17/$AK$2 -> 0 | AO17: =AN17*D17 -> 0 | AP17: =AO17/$AN$2 -> 0 | AR17: =AQ17*D17 -> 0 | AS17: =AR17/$AQ$2 -> 0 | AU17: =D17*AT17 -> 0 | AV17: =AU17/$AT$2 -> 0 | AX17: =D17*AW17 -> 0 | AY17: =AX17/$AW$2 -> 0 | BA17: =AZ17*D17 -> 0 | BB17: =BA17/$AZ$2 -> 0 | BD17: =D17*BC17 -> 0 | BE17: =BD17/$BC$2 -> 0 | BG17: =D17*BF17 -> 0 | BH17: =BG17/$BF$2 -> 0 | BJ17: =BI17*D17 -> 0 | BK17: =BJ17/$BI$2 -> 0 | BM17: =BL17*D17 -> 0 | BN17: =BM17/$BL$2 -> 0 | BP17: =BO17*D17 -> 0 | BQ17: =BP17/$BO$2 -> 0 | BS17: =D17*BR17 -> 0 | BT17: =BS17/$BR$2 -> 0 | BV17: =BU17*D17 -> 0 | BW17: =BV17/$BU$2 -> 0 | BY17: =D17*BX17 -> 0 | BZ17: =BY17/$BX$2 -> 0 | CB17: =CA17*D17 -> 0 | CC17: =CB17/$CA$2 -> 0 | CE17: =D17*CD17 -> 0 | CF17: =CE17/$CD$2 -> 0 | CH17: =D17*CG17 -> 0 | CI17: =CH17/$CG$2 -> 0 | CK17: =D17*CJ17 -> 0 | CL17: =CK17/$CJ$2 -> 0 | CN17: =D17*CM17 -> 0 | CO17: =CN17/$CM$2 -> 0 | CQ17: =CP17*D17 -> 0 | CR17: =CQ17/$CP$2 -> 0 | CT17: =CS17*G17 -> 0 | CU17: =CT17/$CP$2 -> 0 | CW17: =CV17*D17 -> 0 | CX17: =CW17/$CP$2 -> 0 | CZ17: =CY17*M17 -> 0 | DA17: =CZ17/$CP$2 -> 0 | DC17: =DB17*P17 -> 0 | DD17: =DC17/$CP$2 -> 0 | DF17: =DE17*D17 -> 0 | DG17: =DF17/$CP$2 -> 0 | DI17: =DH17*D17 -> 0 | DJ17: =DI17/$CP$2 -> 0 | DL17: =DK17*D17 -> 0 | DM17: =DL17/$CP$2 -> 0
A18: 9 | B18: Argula | C18: جرجير | D18: =E18/G18 -> 56.8125 | E18: 45.45 | F18: 1 | G18: 0.8 | H18: =D18*15% -> 8.521875 | I18: =H18+D18 -> 65.334375 | K18: =J18*D18 -> 0 | L18: =K18/$J$2 -> 0 | N18: =M18*D18 -> 0 | O18: =N18/$M$2 -> 0 | Q18: =P18*D18 -> 0 | R18: =Q18/$P$2 -> 0 | T18: =S18*D18 -> 0 | U18: =T18/$S$2 -> 0 | W18: =V18*D18 -> 0 | X18: =W18/$V$2 -> 0 | Z18: =Y18*D18 -> 0 | AA18: =Z18/$Y$2 -> 0 | AC18: =AB18*D18 -> 0 | AD18: =AC18/$AB$2 -> 0 | AF18: =AE18*D18 -> 0 | AG18: =AF18/$AE$2 -> 0 | AI18: =AH18*D18 -> 0 | AJ18: =AI18/$AH$2 -> 0 | AK18: 0.015 | AL18: =AK18*D18 -> 0.8521875 | AM18: =AL18/$AK$2 -> 0.34757359 | AO18: =AN18*D18 -> 0 | AP18: =AO18/$AN$2 -> 0 | AR18: =AQ18*D18 -> 0 | AS18: =AR18/$AQ$2 -> 0 | AU18: =D18*AT18 -> 0 | AV18: =AU18/$AT$2 -> 0 | AX18: =D18*AW18 -> 0 | AY18: =AX18/$AW$2 -> 0 | BA18: =AZ18*D18 -> 0 | BB18: =BA18/$AZ$2 -> 0 | BD18: =D18*BC18 -> 0 | BE18: =BD18/$BC$2 -> 0 | BG18: =D18*BF18 -> 0 | BH18: =BG18/$BF$2 -> 0 | BJ18: =BI18*D18 -> 0 | BK18: =BJ18/$BI$2 -> 0 | BM18: =BL18*D18 -> 0 | BN18: =BM18/$BL$2 -> 0 | BP18: =BO18*D18 -> 0 | BQ18: =BP18/$BO$2 -> 0 | BS18: =D18*BR18 -> 0 | BT18: =BS18/$BR$2 -> 0 | BV18: =BU18*D18 -> 0 | BW18: =BV18/$BU$2 -> 0 | BY18: =D18*BX18 -> 0 | BZ18: =BY18/$BX$2 -> 0 | CB18: =CA18*D18 -> 0 | CC18: =CB18/$CA$2 -> 0 | CE18: =D18*CD18 -> 0 | CF18: =CE18/$CD$2 -> 0 | CH18: =D18*CG18 -> 0 | CI18: =CH18/$CG$2 -> 0 | CK18: =D18*CJ18 -> 0 | CL18: =CK18/$CJ$2 -> 0 | CN18: =D18*CM18 -> 0 | CO18: =CN18/$CM$2 -> 0 | CQ18: =CP18*D18 -> 0 | CR18: =CQ18/$CP$2 -> 0 | CT18: =CS18*G18 -> 0 | CU18: =CT18/$CP$2 -> 0 | CW18: =CV18*D18 -> 0 | CX18: =CW18/$CP$2 -> 0 | CZ18: =CY18*M18 -> 0 | DA18: =CZ18/$CP$2 -> 0 | DC18: =DB18*P18 -> 0 | DD18: =DC18/$CP$2 -> 0 | DF18: =DE18*D18 -> 0 | DG18: =DF18/$CP$2 -> 0 | DI18: =DH18*D18 -> 0 | DJ18: =DI18/$CP$2 -> 0 | DL18: =DK18*D18 -> 0 | DM18: =DL18/$CP$2 -> 0
A19: 10 | B19: Balsamic vinegar | C19: خل بالسمك | D19: =E19/G19 -> 28.333333 | E19: =170/6 -> 28.333333 | F19: 1 | G19: 1 | H19: =D19*15% -> 4.25 | I19: =H19+D19 -> 32.583333 | J19: 0.005 | K19: =J19*D19 -> 0.14166667 | L19: =K19/$J$2 -> 0.01461621 | N19: =M19*D19 -> 0 | O19: =N19/$M$2 -> 0 | Q19: =P19*D19 -> 0 | R19: =Q19/$P$2 -> 0 | T19: =S19*D19 -> 0 | U19: =T19/$S$2 -> 0 | W19: =V19*D19 -> 0 | X19: =W19/$V$2 -> 0 | Z19: =Y19*D19 -> 0 | AA19: =Z19/$Y$2 -> 0 | AC19: =AB19*D19 -> 0 | AD19: =AC19/$AB$2 -> 0 | AF19: =AE19*D19 -> 0 | AG19: =AF19/$AE$2 -> 0 | AI19: =AH19*D19 -> 0 | AJ19: =AI19/$AH$2 -> 0 | AL19: =AK19*D19 -> 0 | AM19: =AL19/$AK$2 -> 0 | AO19: =AN19*D19 -> 0 | AP19: =AO19/$AN$2 -> 0 | AR19: =AQ19*D19 -> 0 | AS19: =AR19/$AQ$2 -> 0 | AU19: =D19*AT19 -> 0 | AV19: =AU19/$AT$2 -> 0 | AX19: =D19*AW19 -> 0 | AY19: =AX19/$AW$2 -> 0 | BA19: =AZ19*D19 -> 0 | BB19: =BA19/$AZ$2 -> 0 | BD19: =D19*BC19 -> 0 | BE19: =BD19/$BC$2 -> 0 | BG19: =D19*BF19 -> 0 | BH19: =BG19/$BF$2 -> 0 | BJ19: =BI19*D19 -> 0 | BK19: =BJ19/$BI$2 -> 0 | BM19: =BL19*D19 -> 0 | BN19: =BM19/$BL$2 -> 0 | BP19: =BO19*D19 -> 0 | BQ19: =BP19/$BO$2 -> 0 | BS19: =D19*BR19 -> 0 | BT19: =BS19/$BR$2 -> 0 | BV19: =BU19*D19 -> 0 | BW19: =BV19/$BU$2 -> 0 | BY19: =D19*BX19 -> 0 | BZ19: =BY19/$BX$2 -> 0 | CB19: =CA19*D19 -> 0 | CC19: =CB19/$CA$2 -> 0 | CE19: =D19*CD19 -> 0 | CF19: =CE19/$CD$2 -> 0 | CH19: =D19*CG19 -> 0 | CI19: =CH19/$CG$2 -> 0 | CK19: =D19*CJ19 -> 0 | CL19: =CK19/$CJ$2 -> 0 | CN19: =D19*CM19 -> 0 | CO19: =CN19/$CM$2 -> 0 | CQ19: =CP19*D19 -> 0 | CR19: =CQ19/$CP$2 -> 0 | CT19: =CS19*G19 -> 0 | CU19: =CT19/$CP$2 -> 0 | CW19: =CV19*D19 -> 0 | CX19: =CW19/$CP$2 -> 0 | CZ19: =CY19*M19 -> 0 | DA19: =CZ19/$CP$2 -> 0 | DC19: =DB19*P19 -> 0 | DD19: =DC19/$CP$2 -> 0 | DF19: =DE19*D19 -> 0 | DG19: =DF19/$CP$2 -> 0 | DI19: =DH19*D19 -> 0 | DJ19: =DI19/$CP$2 -> 0 | DL19: =DK19*D19 -> 0 | DM19: =DL19/$CP$2 -> 0
A20: 11 | B20: Barkla | C20: باركلا | D20: =E20/G20 -> 3.125 | E20: =15/6 -> 2.5 | F20: 1 | G20: 0.8 | H20: =D20*15% -> 0.46875 | I20: =H20+D20 -> 3.59375 | K20: =J20*D20 -> 0 | L20: =K20/$J$2 -> 0 | N20: =M20*D20 -> 0 | O20: =N20/$M$2 -> 0 | Q20: =P20*D20 -> 0 | R20: =Q20/$P$2 -> 0 | T20: =S20*D20 -> 0 | U20: =T20/$S$2 -> 0 | W20: =V20*D20 -> 0 | X20: =W20/$V$2 -> 0 | Z20: =Y20*D20 -> 0 | AA20: =Z20/$Y$2 -> 0 | AC20: =AB20*D20 -> 0 | AD20: =AC20/$AB$2 -> 0 | AF20: =AE20*D20 -> 0 | AG20: =AF20/$AE$2 -> 0 | AI20: =AH20*D20 -> 0 | AJ20: =AI20/$AH$2 -> 0 | AK20: 0.01 | AL20: =AK20*D20 -> 0.03125 | AM20: =AL20/$AK$2 -> 0.01274564 | AO20: =AN20*D20 -> 0 | AP20: =AO20/$AN$2 -> 0 | AR20: =AQ20*D20 -> 0 | AS20: =AR20/$AQ$2 -> 0 | AU20: =D20*AT20 -> 0 | AV20: =AU20/$AT$2 -> 0 | AX20: =D20*AW20 -> 0 | AY20: =AX20/$AW$2 -> 0 | BA20: =AZ20*D20 -> 0 | BB20: =BA20/$AZ$2 -> 0 | BD20: =D20*BC20 -> 0 | BE20: =BD20/$BC$2 -> 0 | BG20: =D20*BF20 -> 0 | BH20: =BG20/$BF$2 -> 0 | BJ20: =BI20*D20 -> 0 | BK20: =BJ20/$BI$2 -> 0 | BM20: =BL20*D20 -> 0 | BN20: =BM20/$BL$2 -> 0 | BP20: =BO20*D20 -> 0 | BQ20: =BP20/$BO$2 -> 0 | BS20: =D20*BR20 -> 0 | BT20: =BS20/$BR$2 -> 0 | BV20: =BU20*D20 -> 0 | BW20: =BV20/$BU$2 -> 0 | BY20: =D20*BX20 -> 0 | BZ20: =BY20/$BX$2 -> 0 | CB20: =CA20*D20 -> 0 | CC20: =CB20/$CA$2 -> 0 | CE20: =D20*CD20 -> 0 | CF20: =CE20/$CD$2 -> 0 | CH20: =D20*CG20 -> 0 | CI20: =CH20/$CG$2 -> 0 | CK20: =D20*CJ20 -> 0 | CL20: =CK20/$CJ$2 -> 0 | CN20: =D20*CM20 -> 0 | CO20: =CN20/$CM$2 -> 0 | CQ20: =CP20*D20 -> 0 | CR20: =CQ20/$CP$2 -> 0 | CT20: =CS20*G20 -> 0 | CU20: =CT20/$CP$2 -> 0 | CW20: =CV20*D20 -> 0 | CX20: =CW20/$CP$2 -> 0 | CZ20: =CY20*M20 -> 0 | DA20: =CZ20/$CP$2 -> 0 | DC20: =DB20*P20 -> 0 | DD20: =DC20/$CP$2 -> 0 | DF20: =DE20*D20 -> 0 | DG20: =DF20/$CP$2 -> 0 | DI20: =DH20*D20 -> 0 | DJ20: =DI20/$CP$2 -> 0 | DL20: =DK20*D20 -> 0 | DM20: =DL20/$CP$2 -> 0
A21: 12 | B21: WALIMA RICE | C21: ارز بسمتى | D21: =E21/G21 -> 5.75 | E21: =230/40 -> 5.75 | F21: 1 | G21: 1 | H21: =D21*15% -> 0.8625 | I21: =H21+D21 -> 6.6125 | K21: =J21*D21 -> 0 | L21: =K21/$J$2 -> 0 | N21: =M21*D21 -> 0 | O21: =N21/$M$2 -> 0 | Q21: =P21*D21 -> 0 | R21: =Q21/$P$2 -> 0 | T21: =S21*D21 -> 0 | U21: =T21/$S$2 -> 0 | W21: =V21*D21 -> 0 | X21: =W21/$V$2 -> 0 | Z21: =Y21*D21 -> 0 | AA21: =Z21/$Y$2 -> 0 | AC21: =AB21*D21 -> 0 | AD21: =AC21/$AB$2 -> 0 | AF21: =AE21*D21 -> 0 | AG21: =AF21/$AE$2 -> 0 | AI21: =AH21*D21 -> 0 | AJ21: =AI21/$AH$2 -> 0 | AL21: =AK21*D21 -> 0 | AM21: =AL21/$AK$2 -> 0 | AO21: =AN21*D21 -> 0 | AP21: =AO21/$AN$2 -> 0 | AR21: =AQ21*D21 -> 0 | AS21: =AR21/$AQ$2 -> 0 | AU21: =D21*AT21 -> 0 | AV21: =AU21/$AT$2 -> 0 | AX21: =D21*AW21 -> 0 | AY21: =AX21/$AW$2 -> 0 | BA21: =AZ21*D21 -> 0 | BB21: =BA21/$AZ$2 -> 0 | BD21: =D21*BC21 -> 0 | BE21: =BD21/$BC$2 -> 0 | BG21: =D21*BF21 -> 0 | BH21: =BG21/$BF$2 -> 0 | BI21: 0.1 | BJ21: =BI21*D21 -> 0.575 | BK21: =BJ21/$BI$2 -> 0.16687746 | BM21: =BL21*D21 -> 0 | BN21: =BM21/$BL$2 -> 0 | BP21: =BO21*D21 -> 0 | BQ21: =BP21/$BO$2 -> 0 | BS21: =D21*BR21 -> 0 | BT21: =BS21/$BR$2 -> 0 | BV21: =BU21*D21 -> 0 | BW21: =BV21/$BU$2 -> 0 | BY21: =D21*BX21 -> 0 | BZ21: =BY21/$BX$2 -> 0 | CB21: =CA21*D21 -> 0 | CC21: =CB21/$CA$2 -> 0 | CE21: =D21*CD21 -> 0 | CF21: =CE21/$CD$2 -> 0 | CH21: =D21*CG21 -> 0 | CI21: =CH21/$CG$2 -> 0 | CK21: =D21*CJ21 -> 0 | CL21: =CK21/$CJ$2 -> 0 | CN21: =D21*CM21 -> 0 | CO21: =CN21/$CM$2 -> 0 | CQ21: =CP21*D21 -> 0 | CR21: =CQ21/$CP$2 -> 0 | CT21: =CS21*G21 -> 0 | CU21: =CT21/$CP$2 -> 0 | CW21: =CV21*D21 -> 0 | CX21: =CW21/$CP$2 -> 0 | CZ21: =CY21*M21 -> 0 | DA21: =CZ21/$CP$2 -> 0 | DC21: =DB21*P21 -> 0 | DD21: =DC21/$CP$2 -> 0 | DF21: =DE21*D21 -> 0 | DG21: =DF21/$CP$2 -> 0 | DI21: =DH21*D21 -> 0 | DJ21: =DI21/$CP$2 -> 0 | DL21: =DK21*D21 -> 0 | DM21: =DL21/$CP$2 -> 0
A22: 13 | B22: BAY LEAFS | C22: أوراق غار | D22: =E22/G22 -> 10 | E22: 10 | F22: 1 | G22: 1 | H22: =D22*15% -> 1.5 | I22: =H22+D22 -> 11.5 | K22: =J22*D22 -> 0 | L22: =K22/$J$2 -> 0 | N22: =M22*D22 -> 0 | O22: =N22/$M$2 -> 0 | Q22: =P22*D22 -> 0 | R22: =Q22/$P$2 -> 0 | T22: =S22*D22 -> 0 | U22: =T22/$S$2 -> 0 | W22: =V22*D22 -> 0 | X22: =W22/$V$2 -> 0 | Z22: =Y22*D22 -> 0 | AA22: =Z22/$Y$2 -> 0 | AC22: =AB22*D22 -> 0 | AD22: =AC22/$AB$2 -> 0 | AF22: =AE22*D22 -> 0 | AG22: =AF22/$AE$2 -> 0 | AI22: =AH22*D22 -> 0 | AJ22: =AI22/$AH$2 -> 0 | AL22: =AK22*D22 -> 0 | AM22: =AL22/$AK$2 -> 0 | AO22: =AN22*D22 -> 0 | AP22: =AO22/$AN$2 -> 0 | AR22: =AQ22*D22 -> 0 | AS22: =AR22/$AQ$2 -> 0 | AU22: =D22*AT22 -> 0 | AV22: =AU22/$AT$2 -> 0 | AX22: =D22*AW22 -> 0 | AY22: =AX22/$AW$2 -> 0 | BA22: =AZ22*D22 -> 0 | BB22: =BA22/$AZ$2 -> 0 | BD22: =D22*BC22 -> 0 | BE22: =BD22/$BC$2 -> 0 | BG22: =D22*BF22 -> 0 | BH22: =BG22/$BF$2 -> 0 | BI22: 0.001 | BJ22: =BI22*D22 -> 0.01 | BK22: =BJ22/$BI$2 -> 0.0029022166 | BM22: =BL22*D22 -> 0 | BN22: =BM22/$BL$2 -> 0 | BP22: =BO22*D22 -> 0 | BQ22: =BP22/$BO$2 -> 0 | BS22: =D22*BR22 -> 0 | BT22: =BS22/$BR$2 -> 0 | BV22: =BU22*D22 -> 0 | BW22: =BV22/$BU$2 -> 0 | BY22: =D22*BX22 -> 0 | BZ22: =BY22/$BX$2 -> 0 | CB22: =CA22*D22 -> 0 | CC22: =CB22/$CA$2 -> 0 | CE22: =D22*CD22 -> 0 | CF22: =CE22/$CD$2 -> 0 | CH22: =D22*CG22 -> 0 | CI22: =CH22/$CG$2 -> 0 | CK22: =D22*CJ22 -> 0 | CL22: =CK22/$CJ$2 -> 0 | CN22: =D22*CM22 -> 0 | CO22: =CN22/$CM$2 -> 0 | CQ22: =CP22*D22 -> 0 | CR22: =CQ22/$CP$2 -> 0 | CT22: =CS22*G22 -> 0 | CU22: =CT22/$CP$2 -> 0 | CW22: =CV22*D22 -> 0 | CX22: =CW22/$CP$2 -> 0 | CZ22: =CY22*M22 -> 0 | DA22: =CZ22/$CP$2 -> 0 | DC22: =DB22*P22 -> 0 | DD22: =DC22/$CP$2 -> 0 | DF22: =DE22*D22 -> 0 | DG22: =DF22/$CP$2 -> 0 | DI22: =DH22*D22 -> 0 | DJ22: =DI22/$CP$2 -> 0 | DL22: =DK22*D22 -> 0 | DM22: =DL22/$CP$2 -> 0
A23: 14 | B23: Bbq seasoning | C23: بهارات مشاوى | D23: =E23/G23 -> 89.487179 | E23: =13.96*1000/156 -> 89.487179 | F23: 1 | G23: 1 | H23: =D23*15% -> 13.423077 | I23: =H23+D23 -> 102.91026 | K23: =J23*D23 -> 0 | L23: =K23/$J$2 -> 0 | N23: =M23*D23 -> 0 | O23: =N23/$M$2 -> 0 | Q23: =P23*D23 -> 0 | R23: =Q23/$P$2 -> 0 | S23: 0.002 | T23: =S23*D23 -> 0.17897436 | U23: =T23/$S$2 -> 0.035553705 | W23: =V23*D23 -> 0 | X23: =W23/$V$2 -> 0 | Z23: =Y23*D23 -> 0 | AA23: =Z23/$Y$2 -> 0 | AC23: =AB23*D23 -> 0 | AD23: =AC23/$AB$2 -> 0 | AF23: =AE23*D23 -> 0 | AG23: =AF23/$AE$2 -> 0 | AI23: =AH23*D23 -> 0 | AJ23: =AI23/$AH$2 -> 0 | AL23: =AK23*D23 -> 0 | AM23: =AL23/$AK$2 -> 0 | AO23: =AN23*D23 -> 0 | AP23: =AO23/$AN$2 -> 0 | AR23: =AQ23*D23 -> 0 | AS23: =AR23/$AQ$2 -> 0 | AU23: =D23*AT23 -> 0 | AV23: =AU23/$AT$2 -> 0 | AX23: =D23*AW23 -> 0 | AY23: =AX23/$AW$2 -> 0 | BA23: =AZ23*D23 -> 0 | BB23: =BA23/$AZ$2 -> 0 | BD23: =D23*BC23 -> 0 | BE23: =BD23/$BC$2 -> 0 | BG23: =D23*BF23 -> 0 | BH23: =BG23/$BF$2 -> 0 | BJ23: =BI23*D23 -> 0 | BK23: =BJ23/$BI$2 -> 0 | BM23: =BL23*D23 -> 0 | BN23: =BM23/$BL$2 -> 0 | BP23: =BO23*D23 -> 0 | BQ23: =BP23/$BO$2 -> 0 | BS23: =D23*BR23 -> 0 | BT23: =BS23/$BR$2 -> 0 | BV23: =BU23*D23 -> 0 | BW23: =BV23/$BU$2 -> 0 | BY23: =D23*BX23 -> 0 | BZ23: =BY23/$BX$2 -> 0 | CB23: =CA23*D23 -> 0 | CC23: =CB23/$CA$2 -> 0 | CE23: =D23*CD23 -> 0 | CF23: =CE23/$CD$2 -> 0 | CH23: =D23*CG23 -> 0 | CI23: =CH23/$CG$2 -> 0 | CK23: =D23*CJ23 -> 0 | CL23: =CK23/$CJ$2 -> 0 | CN23: =D23*CM23 -> 0 | CO23: =CN23/$CM$2 -> 0 | CQ23: =CP23*D23 -> 0 | CR23: =CQ23/$CP$2 -> 0 | CT23: =CS23*G23 -> 0 | CU23: =CT23/$CP$2 -> 0 | CW23: =CV23*D23 -> 0 | CX23: =CW23/$CP$2 -> 0 | CZ23: =CY23*M23 -> 0 | DA23: =CZ23/$CP$2 -> 0 | DC23: =DB23*P23 -> 0 | DD23: =DC23/$CP$2 -> 0 | DF23: =DE23*D23 -> 0 | DG23: =DF23/$CP$2 -> 0 | DI23: =DH23*D23 -> 0 | DJ23: =DI23/$CP$2 -> 0 | DL23: =DK23*D23 -> 0 | DM23: =DL23/$CP$2 -> 0
A24: 15 | B24: Black Olives | C24: زيتون اسود | D24: =E24/G24 -> 13.6 | E24: =136/10 -> 13.6 | F24: 1 | G24: 1 | H24: =D24*15% -> 2.04 | I24: =H24+D24 -> 15.64 | K24: =J24*D24 -> 0 | L24: =K24/$J$2 -> 0 | N24: =M24*D24 -> 0 | O24: =N24/$M$2 -> 0 | Q24: =P24*D24 -> 0 | R24: =Q24/$P$2 -> 0 | T24: =S24*D24 -> 0 | U24: =T24/$S$2 -> 0 | W24: =V24*D24 -> 0 | X24: =W24/$V$2 -> 0 | Z24: =Y24*D24 -> 0 | AA24: =Z24/$Y$2 -> 0 | AB24: 0.01 | AC24: =AB24*D24 -> 0.136 | AD24: =AC24/$AB$2 -> 0.036867163 | AF24: =AE24*D24 -> 0 | AG24: =AF24/$AE$2 -> 0 | AI24: =AH24*D24 -> 0 | AJ24: =AI24/$AH$2 -> 0 | AL24: =AK24*D24 -> 0 | AM24: =AL24/$AK$2 -> 0 | AO24: =AN24*D24 -> 0 | AP24: =AO24/$AN$2 -> 0 | AR24: =AQ24*D24 -> 0 | AS24: =AR24/$AQ$2 -> 0 | AU24: =D24*AT24 -> 0 | AV24: =AU24/$AT$2 -> 0 | AX24: =D24*AW24 -> 0 | AY24: =AX24/$AW$2 -> 0 | BA24: =AZ24*D24 -> 0 | BB24: =BA24/$AZ$2 -> 0 | BD24: =D24*BC24 -> 0 | BE24: =BD24/$BC$2 -> 0 | BG24: =D24*BF24 -> 0 | BH24: =BG24/$BF$2 -> 0 | BJ24: =BI24*D24 -> 0 | BK24: =BJ24/$BI$2 -> 0 | BM24: =BL24*D24 -> 0 | BN24: =BM24/$BL$2 -> 0 | BP24: =BO24*D24 -> 0 | BQ24: =BP24/$BO$2 -> 0 | BS24: =D24*BR24 -> 0 | BT24: =BS24/$BR$2 -> 0 | BV24: =BU24*D24 -> 0 | BW24: =BV24/$BU$2 -> 0 | BY24: =D24*BX24 -> 0 | BZ24: =BY24/$BX$2 -> 0 | CB24: =CA24*D24 -> 0 | CC24: =CB24/$CA$2 -> 0 | CE24: =D24*CD24 -> 0 | CF24: =CE24/$CD$2 -> 0 | CH24: =D24*CG24 -> 0 | CI24: =CH24/$CG$2 -> 0 | CK24: =D24*CJ24 -> 0 | CL24: =CK24/$CJ$2 -> 0 | CN24: =D24*CM24 -> 0 | CO24: =CN24/$CM$2 -> 0 | CQ24: =CP24*D24 -> 0 | CR24: =CQ24/$CP$2 -> 0 | CT24: =CS24*G24 -> 0 | CU24: =CT24/$CP$2 -> 0 | CW24: =CV24*D24 -> 0 | CX24: =CW24/$CP$2 -> 0 | CZ24: =CY24*M24 -> 0 | DA24: =CZ24/$CP$2 -> 0 | DC24: =DB24*P24 -> 0 | DD24: =DC24/$CP$2 -> 0 | DF24: =DE24*D24 -> 0 | DG24: =DF24/$CP$2 -> 0 | DI24: =DH24*D24 -> 0 | DJ24: =DI24/$CP$2 -> 0 | DL24: =DK24*D24 -> 0 | DM24: =DL24/$CP$2 -> 0
A25: 16 | B25: Black pepper | C25: فلفل اسود | D25: =E25/G25 -> 18 | E25: 18 | F25: 1 | G25: 1 | H25: =D25*15% -> 2.7 | I25: =H25+D25 -> 20.7 | J25: 0.005 | K25: =J25*D25 -> 0.09 | L25: =K25/$J$2 -> 0.0092855922 | M25: 0.002 | N25: =M25*D25 -> 0.036 | O25: =N25/$M$2 -> 0.004820387 | P25: 0.002 | Q25: =P25*D25 -> 0.036 | R25: =Q25/$P$2 -> 0.0086277814 | S25: 0.002 | T25: =S25*D25 -> 0.036 | U25: =T25/$S$2 -> 0.0071514903 | V25: 0.001 | W25: =V25*D25 -> 0.018 | X25: =W25/$V$2 -> 0.0027133827 | Y25: 0.002 | Z25: =Y25*D25 -> 0.036 | AA25: =Z25/$Y$2 -> 0.0083801972 | AC25: =AB25*D25 -> 0 | AD25: =AC25/$AB$2 -> 0 | AF25: =AE25*D25 -> 0 | AG25: =AF25/$AE$2 -> 0 | AI25: =AH25*D25 -> 0 | AJ25: =AI25/$AH$2 -> 0 | AL25: =AK25*D25 -> 0 | AM25: =AL25/$AK$2 -> 0 | AN25: 0.002 | AO25: =AN25*D25 -> 0.036 | AP25: =AO25/$AN$2 -> 0.0088014397 | AR25: =AQ25*D25 -> 0 | AS25: =AR25/$AQ$2 -> 0 | AT25: 0.0005 | AU25: =D25*AT25 -> 0.009 | AV25: =AU25/$AT$2 -> 0.00665242 | AX25: =D25*AW25 -> 0 | AY25: =AX25/$AW$2 -> 0 | BA25: =AZ25*D25 -> 0 | BB25: =BA25/$AZ$2 -> 0 | BD25: =D25*BC25 -> 0 | BE25: =BD25/$BC$2 -> 0 | BG25: =D25*BF25 -> 0 | BH25: =BG25/$BF$2 -> 0 | BJ25: =BI25*D25 -> 0 | BK25: =BJ25/$BI$2 -> 0 | BL25: 0.002 | BM25: =BL25*D25 -> 0.036 | BN25: =BM25/$BL$2 -> 0.026455591 | BO25: 0.0002 | BP25: =BO25*D25 -> 0.0036 | BQ25: =BP25/$BO$2 -> 0.0015670271 | BR25: 0.001 | BS25: =D25*BR25 -> 0.018 | BT25: =BS25/$BR$2 -> 0.0049695708 | BU25: 0.0025 | BV25: =BU25*D25 -> 0.045 | BW25: =BV25/$BU$2 -> 0.013423707 | BY25: =D25*BX25 -> 0 | BZ25: =BY25/$BX$2 -> 0 | CB25: =CA25*D25 -> 0 | CC25: =CB25/$CA$2 -> 0 | CE25: =D25*CD25 -> 0 | CF25: =CE25/$CD$2 -> 0 | CH25: =D25*CG25 -> 0 | CI25: =CH25/$CG$2 -> 0 | CK25: =D25*CJ25 -> 0 | CL25: =CK25/$CJ$2 -> 0 | CN25: =D25*CM25 -> 0 | CO25: =CN25/$CM$2 -> 0 | CQ25: =CP25*D25 -> 0 | CR25: =CQ25/$CP$2 -> 0 | CT25: =CS25*G25 -> 0 | CU25: =CT25/$CP$2 -> 0 | CV25: 0.01 | CW25: =CV25*D25 -> 0.18 | CX25: =CW25/$CP$2 -> 1.0612458 | CZ25: =CY25*M25 -> 0 | DA25: =CZ25/$CP$2 -> 0 | DC25: =DB25*P25 -> 0 | DD25: =DC25/$CP$2 -> 0 | DE25: =0.01/50 -> 0.0002 | DF25: =DE25*D25 -> 0.0036 | DG25: =DF25/$CP$2 -> 0.021224916 | DH25: 0.02 | DI25: =DH25*D25 -> 0.36 | DJ25: =DI25/$CP$2 -> 2.1224916 | DK25: 0.01 | DL25: =DK25*D25 -> 0.18 | DM25: =DL25/$CP$2 -> 1.0612458
A26: 17 | B26: Boiled chickpeas | C26: حمص مغلى | D26: =E26/G26 -> 5.3333333 | E26: =80/15 -> 5.3333333 | F26: 1 | G26: 1 | H26: =D26*15% -> 0.8 | I26: =H26+D26 -> 6.1333333 | K26: =J26*D26 -> 0 | L26: =K26/$J$2 -> 0 | N26: =M26*D26 -> 0 | O26: =N26/$M$2 -> 0 | Q26: =P26*D26 -> 0 | R26: =Q26/$P$2 -> 0 | T26: =S26*D26 -> 0 | U26: =T26/$S$2 -> 0 | W26: =V26*D26 -> 0 | X26: =W26/$V$2 -> 0 | Z26: =Y26*D26 -> 0 | AA26: =Z26/$Y$2 -> 0 | AC26: =AB26*D26 -> 0 | AD26: =AC26/$AB$2 -> 0 | AE26: 0.02 | AF26: =AE26*D26 -> 0.10666667 | AG26: =AF26/$AE$2 -> 0.037072694 | AI26: =AH26*D26 -> 0 | AJ26: =AI26/$AH$2 -> 0 | AL26: =AK26*D26 -> 0 | AM26: =AL26/$AK$2 -> 0 | AO26: =AN26*D26 -> 0 | AP26: =AO26/$AN$2 -> 0 | AR26: =AQ26*D26 -> 0 | AS26: =AR26/$AQ$2 -> 0 | AU26: =D26*AT26 -> 0 | AV26: =AU26/$AT$2 -> 0 | AW26: 0.0625 | AX26: =D26*AW26 -> 0.33333333 | AY26: =AX26/$AW$2 -> 0.15226797 | BA26: =AZ26*D26 -> 0 | BB26: =BA26/$AZ$2 -> 0 | BD26: =D26*BC26 -> 0 | BE26: =BD26/$BC$2 -> 0 | BG26: =D26*BF26 -> 0 | BH26: =BG26/$BF$2 -> 0 | BJ26: =BI26*D26 -> 0 | BK26: =BJ26/$BI$2 -> 0 | BM26: =BL26*D26 -> 0 | BN26: =BM26/$BL$2 -> 0 | BP26: =BO26*D26 -> 0 | BQ26: =BP26/$BO$2 -> 0 | BS26: =D26*BR26 -> 0 | BT26: =BS26/$BR$2 -> 0 | BV26: =BU26*D26 -> 0 | BW26: =BV26/$BU$2 -> 0 | BY26: =D26*BX26 -> 0 | BZ26: =BY26/$BX$2 -> 0 | CA26: 0.02 | CB26: =CA26*D26 -> 0.10666667 | CC26: =CB26/$CA$2 -> 0.029737657 | CE26: =D26*CD26 -> 0 | CF26: =CE26/$CD$2 -> 0 | CH26: =D26*CG26 -> 0 | CI26: =CH26/$CG$2 -> 0 | CK26: =D26*CJ26 -> 0 | CL26: =CK26/$CJ$2 -> 0 | CN26: =D26*CM26 -> 0 | CO26: =CN26/$CM$2 -> 0 | CQ26: =CP26*D26 -> 0 | CR26: =CQ26/$CP$2 -> 0 | CT26: =CS26*G26 -> 0 | CU26: =CT26/$CP$2 -> 0 | CW26: =CV26*D26 -> 0 | CX26: =CW26/$CP$2 -> 0 | CZ26: =CY26*M26 -> 0 | DA26: =CZ26/$CP$2 -> 0 | DC26: =DB26*P26 -> 0 | DD26: =DC26/$CP$2 -> 0 | DF26: =DE26*D26 -> 0 | DG26: =DF26/$CP$2 -> 0 | DI26: =DH26*D26 -> 0 | DJ26: =DI26/$CP$2 -> 0 | DL26: =DK26*D26 -> 0 | DM26: =DL26/$CP$2 -> 0
A27: 19 | B27: Bread regular | C27: خبز عادى | D27: =E27/G27 -> 0.12 | E27: =0.12 -> 0.12 | F27: 1 | G27: 1 | H27: =D27*15% -> 0.018 | I27: =H27+D27 -> 0.138 | J27: 2 | K27: =J27*D27 -> 0.24 | L27: =K27/$J$2 -> 0.024761579 | M27: 2 | N27: =M27*D27 -> 0.24 | O27: =N27/$M$2 -> 0.032135913 | P27: 2 | Q27: =P27*D27 -> 0.24 | R27: =Q27/$P$2 -> 0.057518543 | S27: 2 | T27: =S27*D27 -> 0.24 | U27: =T27/$S$2 -> 0.047676602 | V27: 2 | W27: =V27*D27 -> 0.24 | X27: =W27/$V$2 -> 0.036178435 | Y27: 2 | Z27: =Y27*D27 -> 0.24 | AA27: =Z27/$Y$2 -> 0.055867981 | AB27: 2 | AC27: =AB27*D27 -> 0.24 | AD27: =AC27/$AB$2 -> 0.0650597 | AE27: 2 | AF27: =AE27*D27 -> 0.24 | AG27: =AF27/$AE$2 -> 0.083413562 | AI27: =AH27*D27 -> 0 | AJ27: =AI27/$AH$2 -> 0 | AK27: 0.1 | AL27: =AK27*D27 -> 0.012 | AM27: =AL27/$AK$2 -> 0.0048943256 | AN27: 2 | AO27: =AN27*D27 -> 0.24 | AP27: =AO27/$AN$2 -> 0.058676265 | AR27: =AQ27*D27 -> 0 | AS27: =AR27/$AQ$2 -> 0 | AU27: =D27*AT27 -> 0 | AV27: =AU27/$AT$2 -> 0 | AX27: =D27*AW27 -> 0 | AY27: =AX27/$AW$2 -> 0 | BA27: =AZ27*D27 -> 0 | BB27: =BA27/$AZ$2 -> 0 | BD27: =D27*BC27 -> 0 | BE27: =BD27/$BC$2 -> 0 | BG27: =D27*BF27 -> 0 | BH27: =BG27/$BF$2 -> 0 | BJ27: =BI27*D27 -> 0 | BK27: =BJ27/$BI$2 -> 0 | BM27: =BL27*D27 -> 0 | BN27: =BM27/$BL$2 -> 0 | BP27: =BO27*D27 -> 0 | BQ27: =BP27/$BO$2 -> 0 | BS27: =D27*BR27 -> 0 | BT27: =BS27/$BR$2 -> 0 | BV27: =BU27*D27 -> 0 | BW27: =BV27/$BU$2 -> 0 | BY27: =D27*BX27 -> 0 | BZ27: =BY27/$BX$2 -> 0 | CA27: 2 | CB27: =CA27*D27 -> 0.24 | CC27: =CB27/$CA$2 -> 0.066909728 | CE27: =D27*CD27 -> 0 | CF27: =CE27/$CD$2 -> 0 | CH27: =D27*CG27 -> 0 | CI27: =CH27/$CG$2 -> 0 | CK27: =D27*CJ27 -> 0 | CL27: =CK27/$CJ$2 -> 0 | CN27: =D27*CM27 -> 0 | CO27: =CN27/$CM$2 -> 0 | CQ27: =CP27*D27 -> 0 | CR27: =CQ27/$CP$2 -> 0 | CT27: =CS27*G27 -> 0 | CU27: =CT27/$CP$2 -> 0 | CW27: =CV27*D27 -> 0 | CX27: =CW27/$CP$2 -> 0 | CZ27: =CY27*M27 -> 0 | DA27: =CZ27/$CP$2 -> 0 | DC27: =DB27*P27 -> 0 | DD27: =DC27/$CP$2 -> 0 | DF27: =DE27*D27 -> 0 | DG27: =DF27/$CP$2 -> 0 | DI27: =DH27*D27 -> 0 | DJ27: =DI27/$CP$2 -> 0 | DL27: =DK27*D27 -> 0 | DM27: =DL27/$CP$2 -> 0
A28: 20 | B28: Breadcrumbs | C28: فتات خبز | D28: =E28/G28 -> 12.5 | E28: =60/(12*400)*1000 -> 12.5 | F28: 1 | G28: 1 | H28: =D28*15% -> 1.875 | I28: =H28+D28 -> 14.375 | K28: =J28*D28 -> 0 | L28: =K28/$J$2 -> 0 | N28: =M28*D28 -> 0 | O28: =N28/$M$2 -> 0 | Q28: =P28*D28 -> 0 | R28: =Q28/$P$2 -> 0 | T28: =S28*D28 -> 0 | U28: =T28/$S$2 -> 0 | W28: =V28*D28 -> 0 | X28: =W28/$V$2 -> 0 | Z28: =Y28*D28 -> 0 | AA28: =Z28/$Y$2 -> 0 | AC28: =AB28*D28 -> 0 | AD28: =AC28/$AB$2 -> 0 | AF28: =AE28*D28 -> 0 | AG28: =AF28/$AE$2 -> 0 | AI28: =AH28*D28 -> 0 | AJ28: =AI28/$AH$2 -> 0 | AL28: =AK28*D28 -> 0 | AM28: =AL28/$AK$2 -> 0 | AO28: =AN28*D28 -> 0 | AP28: =AO28/$AN$2 -> 0 | AR28: =AQ28*D28 -> 0 | AS28: =AR28/$AQ$2 -> 0 | AU28: =D28*AT28 -> 0 | AV28: =AU28/$AT$2 -> 0 | AX28: =D28*AW28 -> 0 | AY28: =AX28/$AW$2 -> 0 | BA28: =AZ28*D28 -> 0 | BB28: =BA28/$AZ$2 -> 0 | BD28: =D28*BC28 -> 0 | BE28: =BD28/$BC$2 -> 0 | BG28: =D28*BF28 -> 0 | BH28: =BG28/$BF$2 -> 0 | BJ28: =BI28*D28 -> 0 | BK28: =BJ28/$BI$2 -> 0 | BM28: =BL28*D28 -> 0 | BN28: =BM28/$BL$2 -> 0 | BP28: =BO28*D28 -> 0 | BQ28: =BP28/$BO$2 -> 0 | BS28: =D28*BR28 -> 0 | BT28: =BS28/$BR$2 -> 0 | BV28: =BU28*D28 -> 0 | BW28: =BV28/$BU$2 -> 0 | BY28: =D28*BX28 -> 0 | BZ28: =BY28/$BX$2 -> 0 | CB28: =CA28*D28 -> 0 | CC28: =CB28/$CA$2 -> 0 | CE28: =D28*CD28 -> 0 | CF28: =CE28/$CD$2 -> 0 | CH28: =D28*CG28 -> 0 | CI28: =CH28/$CG$2 -> 0 | CK28: =D28*CJ28 -> 0 | CL28: =CK28/$CJ$2 -> 0 | CN28: =D28*CM28 -> 0 | CO28: =CN28/$CM$2 -> 0 | CQ28: =CP28*D28 -> 0 | CR28: =CQ28/$CP$2 -> 0 | CT28: =CS28*G28 -> 0 | CU28: =CT28/$CP$2 -> 0 | CW28: =CV28*D28 -> 0 | CX28: =CW28/$CP$2 -> 0 | CZ28: =CY28*M28 -> 0 | DA28: =CZ28/$CP$2 -> 0 | DC28: =DB28*P28 -> 0 | DD28: =DC28/$CP$2 -> 0 | DF28: =DE28*D28 -> 0 | DG28: =DF28/$CP$2 -> 0 | DI28: =DH28*D28 -> 0 | DJ28: =DI28/$CP$2 -> 0 | DL28: =DK28*D28 -> 0 | DM28: =DL28/$CP$2 -> 0
A29: 21 | B29: Breads toasted | C29: خبز توست | D29: =E29/G29 -> 0.12631579 | E29: 0.12 | F29: 1 | G29: 0.95 | H29: =D29*15% -> 0.018947368 | I29: =H29+D29 -> 0.14526316 | K29: =J29*D29 -> 0 | L29: =K29/$J$2 -> 0 | N29: =M29*D29 -> 0 | O29: =N29/$M$2 -> 0 | Q29: =P29*D29 -> 0 | R29: =Q29/$P$2 -> 0 | T29: =S29*D29 -> 0 | U29: =T29/$S$2 -> 0 | W29: =V29*D29 -> 0 | X29: =W29/$V$2 -> 0 | Z29: =Y29*D29 -> 0 | AA29: =Z29/$Y$2 -> 0 | AC29: =AB29*D29 -> 0 | AD29: =AC29/$AB$2 -> 0 | AF29: =AE29*D29 -> 0 | AG29: =AF29/$AE$2 -> 0 | AI29: =AH29*D29 -> 0 | AJ29: =AI29/$AH$2 -> 0 | AL29: =AK29*D29 -> 0 | AM29: =AL29/$AK$2 -> 0 | AO29: =AN29*D29 -> 0 | AP29: =AO29/$AN$2 -> 0 | AR29: =AQ29*D29 -> 0 | AS29: =AR29/$AQ$2 -> 0 | AU29: =D29*AT29 -> 0 | AV29: =AU29/$AT$2 -> 0 | AX29: =D29*AW29 -> 0 | AY29: =AX29/$AW$2 -> 0 | BA29: =AZ29*D29 -> 0 | BB29: =BA29/$AZ$2 -> 0 | BD29: =D29*BC29 -> 0 | BE29: =BD29/$BC$2 -> 0 | BG29: =D29*BF29 -> 0 | BH29: =BG29/$BF$2 -> 0 | BJ29: =BI29*D29 -> 0 | BK29: =BJ29/$BI$2 -> 0 | BM29: =BL29*D29 -> 0 | BN29: =BM29/$BL$2 -> 0 | BP29: =BO29*D29 -> 0 | BQ29: =BP29/$BO$2 -> 0 | BS29: =D29*BR29 -> 0 | BT29: =BS29/$BR$2 -> 0 | BV29: =BU29*D29 -> 0 | BW29: =BV29/$BU$2 -> 0 | BY29: =D29*BX29 -> 0 | BZ29: =BY29/$BX$2 -> 0 | CB29: =CA29*D29 -> 0 | CC29: =CB29/$CA$2 -> 0 | CE29: =D29*CD29 -> 0 | CF29: =CE29/$CD$2 -> 0 | CH29: =D29*CG29 -> 0 | CI29: =CH29/$CG$2 -> 0 | CK29: =D29*CJ29 -> 0 | CL29: =CK29/$CJ$2 -> 0 | CN29: =D29*CM29 -> 0 | CO29: =CN29/$CM$2 -> 0 | CQ29: =CP29*D29 -> 0 | CR29: =CQ29/$CP$2 -> 0 | CT29: =CS29*G29 -> 0 | CU29: =CT29/$CP$2 -> 0 | CW29: =CV29*D29 -> 0 | CX29: =CW29/$CP$2 -> 0 | CZ29: =CY29*M29 -> 0 | DA29: =CZ29/$CP$2 -> 0 | DC29: =DB29*P29 -> 0 | DD29: =DC29/$CP$2 -> 0 | DF29: =DE29*D29 -> 0 | DG29: =DF29/$CP$2 -> 0 | DI29: =DH29*D29 -> 0 | DJ29: =DI29/$CP$2 -> 0 | DL29: =DK29*D29 -> 0 | DM29: =DL29/$CP$2 -> 0
A30: 22 | B30: Burgul | C30: برغل | D30: =E30/G30 -> 3.6666667 | E30: =55/15 -> 3.6666667 | F30: 1 | G30: 1 | H30: =D30*15% -> 0.55 | I30: =H30+D30 -> 4.2166667 | K30: =J30*D30 -> 0 | L30: =K30/$J$2 -> 0 | N30: =M30*D30 -> 0 | O30: =N30/$M$2 -> 0 | Q30: =P30*D30 -> 0 | R30: =Q30/$P$2 -> 0 | T30: =S30*D30 -> 0 | U30: =T30/$S$2 -> 0 | W30: =V30*D30 -> 0 | X30: =W30/$V$2 -> 0 | Z30: =Y30*D30 -> 0 | AA30: =Z30/$Y$2 -> 0 | AC30: =AB30*D30 -> 0 | AD30: =AC30/$AB$2 -> 0 | AF30: =AE30*D30 -> 0 | AG30: =AF30/$AE$2 -> 0 | AH30: 0.01 | AI30: =AH30*D30 -> 0.036666667 | AJ30: =AI30/$AH$2 -> 0.032234897 | AL30: =AK30*D30 -> 0 | AM30: =AL30/$AK$2 -> 0 | AO30: =AN30*D30 -> 0 | AP30: =AO30/$AN$2 -> 0 | AR30: =AQ30*D30 -> 0 | AS30: =AR30/$AQ$2 -> 0 | AU30: =D30*AT30 -> 0 | AV30: =AU30/$AT$2 -> 0 | AX30: =D30*AW30 -> 0 | AY30: =AX30/$AW$2 -> 0 | BA30: =AZ30*D30 -> 0 | BB30: =BA30/$AZ$2 -> 0 | BD30: =D30*BC30 -> 0 | BE30: =BD30/$BC$2 -> 0 | BG30: =D30*BF30 -> 0 | BH30: =BG30/$BF$2 -> 0 | BJ30: =BI30*D30 -> 0 | BK30: =BJ30/$BI$2 -> 0 | BM30: =BL30*D30 -> 0 | BN30: =BM30/$BL$2 -> 0 | BO30: 0.008 | BP30: =BO30*D30 -> 0.029333333 | BQ30: =BP30/$BO$2 -> 0.012768369 | BS30: =D30*BR30 -> 0 | BT30: =BS30/$BR$2 -> 0 | BV30: =BU30*D30 -> 0 | BW30: =BV30/$BU$2 -> 0 | BY30: =D30*BX30 -> 0 | BZ30: =BY30/$BX$2 -> 0 | CB30: =CA30*D30 -> 0 | CC30: =CB30/$CA$2 -> 0 | CE30: =D30*CD30 -> 0 | CF30: =CE30/$CD$2 -> 0 | CH30: =D30*CG30 -> 0 | CI30: =CH30/$CG$2 -> 0 | CK30: =D30*CJ30 -> 0 | CL30: =CK30/$CJ$2 -> 0 | CN30: =D30*CM30 -> 0 | CO30: =CN30/$CM$2 -> 0 | CQ30: =CP30*D30 -> 0 | CR30: =CQ30/$CP$2 -> 0 | CT30: =CS30*G30 -> 0 | CU30: =CT30/$CP$2 -> 0 | CW30: =CV30*D30 -> 0 | CX30: =CW30/$CP$2 -> 0 | CZ30: =CY30*M30 -> 0 | DA30: =CZ30/$CP$2 -> 0 | DC30: =DB30*P30 -> 0 | DD30: =DC30/$CP$2 -> 0 | DF30: =DE30*D30 -> 0 | DG30: =DF30/$CP$2 -> 0 | DH30: =0.2/15 -> 0.013333333 | DI30: =DH30*D30 -> 0.048888889 | DJ30: =DI30/$CP$2 -> 0.2882396 | DL30: =DK30*D30 -> 0 | DM30: =DL30/$CP$2 -> 0
A31: 23 | B31: BUTTER | C31: زبدة | D31: =E31/G31 -> 36 | E31: 36 | F31: 1 | G31: 1 | H31: =D31*15% -> 5.4 | I31: =H31+D31 -> 41.4 | K31: =J31*D31 -> 0 | L31: =K31/$J$2 -> 0 | N31: =M31*D31 -> 0 | O31: =N31/$M$2 -> 0 | Q31: =P31*D31 -> 0 | R31: =Q31/$P$2 -> 0 | T31: =S31*D31 -> 0 | U31: =T31/$S$2 -> 0 | W31: =V31*D31 -> 0 | X31: =W31/$V$2 -> 0 | Z31: =Y31*D31 -> 0 | AA31: =Z31/$Y$2 -> 0 | AC31: =AB31*D31 -> 0 | AD31: =AC31/$AB$2 -> 0 | AF31: =AE31*D31 -> 0 | AG31: =AF31/$AE$2 -> 0 | AI31: =AH31*D31 -> 0 | AJ31: =AI31/$AH$2 -> 0 | AL31: =AK31*D31 -> 0 | AM31: =AL31/$AK$2 -> 0 | AO31: =AN31*D31 -> 0 | AP31: =AO31/$AN$2 -> 0 | AR31: =AQ31*D31 -> 0 | AS31: =AR31/$AQ$2 -> 0 | AU31: =D31*AT31 -> 0 | AV31: =AU31/$AT$2 -> 0 | AX31: =D31*AW31 -> 0 | AY31: =AX31/$AW$2 -> 0 | BA31: =AZ31*D31 -> 0 | BB31: =BA31/$AZ$2 -> 0 | BD31: =D31*BC31 -> 0 | BE31: =BD31/$BC$2 -> 0 | BG31: =D31*BF31 -> 0 | BH31: =BG31/$BF$2 -> 0 | BJ31: =BI31*D31 -> 0 | BK31: =BJ31/$BI$2 -> 0 | BM31: =BL31*D31 -> 0 | BN31: =BM31/$BL$2 -> 0 | BP31: =BO31*D31 -> 0 | BQ31: =BP31/$BO$2 -> 0 | BS31: =D31*BR31 -> 0 | BT31: =BS31/$BR$2 -> 0 | BV31: =BU31*D31 -> 0 | BW31: =BV31/$BU$2 -> 0 | BY31: =D31*BX31 -> 0 | BZ31: =BY31/$BX$2 -> 0 | CB31: =CA31*D31 -> 0 | CC31: =CB31/$CA$2 -> 0 | CE31: =D31*CD31 -> 0 | CF31: =CE31/$CD$2 -> 0 | CH31: =D31*CG31 -> 0 | CI31: =CH31/$CG$2 -> 0 | CK31: =D31*CJ31 -> 0 | CL31: =CK31/$CJ$2 -> 0 | CN31: =D31*CM31 -> 0 | CO31: =CN31/$CM$2 -> 0 | CQ31: =CP31*D31 -> 0 | CR31: =CQ31/$CP$2 -> 0 | CT31: =CS31*G31 -> 0 | CU31: =CT31/$CP$2 -> 0 | CW31: =CV31*D31 -> 0 | CX31: =CW31/$CP$2 -> 0 | CZ31: =CY31*M31 -> 0 | DA31: =CZ31/$CP$2 -> 0 | DC31: =DB31*P31 -> 0 | DD31: =DC31/$CP$2 -> 0 | DF31: =DE31*D31 -> 0 | DG31: =DF31/$CP$2 -> 0 | DI31: =DH31*D31 -> 0 | DJ31: =DI31/$CP$2 -> 0 | DL31: =DK31*D31 -> 0 | DM31: =DL31/$CP$2 -> 0
A32: 24 | B32: CABBAGE | C32: ملفوف | D32: =E32/G32 -> 1.8072289 | E32: 1.5 | F32: 1 | G32: 0.83 | H32: =D32*15% -> 0.27108434 | I32: =H32+D32 -> 2.0783133 | K32: =J32*D32 -> 0 | L32: =K32/$J$2 -> 0 | N32: =M32*D32 -> 0 | O32: =N32/$M$2 -> 0 | Q32: =P32*D32 -> 0 | R32: =Q32/$P$2 -> 0 | T32: =S32*D32 -> 0 | U32: =T32/$S$2 -> 0 | W32: =V32*D32 -> 0 | X32: =W32/$V$2 -> 0 | Z32: =Y32*D32 -> 0 | AA32: =Z32/$Y$2 -> 0 | AC32: =AB32*D32 -> 0 | AD32: =AC32/$AB$2 -> 0 | AF32: =AE32*D32 -> 0 | AG32: =AF32/$AE$2 -> 0 | AI32: =AH32*D32 -> 0 | AJ32: =AI32/$AH$2 -> 0 | AL32: =AK32*D32 -> 0 | AM32: =AL32/$AK$2 -> 0 | AO32: =AN32*D32 -> 0 | AP32: =AO32/$AN$2 -> 0 | AR32: =AQ32*D32 -> 0 | AS32: =AR32/$AQ$2 -> 0 | AT32: 0.12 | AU32: =D32*AT32 -> 0.21686747 | AV32: =AU32/$AT$2 -> 0.16029928 | AX32: =D32*AW32 -> 0 | AY32: =AX32/$AW$2 -> 0 | BA32: =AZ32*D32 -> 0 | BB32: =BA32/$AZ$2 -> 0 | BD32: =D32*BC32 -> 0 | BE32: =BD32/$BC$2 -> 0 | BG32: =D32*BF32 -> 0 | BH32: =BG32/$BF$2 -> 0 | BJ32: =BI32*D32 -> 0 | BK32: =BJ32/$BI$2 -> 0 | BM32: =BL32*D32 -> 0 | BN32: =BM32/$BL$2 -> 0 | BP32: =BO32*D32 -> 0 | BQ32: =BP32/$BO$2 -> 0 | BS32: =D32*BR32 -> 0 | BT32: =BS32/$BR$2 -> 0 | BV32: =BU32*D32 -> 0 | BW32: =BV32/$BU$2 -> 0 | BY32: =D32*BX32 -> 0 | BZ32: =BY32/$BX$2 -> 0 | CB32: =CA32*D32 -> 0 | CC32: =CB32/$CA$2 -> 0 | CE32: =D32*CD32 -> 0 | CF32: =CE32/$CD$2 -> 0 | CH32: =D32*CG32 -> 0 | CI32: =CH32/$CG$2 -> 0 | CK32: =D32*CJ32 -> 0 | CL32: =CK32/$CJ$2 -> 0 | CN32: =D32*CM32 -> 0 | CO32: =CN32/$CM$2 -> 0 | CQ32: =CP32*D32 -> 0 | CR32: =CQ32/$CP$2 -> 0 | CT32: =CS32*G32 -> 0 | CU32: =CT32/$CP$2 -> 0 | CW32: =CV32*D32 -> 0 | CX32: =CW32/$CP$2 -> 0 | CZ32: =CY32*M32 -> 0 | DA32: =CZ32/$CP$2 -> 0 | DC32: =DB32*P32 -> 0 | DD32: =DC32/$CP$2 -> 0 | DF32: =DE32*D32 -> 0 | DG32: =DF32/$CP$2 -> 0 | DI32: =DH32*D32 -> 0 | DJ32: =DI32/$CP$2 -> 0 | DL32: =DK32*D32 -> 0 | DM32: =DL32/$CP$2 -> 0
A33: 25 | B33: CANOILA OIL | C33: زيت كانيولا | D33: =E33/G33 -> 15.966667 | E33: =23.95/1.5 -> 15.966667 | F33: 1 | G33: 1 | H33: =D33*15% -> 2.395 | I33: =H33+D33 -> 18.361667 | K33: =J33*D33 -> 0 | L33: =K33/$J$2 -> 0 | N33: =M33*D33 -> 0 | O33: =N33/$M$2 -> 0 | Q33: =P33*D33 -> 0 | R33: =Q33/$P$2 -> 0 | T33: =S33*D33 -> 0 | U33: =T33/$S$2 -> 0 | W33: =V33*D33 -> 0 | X33: =W33/$V$2 -> 0 | Z33: =Y33*D33 -> 0 | AA33: =Z33/$Y$2 -> 0 | AC33: =AB33*D33 -> 0 | AD33: =AC33/$AB$2 -> 0 | AF33: =AE33*D33 -> 0 | AG33: =AF33/$AE$2 -> 0 | AI33: =AH33*D33 -> 0 | AJ33: =AI33/$AH$2 -> 0 | AL33: =AK33*D33 -> 0 | AM33: =AL33/$AK$2 -> 0 | AO33: =AN33*D33 -> 0 | AP33: =AO33/$AN$2 -> 0 | AR33: =AQ33*D33 -> 0 | AS33: =AR33/$AQ$2 -> 0 | AU33: =D33*AT33 -> 0 | AV33: =AU33/$AT$2 -> 0 | AX33: =D33*AW33 -> 0 | AY33: =AX33/$AW$2 -> 0 | BA33: =AZ33*D33 -> 0 | BB33: =BA33/$AZ$2 -> 0 | BD33: =D33*BC33 -> 0 | BE33: =BD33/$BC$2 -> 0 | BG33: =D33*BF33 -> 0 | BH33: =BG33/$BF$2 -> 0 | BJ33: =BI33*D33 -> 0 | BK33: =BJ33/$BI$2 -> 0 | BM33: =BL33*D33 -> 0 | BN33: =BM33/$BL$2 -> 0 | BP33: =BO33*D33 -> 0 | BQ33: =BP33/$BO$2 -> 0 | BR33: 0.05 | BS33: =D33*BR33 -> 0.79833333 | BT33: =BS33/$BR$2 -> 0.22040967 | BU33: 0.06 | BV33: =BU33*D33 -> 0.958 | BW33: =BV33/$BU$2 -> 0.28577581 | BY33: =D33*BX33 -> 0 | BZ33: =BY33/$BX$2 -> 0 | CB33: =CA33*D33 -> 0 | CC33: =CB33/$CA$2 -> 0 | CE33: =D33*CD33 -> 0 | CF33: =CE33/$CD$2 -> 0 | CH33: =D33*CG33 -> 0 | CI33: =CH33/$CG$2 -> 0 | CK33: =D33*CJ33 -> 0 | CL33: =CK33/$CJ$2 -> 0 | CN33: =D33*CM33 -> 0 | CO33: =CN33/$CM$2 -> 0 | CQ33: =CP33*D33 -> 0 | CR33: =CQ33/$CP$2 -> 0 | CT33: =CS33*G33 -> 0 | CU33: =CT33/$CP$2 -> 0 | CW33: =CV33*D33 -> 0 | CX33: =CW33/$CP$2 -> 0 | CZ33: =CY33*M33 -> 0 | DA33: =CZ33/$CP$2 -> 0 | DC33: =DB33*P33 -> 0 | DD33: =DC33/$CP$2 -> 0 | DF33: =DE33*D33 -> 0 | DG33: =DF33/$CP$2 -> 0 | DI33: =DH33*D33 -> 0 | DJ33: =DI33/$CP$2 -> 0 | DL33: =DK33*D33 -> 0 | DM33: =DL33/$CP$2 -> 0
A34: 26 | B34: cardmom | C34: هيل | D34: =E34/G34 -> 58 | E34: 58 | F34: 1 | G34: 1 | H34: =D34*15% -> 8.7 | I34: =H34+D34 -> 66.7 | K34: =J34*D34 -> 0 | L34: =K34/$J$2 -> 0 | N34: =M34*D34 -> 0 | O34: =N34/$M$2 -> 0 | Q34: =P34*D34 -> 0 | R34: =Q34/$P$2 -> 0 | S34: 0.002 | T34: =S34*D34 -> 0.116 | U34: =T34/$S$2 -> 0.023043691 | W34: =V34*D34 -> 0 | X34: =W34/$V$2 -> 0 | Z34: =Y34*D34 -> 0 | AA34: =Z34/$Y$2 -> 0 | AC34: =AB34*D34 -> 0 | AD34: =AC34/$AB$2 -> 0 | AF34: =AE34*D34 -> 0 | AG34: =AF34/$AE$2 -> 0 | AI34: =AH34*D34 -> 0 | AJ34: =AI34/$AH$2 -> 0 | AL34: =AK34*D34 -> 0 | AM34: =AL34/$AK$2 -> 0 | AO34: =AN34*D34 -> 0 | AP34: =AO34/$AN$2 -> 0 | AR34: =AQ34*D34 -> 0 | AS34: =AR34/$AQ$2 -> 0 | AU34: =D34*AT34 -> 0 | AV34: =AU34/$AT$2 -> 0 | AX34: =D34*AW34 -> 0 | AY34: =AX34/$AW$2 -> 0 | BA34: =AZ34*D34 -> 0 | BB34: =BA34/$AZ$2 -> 0 | BD34: =D34*BC34 -> 0 | BE34: =BD34/$BC$2 -> 0 | BG34: =D34*BF34 -> 0 | BH34: =BG34/$BF$2 -> 0 | BJ34: =BI34*D34 -> 0 | BK34: =BJ34/$BI$2 -> 0 | BM34: =BL34*D34 -> 0 | BN34: =BM34/$BL$2 -> 0 | BP34: =BO34*D34 -> 0 | BQ34: =BP34/$BO$2 -> 0 | BS34: =D34*BR34 -> 0 | BT34: =BS34/$BR$2 -> 0 | BV34: =BU34*D34 -> 0 | BW34: =BV34/$BU$2 -> 0 | BY34: =D34*BX34 -> 0 | BZ34: =BY34/$BX$2 -> 0 | CB34: =CA34*D34 -> 0 | CC34: =CB34/$CA$2 -> 0 | CE34: =D34*CD34 -> 0 | CF34: =CE34/$CD$2 -> 0 | CH34: =D34*CG34 -> 0 | CI34: =CH34/$CG$2 -> 0 | CK34: =D34*CJ34 -> 0 | CL34: =CK34/$CJ$2 -> 0 | CN34: =D34*CM34 -> 0 | CO34: =CN34/$CM$2 -> 0 | CQ34: =CP34*D34 -> 0 | CR34: =CQ34/$CP$2 -> 0 | CT34: =CS34*G34 -> 0 | CU34: =CT34/$CP$2 -> 0 | CW34: =CV34*D34 -> 0 | CX34: =CW34/$CP$2 -> 0 | CZ34: =CY34*M34 -> 0 | DA34: =CZ34/$CP$2 -> 0 | DC34: =DB34*P34 -> 0 | DD34: =DC34/$CP$2 -> 0 | DF34: =DE34*D34 -> 0 | DG34: =DF34/$CP$2 -> 0 | DI34: =DH34*D34 -> 0 | DJ34: =DI34/$CP$2 -> 0 | DL34: =DK34*D34 -> 0 | DM34: =DL34/$CP$2 -> 0
A35: 27 | B35: CAULIFLWER | C35: زهرة | D35: =E35/G35 -> 5.4375 | E35: 4.35 | F35: 1 | G35: 0.8 | H35: =D35*15% -> 0.815625 | I35: =H35+D35 -> 6.253125 | K35: =J35*D35 -> 0 | L35: =K35/$J$2 -> 0 | N35: =M35*D35 -> 0 | O35: =N35/$M$2 -> 0 | Q35: =P35*D35 -> 0 | R35: =Q35/$P$2 -> 0 | T35: =S35*D35 -> 0 | U35: =T35/$S$2 -> 0 | W35: =V35*D35 -> 0 | X35: =W35/$V$2 -> 0 | Z35: =Y35*D35 -> 0 | AA35: =Z35/$Y$2 -> 0 | AC35: =AB35*D35 -> 0 | AD35: =AC35/$AB$2 -> 0 | AF35: =AE35*D35 -> 0 | AG35: =AF35/$AE$2 -> 0 | AI35: =AH35*D35 -> 0 | AJ35: =AI35/$AH$2 -> 0 | AL35: =AK35*D35 -> 0 | AM35: =AL35/$AK$2 -> 0 | AO35: =AN35*D35 -> 0 | AP35: =AO35/$AN$2 -> 0 | AR35: =AQ35*D35 -> 0 | AS35: =AR35/$AQ$2 -> 0 | AU35: =D35*AT35 -> 0 | AV35: =AU35/$AT$2 -> 0 | AX35: =D35*AW35 -> 0 | AY35: =AX35/$AW$2 -> 0 | BA35: =AZ35*D35 -> 0 | BB35: =BA35/$AZ$2 -> 0 | BD35: =D35*BC35 -> 0 | BE35: =BD35/$BC$2 -> 0 | BG35: =D35*BF35 -> 0 | BH35: =BG35/$BF$2 -> 0 | BJ35: =BI35*D35 -> 0 | BK35: =BJ35/$BI$2 -> 0 | BM35: =BL35*D35 -> 0 | BN35: =BM35/$BL$2 -> 0 | BP35: =BO35*D35 -> 0 | BQ35: =BP35/$BO$2 -> 0 | BR35: 0.2 | BS35: =D35*BR35 -> 1.0875 | BT35: =BS35/$BR$2 -> 0.30024491 | BV35: =BU35*D35 -> 0 | BW35: =BV35/$BU$2 -> 0 | BY35: =D35*BX35 -> 0 | BZ35: =BY35/$BX$2 -> 0 | CB35: =CA35*D35 -> 0 | CC35: =CB35/$CA$2 -> 0 | CE35: =D35*CD35 -> 0 | CF35: =CE35/$CD$2 -> 0 | CH35: =D35*CG35 -> 0 | CI35: =CH35/$CG$2 -> 0 | CK35: =D35*CJ35 -> 0 | CL35: =CK35/$CJ$2 -> 0 | CN35: =D35*CM35 -> 0 | CO35: =CN35/$CM$2 -> 0 | CQ35: =CP35*D35 -> 0 | CR35: =CQ35/$CP$2 -> 0 | CT35: =CS35*G35 -> 0 | CU35: =CT35/$CP$2 -> 0 | CW35: =CV35*D35 -> 0 | CX35: =CW35/$CP$2 -> 0 | CZ35: =CY35*M35 -> 0 | DA35: =CZ35/$CP$2 -> 0 | DC35: =DB35*P35 -> 0 | DD35: =DC35/$CP$2 -> 0 | DF35: =DE35*D35 -> 0 | DG35: =DF35/$CP$2 -> 0 | DI35: =DH35*D35 -> 0 | DJ35: =DI35/$CP$2 -> 0 | DL35: =DK35*D35 -> 0 | DM35: =DL35/$CP$2 -> 0
